Workbook

Sheet Dashboard
A1: ='Company Info'!B4
A2: FINANCIAL MODEL DASHBOARD · E£ (Egyptian Pound) · February 20, 2026 · CONFIDENTIAL
A4: 📊 SCENARIO CONTROL
A5: Active Scenario | B5: Select Scenario → | E5: Revenue Base (E£) | F5: ='Company Info'!B18 | G5: Fiscal Year | H5: ='Company Info'!B15
A6: ▼ Scenario Selector | B6: Base Case | E6: =IF(B6="Base Case","Central planning — stable market conditions | Revenue growth 10%→5% | COGS 60% | Rate 20%",IF(B6="Optimistic","Bull case — strong execution | Revenue growth 15%→8% | COGS 55% | Rate 15%","Bear case — headwinds | Revenue growth 5%→2% | COGS 63% | Rate 22%"))
A8: 📈 KEY METRICS — ACTIVE SCENARIO
B9: 2021 (A) | C9: 2022 (A) | D9: 2023 (A) | E9: 2024E | F9: 2025E | G9: 2026E | H9: 2027E | I9: 2028E
A10: 📗 INCOME STATEMENT
A11: Revenue (E£) | B11: ='Income Statement'!B2 | C11: ='Income Statement'!C2 | D11: ='Income Statement'!D2 | E11: ='Income Statement'!E2 | F11: ='Income Statement'!F2 | G11: ='Income Statement'!G2 | H11: ='Income Statement'!H2 | I11: ='Income Statement'!I2
A12: Revenue Growth % | B12: ='Income Statement'!B3 | C12: ='Income Statement'!C3 | D12: ='Income Statement'!D3 | E12: ='Income Statement'!E3 | F12: ='Income Statement'!F3 | G12: ='Income Statement'!G3 | H12: ='Income Statement'!H3 | I12: ='Income Statement'!I3
A13: Gross Profit (E£) | B13: ='Income Statement'!B5 | C13: ='Income Statement'!C5 | D13: ='Income Statement'!D5 | E13: ='Income Statement'!E5 | F13: ='Income Statement'!F5 | G13: ='Income Statement'!G5 | H13: ='Income Statement'!H5 | I13: ='Income Statement'!I5
A14: Gross Margin % | B14: ='Income Statement'!B6 | C14: ='Income Statement'!C6 | D14: ='Income Statement'!D6 | E14: ='Income Statement'!E6 | F14: ='Income Statement'!F6 | G14: ='Income Statement'!G6 | H14: ='Income Statement'!H6 | I14: ='Income Statement'!I6
A15: EBITDA (E£) | B15: ='Income Statement'!B18 | C15: ='Income Statement'!C18 | D15: ='Income Statement'!D18 | E15: ='Income Statement'!E18 | F15: ='Income Statement'!F18 | G15: ='Income Statement'!G18 | H15: ='Income Statement'!H18 | I15: ='Income Statement'!I18
A16: EBITDA Margin % | B16: =IF('Income Statement'!B2=0,0,'Income Statement'!B18/'Income Statement'!B2) | C16: =IF('Income Statement'!C2=0,0,'Income Statement'!C18/'Income Statement'!C2) | D16: =IF('Income Statement'!D2=0,0,'Income Statement'!D18/'Income Statement'!D2) | E16: =IF('Income Statement'!E2=0,0,'Income Statement'!E18/'Income Statement'!E2) | F16: =IF('Income Statement'!F2=0,0,'Income Statement'!F18/'Income Statement'!F2) | G16: =IF('Income Statement'!G2=0,0,'Income Statement'!G18/'Income Statement'!G2) | H16: =IF('Income Statement'!H2=0,0,'Income Statement'!H18/'Income Statement'!H2) | I16: =IF('Income Statement'!I2=0,0,'Income Statement'!I18/'Income Statement'!I2)
A17: EBIT (E£) | B17: ='Income Statement'!B17 | C17: ='Income Statement'!C17 | D17: ='Income Statement'!D17 | E17: ='Income Statement'!E17 | F17: ='Income Statement'!F17 | G17: ='Income Statement'!G17 | H17: ='Income Statement'!H17 | I17: ='Income Statement'!I17
A18: EBIT Margin % | B18: ='Income Statement'!B19 | C18: ='Income Statement'!C19 | D18: ='Income Statement'!D19 | E18: ='Income Statement'!E19 | F18: ='Income Statement'!F19 | G18: ='Income Statement'!G19 | H18: ='Income Statement'!H19 | I18: ='Income Statement'!I19
A19: Net Income (E£) | B19: ='Income Statement'!B28 | C19: ='Income Statement'!C28 | D19: ='Income Statement'!D28 | E19: ='Income Statement'!E28 | F19: ='Income Statement'!F28 | G19: ='Income Statement'!G28 | H19: ='Income Statement'!H28 | I19: ='Income Statement'!I28
A20: Net Margin % | B20: ='Income Statement'!B29 | C20: ='Income Statement'!C29 | D20: ='Income Statement'!D29 | E20: ='Income Statement'!E29 | F20: ='Income Statement'!F29 | G20: ='Income Statement'!G29 | H20: ='Income Statement'!H29 | I20: ='Income Statement'!I29
A21: EPS (E£) | B21: ='Income Statement'!B30 | C21: ='Income Statement'!C30 | D21: ='Income Statement'!D30 | E21: ='Income Statement'!E30 | F21: ='Income Statement'!F30 | G21: ='Income Statement'!G30 | H21: ='Income Statement'!H30 | I21: ='Income Statement'!I30
A22: 💵 CASH FLOW
A23: Cash from Operations (E£) | B23: — | C23: ='Cash Flow Statement'!B16 | D23: ='Cash Flow Statement'!C16 | E23: ='Cash Flow Statement'!D16 | F23: ='Cash Flow Statement'!E16 | G23: ='Cash Flow Statement'!F16 | H23: ='Cash Flow Statement'!G16 | I23: ='Cash Flow Statement'!H16
A24: Free Cash Flow (E£) | B24: — | C24: ='Cash Flow Statement'!B36 | D24: ='Cash Flow Statement'!C36 | E24: ='Cash Flow Statement'!D36 | F24: ='Cash Flow Statement'!E36 | G24: ='Cash Flow Statement'!F36 | H24: ='Cash Flow Statement'!G36 | I24: ='Cash Flow Statement'!H36
A25: Ending Cash (E£) | B25: — | C25: ='Cash Flow Statement'!B34 | D25: ='Cash Flow Statement'!C34 | E25: ='Cash Flow Statement'!D34 | F25: ='Cash Flow Statement'!E34 | G25: ='Cash Flow Statement'!F34 | H25: ='Cash Flow Statement'!G34 | I25: ='Cash Flow Statement'!H34
A26: 🏦 BALANCE SHEET
A27: Total Assets (E£) | B27: ='Balance Sheet'!B15 | C27: ='Balance Sheet'!C15 | D27: ='Balance Sheet'!D15 | E27: ='Balance Sheet'!E15 | F27: ='Balance Sheet'!F15 | G27: ='Balance Sheet'!G15 | H27: ='Balance Sheet'!H15 | I27: ='Balance Sheet'!I15
A28: Total Debt (E£) | B28: ='Balance Sheet'!B20+'Balance Sheet'!B21+'Balance Sheet'!B26 | C28: ='Balance Sheet'!C20+'Balance Sheet'!C21+'Balance Sheet'!C26 | D28: ='Balance Sheet'!D20+'Balance Sheet'!D21+'Balance Sheet'!D26 | E28: ='Balance Sheet'!E20+'Balance Sheet'!E21+'Balance Sheet'!E26 | F28: ='Balance Sheet'!F20+'Balance Sheet'!F21+'Balance Sheet'!F26 | G28: ='Balance Sheet'!G20+'Balance Sheet'!G21+'Balance Sheet'!G26 | H28: ='Balance Sheet'!H20+'Balance Sheet'!H21+'Balance Sheet'!H26 | I28: ='Balance Sheet'!I20+'Balance Sheet'!I21+'Balance Sheet'!I26
A29: Total Equity (E£) | B29: ='Balance Sheet'!B38 | C29: ='Balance Sheet'!C38 | D29: ='Balance Sheet'!D38 | E29: ='Balance Sheet'!E38 | F29: ='Balance Sheet'!F38 | G29: ='Balance Sheet'!G38 | H29: ='Balance Sheet'!H38 | I29: ='Balance Sheet'!I38
A30: Cash & Equivalents (E£) | B30: ='Balance Sheet'!B3 | C30: ='Balance Sheet'!C3 | D30: ='Balance Sheet'!D3 | E30: ='Balance Sheet'!E3 | F30: ='Balance Sheet'!F3 | G30: ='Balance Sheet'!G3 | H30: ='Balance Sheet'!H3 | I30: ='Balance Sheet'!I3
A31: 📊 KEY RATIOS
A32: Current Ratio | B32: =Ratios!B9 | C32: =Ratios!C9 | D32: =Ratios!D9 | E32: =Ratios!E9 | F32: =Ratios!F9 | G32: =Ratios!G9 | H32: =Ratios!H9 | I32: =Ratios!I9
A33: Debt / Equity | B33: =Ratios!B10 | C33: =Ratios!C10 | D33: =Ratios!D10 | E33: =Ratios!E10 | F33: =Ratios!F10 | G33: =Ratios!G10 | H33: =Ratios!H10 | I33: =Ratios!I10
A34: ROE % | B34: =Ratios!B7 | C34: =Ratios!C7 | D34: =Ratios!D7 | E34: =Ratios!E7 | F34: =Ratios!F7 | G34: =Ratios!G7 | H34: =Ratios!H7 | I34: =Ratios!I7
A35: ROA % | B35: =Ratios!B6 | C35: =Ratios!C6 | D35: =Ratios!D6 | E35: =Ratios!E6 | F35: =Ratios!F6 | G35: =Ratios!G6 | H35: =Ratios!H6 | I35: =Ratios!I6
A38: ⚖️ SCENARIO COMPARISON — Terminal Year 2028E
A39: Values are pre-computed scenario snapshots. Change the active scenario via the dropdown above.
A40: Metric | C40: Base Case | E40: Optimistic | G40: Conservative | I40: Base→Opt Δ | J40: Base→Cons Δ
A41: Revenue (E£) | C41: 1414801.1 | E41: 1667857 | G41: 1181672.9 | I41: 0.17886322 | J41: -0.16477809
A42: Gross Margin % | C42: 0.4 | E42: 0.45 | G42: 0.38 | I42: 0.05 | J42: -0.02
A43: EBITDA (E£) | C43: 244664.19 | E43: 431982.09 | G43: 161342.56 | I43: 0.76561223 | J43: -0.34055506
A44: EBITDA Margin % | C44: 0.17293187 | E44: 0.25900428 | G44: 0.13653742 | I44: 0.086072413 | J44: -0.036394448
...

Sheet Company Info
A1: COMPANY INFORMATION & MODEL CONFIGURATION
A3: SECTION 1 — COMPANY IDENTIFICATION
A4: Company Name | B4: Demo Company Inc. | C4: ← Edit
A5: Legal Entity Type | B5: Société Anonyme (S.A.E.) | C5: ← Edit
A6: Industry / Sector | B6: Technology / Software | C6: ← Edit
A7: Founded Year | B7: 2010 | C7: ← Edit
A8: Commercial Register No. | B8: 12345-Cairo-2010 | C8: Auto
A9: Tax Identification No. | B9: 123-456-789 | C9: Auto
A10: Headquarters Address | B10: 5 El-Nile Street, Zamalek, Cairo, Egypt | C10: Auto
A12: SECTION 2 — FINANCIAL MODEL CONFIGURATION
A13: Reporting Currency | B13: Egyptian Pound (EGP) | C13: Auto
A14: Currency Symbol | B14: E£ | C14: Auto
A15: Fiscal Year End | B15: December 31 | C15: ← Edit
A16: Historical Period | B16: 2021 – 2023 (Actual) | C16: Auto
A17: Projection Period | B17: 2024E – 2028E (5 Years) | C17: Auto
A18: Revenue Projection Base (E£) | B18: 1000000 | C18: ← Edit
A19: Model Version | B19: v2.0 | Feb 2026 | C19: Auto
A20: Last Updated | B20: February 20, 2026 | C20: Auto
A22: SECTION 3 — EGYPT REGULATORY / TAX
A23: Corporate Income Tax Rate | B23: 0.225 | C23: ← Edit
A24: VAT Rate (Standard) | B24: 0.14 | C24: ← Edit
A25: Dividend Withholding Tax | B25: 0.1 | C25: ← Edit
A26: CBE Policy Rate (Reference) | B26: 0.2725 | C26: ← Edit
A27: Financial Year Note | B27: July 1 – June 30 (Note: model uses Dec) | C27: ← Edit
A29: SECTION 4 — REPORT & PREPARER INFORMATION
A30: Prepared By | B30: Financial Modeling Team | C30: ← Edit
A31: Reviewed By | B31: CFO | C31: ← Edit
A32: Preparation Date | B32: February 20, 2026 | C32: ← Edit
A33: Purpose | B33: Internal Planning & Analysis | C33: ← Edit
A34: Confidentiality | B34: CONFIDENTIAL — Internal Use Only | C34: ← Edit
A35: Contact Email | B35: finance@democompany.com | C35: ← Edit
A37: Note: Blue-text cells are editable inputs. Company Name (B4) flows to Dashboard and all sheet headers.

Sheet Scenarios
A1: SCENARIO ASSUMPTIONS
A2: This sheet is the single source of truth for all scenario assumption values. It feeds the Assumptions sheet when a scenario is selected in the Dashboard.
A4: ▎ BASE CASE | G4: Base Case
A5: Assumption | B5: 2024E | C5: 2025E | D5: 2026E | E5: 2027E | F5: 2028E | G5: Central planning scenario — stable market conditions
A6: Revenue Growth Rate | B6: 0.1 | C6: 0.08 | D6: 0.07 | E6: 0.06 | F6: 0.05 | G6: • Revenue growth decelerates from 10% to 5% over 5 years
A7: COGS % of Revenue | B7: 0.6 | C7: 0.6 | D7: 0.6 | E7: 0.6 | F7: 0.6 | G7: • COGS maintained at 60% — stable supply chain
A8: SG&A % of Revenue | B8: 0.15 | C8: 0.15 | D8: 0.15 | E8: 0.15 | F8: 0.15 | G8: • SG&A at 15% — steady marketing investment
A9: R&D % of Revenue | B9: 0.05 | C9: 0.05 | D9: 0.05 | E9: 0.05 | F9: 0.05 | G9: • Interest rate fixed at 20% — current CBE environment
A10: Other OpEx % of Revenue | B10: 0.02 | C10: 0.02 | D10: 0.02 | E10: 0.02 | F10: 0.02 | G10: • Conservative 5% dividend payout ratio
A11: Tax Rate | B11: 0.225 | C11: 0.225 | D11: 0.225 | E11: 0.225 | F11: 0.225
A12: CapEx % of Revenue | B12: 0.05 | C12: 0.05 | D12: 0.05 | E12: 0.05 | F12: 0.05
A13: Interest Rate (on Debt) | B13: 0.2 | C13: 0.2 | D13: 0.2 | E13: 0.2 | F13: 0.2
A14: Dividend Payout Ratio | B14: 0.05 | C14: 0.05 | D14: 0.05 | E14: 0.05 | F14: 0.05
A16: ▎ OPTIMISTIC | G16: Optimistic
A17: Assumption | B17: 2024E | C17: 2025E | D17: 2026E | E17: 2027E | F17: 2028E | G17: Bull case — strong execution & market tailwinds
A18: Revenue Growth Rate | B18: 0.15 | C18: 0.12 | D18: 0.1 | E18: 0.09 | F18: 0.08 | G18: • Aggressive revenue growth from 15% tapering to 8%
A19: COGS % of Revenue | B19: 0.57 | C19: 0.56 | D19: 0.56 | E19: 0.55 | F19: 0.55 | G19: • COGS improves from 57% to 55% — scale economies
A20: SG&A % of Revenue | B20: 0.13 | C20: 0.13 | D20: 0.13 | E20: 0.13 | F20: 0.13 | G20: • Lower SG&A at 13% — efficient customer acquisition
A21: R&D % of Revenue | B21: 0.04 | C21: 0.04 | D21: 0.04 | E21: 0.04 | F21: 0.04 | G21: • Interest rates decline from 18% to 15% — CBE easing
A22: Other OpEx % of Revenue | B22: 0.015 | C22: 0.015 | D22: 0.015 | E22: 0.015 | F22: 0.015 | G22: • Dividend payout increases from 5% to 12%
A23: Tax Rate | B23: 0.225 | C23: 0.225 | D23: 0.225 | E23: 0.225 | F23: 0.225
A24: CapEx % of Revenue | B24: 0.06 | C24: 0.05 | D24: 0.05 | E24: 0.04 | F24: 0.04
A25: Interest Rate (on Debt) | B25: 0.18 | C25: 0.17 | D25: 0.16 | E25: 0.15 | F25: 0.15
A26: Dividend Payout Ratio | B26: 0.05 | C26: 0.08 | D26: 0.1 | E26: 0.1 | F26: 0.12
A28: ▎ CONSERVATIVE | G28: Conservative
A29: Assumption | B29: 2024E | C29: 2025E | D29: 2026E | E29: 2027E | F29: 2028E | G29: Bear case — macro headwinds & competitive pressure
A30: Revenue Growth Rate | B30: 0.05 | C30: 0.04 | D30: 0.03 | E30: 0.03 | F30: 0.02 | G30: • Slow revenue growth from 5% declining to 2%
A31: COGS % of Revenue | B31: 0.63 | C31: 0.63 | D31: 0.63 | E31: 0.63 | F31: 0.62 | G31: • COGS elevated at 63% — input cost pressure
A32: SG&A % of Revenue | B32: 0.17 | C32: 0.17 | D32: 0.16 | E32: 0.16 | F32: 0.16 | G32: • Higher SG&A at 17% — customer retention costs
A33: R&D % of Revenue | B33: 0.06 | C33: 0.06 | D33: 0.06 | E33: 0.05 | F33: 0.05 | G33: • High interest rates at 22% — tight monetary policy
A34: Other OpEx % of Revenue | B34: 0.025 | C34: 0.025 | D34: 0.025 | E34: 0.025 | F34: 0.025 | G34: • Minimal 3% dividend payout — cash preservation
A35: Tax Rate | B35: 0.225 | C35: 0.225 | D35: 0.225 | E35: 0.225 | F35: 0.225
A36: CapEx % of Revenue | B36: 0.06 | C36: 0.06 | D36: 0.06 | E36: 0.06 | F36: 0.06
A37: Interest Rate (on Debt) | B37: 0.22 | C37: 0.22 | D37: 0.21 | E37: 0.21 | F37: 0.2
A38: Dividend Payout Ratio | B38: 0.03 | C38: 0.03 | D38: 0.03 | E38: 0.03 | F38: 0.03

Sheet Assumptions
A1: Assumption | B1: 2021 | C1: 2022 | D1: 2023 | E1: 2024E | F1: 2025E | G1: 2026E | H1: 2027E | I1: 2028E
A2: ── Income Statement Drivers ──
A3: Revenue Base (Historical) | B3: 750000
A4: Revenue Base (Projection) | B4: 1000000
A5: Revenue Growth Rate | B5: 0 | C5: 0.13333333 | D5: 0.11764706 | E5: =IF($B$63="Base Case",Scenarios!B6,IF($B$63="Optimistic",Scenarios!B18,Scenarios!B30)) | F5: =IF($B$63="Base Case",Scenarios!C6,IF($B$63="Optimistic",Scenarios!C18,Scenarios!C30)) | G5: =IF($B$63="Base Case",Scenarios!D6,IF($B$63="Optimistic",Scenarios!D18,Scenarios!D30)) | H5: =IF($B$63="Base Case",Scenarios!E6,IF($B$63="Optimistic",Scenarios!E18,Scenarios!E30)) | I5: =IF($B$63="Base Case",Scenarios!F6,IF($B$63="Optimistic",Scenarios!F18,Scenarios!F30))
A6: COGS % of Revenue | B6: 0.6 | C6: 0.6 | D6: 0.6 | E6: =IF($B$63="Base Case",Scenarios!B7,IF($B$63="Optimistic",Scenarios!B19,Scenarios!B31)) | F6: =IF($B$63="Base Case",Scenarios!C7,IF($B$63="Optimistic",Scenarios!C19,Scenarios!C31)) | G6: =IF($B$63="Base Case",Scenarios!D7,IF($B$63="Optimistic",Scenarios!D19,Scenarios!D31)) | H6: =IF($B$63="Base Case",Scenarios!E7,IF($B$63="Optimistic",Scenarios!E19,Scenarios!E31)) | I6: =IF($B$63="Base Case",Scenarios!F7,IF($B$63="Optimistic",Scenarios!F19,Scenarios!F31))
A7: SG&A % of Revenue | B7: 0.15 | C7: 0.15 | D7: 0.15 | E7: =IF($B$63="Base Case",Scenarios!B8,IF($B$63="Optimistic",Scenarios!B20,Scenarios!B32)) | F7: =IF($B$63="Base Case",Scenarios!C8,IF($B$63="Optimistic",Scenarios!C20,Scenarios!C32)) | G7: =IF($B$63="Base Case",Scenarios!D8,IF($B$63="Optimistic",Scenarios!D20,Scenarios!D32)) | H7: =IF($B$63="Base Case",Scenarios!E8,IF($B$63="Optimistic",Scenarios!E20,Scenarios!E32)) | I7: =IF($B$63="Base Case",Scenarios!F8,IF($B$63="Optimistic",Scenarios!F20,Scenarios!F32))
A8: R&D % of Revenue | B8: 0.05 | C8: 0.05 | D8: 0.05 | E8: =IF($B$63="Base Case",Scenarios!B9,IF($B$63="Optimistic",Scenarios!B21,Scenarios!B33)) | F8: =IF($B$63="Base Case",Scenarios!C9,IF($B$63="Optimistic",Scenarios!C21,Scenarios!C33)) | G8: =IF($B$63="Base Case",Scenarios!D9,IF($B$63="Optimistic",Scenarios!D21,Scenarios!D33)) | H8: =IF($B$63="Base Case",Scenarios!E9,IF($B$63="Optimistic",Scenarios!E21,Scenarios!E33)) | I8: =IF($B$63="Base Case",Scenarios!F9,IF($B$63="Optimistic",Scenarios!F21,Scenarios!F33))
A9: Other OpEx % of Revenue | B9: 0.02 | C9: 0.02 | D9: 0.02 | E9: =IF($B$63="Base Case",Scenarios!B10,IF($B$63="Optimistic",Scenarios!B22,Scenarios!B34)) | F9: =IF($B$63="Base Case",Scenarios!C10,IF($B$63="Optimistic",Scenarios!C22,Scenarios!C34)) | G9: =IF($B$63="Base Case",Scenarios!D10,IF($B$63="Optimistic",Scenarios!D22,Scenarios!D34)) | H9: =IF($B$63="Base Case",Scenarios!E10,IF($B$63="Optimistic",Scenarios!E22,Scenarios!E34)) | I9: =IF($B$63="Base Case",Scenarios!F10,IF($B$63="Optimistic",Scenarios!F22,Scenarios!F34))
A10: Tax Rate | B10: 0.2513587 | C10: 0.25230415 | D10: 0.25201613 | E10: =IF($B$63="Base Case",Scenarios!B11,IF($B$63="Optimistic",Scenarios!B23,Scenarios!B35)) | F10: =IF($B$63="Base Case",Scenarios!C11,IF($B$63="Optimistic",Scenarios!C23,Scenarios!C35)) | G10: =IF($B$63="Base Case",Scenarios!D11,IF($B$63="Optimistic",Scenarios!D23,Scenarios!D35)) | H10: =IF($B$63="Base Case",Scenarios!E11,IF($B$63="Optimistic",Scenarios!E23,Scenarios!E35)) | I10: =IF($B$63="Base Case",Scenarios!F11,IF($B$63="Optimistic",Scenarios!F23,Scenarios!F35))
A11: Other Income / Expense | B11: 0 | C11: 0 | D11: 0 | E11: 0 | F11: 0 | G11: 0 | H11: 0 | I11: 0
A12: Shares Outstanding | B12: 100000 | C12: 100000 | D12: 100000 | E12: 100000 | F12: 100000 | G12: 100000 | H12: 100000 | I12: 100000
A13: Stock-Based Comp Amount | B13: 0 | C13: 0 | D13: 0 | E13: 10000 | F13: 10000 | G13: 10000 | H13: 10000 | I13: 10000
A14: ── Balance Sheet / WC Drivers ──
A15: DSO (Days) | B15: 45.00012 | C15: 45.000206 | D15: 44.999889 | E15: 45 | F15: 45 | G15: 45 | H15: 45 | I15: 45
A16: DIO (Days) | B16: 29.999756 | C16: 30.000137 | D16: 29.999798 | E16: 30 | F16: 30 | G16: 30 | H16: 30 | I16: 30
A17: DPO (Days) | B17: 39.999944 | C17: 39.999706 | D17: 40.000158 | E17: 40 | F17: 40 | G17: 40 | H17: 40 | I17: 40
A18: Prepaid % of Revenue | B18: 0.01 | C18: 0.01 | D18: 0.01 | E18: 0.01 | F18: 0.01 | G18: 0.01 | H18: 0.01 | I18: 0.01
A19: Accrued Exp % of Revenue | B19: 0.03 | C19: 0.03 | D19: 0.03 | E19: 0.03 | F19: 0.03 | G19: 0.03 | H19: 0.03 | I19: 0.03
A20: Deferred Rev % of Revenue | B20: 0.02 | C20: 0.02 | D20: 0.02 | E20: 0.02 | F20: 0.02 | G20: 0.02 | H20: 0.02 | I20: 0.02
A21: ── CapEx & Depreciation Drivers ──
A22: CapEx % of Revenue | B22: 0 | C22: 0.047058824 | D22: 0.047368421 | E22: =IF($B$63="Base Case",Scenarios!B12,IF($B$63="Optimistic",Scenarios!B24,Scenarios!B36)) | F22: =IF($B$63="Base Case",Scenarios!C12,IF($B$63="Optimistic",Scenarios!C24,Scenarios!C36)) | G22: =IF($B$63="Base Case",Scenarios!D12,IF($B$63="Optimistic",Scenarios!D24,Scenarios!D36)) | H22: =IF($B$63="Base Case",Scenarios!E12,IF($B$63="Optimistic",Scenarios!E24,Scenarios!E36)) | I22: =IF($B$63="Base Case",Scenarios!F12,IF($B$63="Optimistic",Scenarios!F24,Scenarios!F36))
A23: Depreciation Rate (% Gross PPE) | B23: 0.083333333 | C23: 0.082352941 | D23: 0.083116883 | E23: 0.1 | F23: 0.1 | G23: 0.1 | H23: 0.1 | I23: 0.1
A24: Amortization Amount | B24: 5000 | C24: 5000 | D24: 5000 | E24: 5000 | F24: 5000 | G24: 5000 | H24: 5000 | I24: 5000
A25: ── Debt & Financing ──
A26: Interest Rate (on Debt) | B26: 0.2 | C26: 0.2 | D26: 0.2 | E26: =IF($B$63="Base Case",Scenarios!B13,IF($B$63="Optimistic",Scenarios!B25,Scenarios!B37)) | F26: =IF($B$63="Base Case",Scenarios!C13,IF($B$63="Optimistic",Scenarios!C25,Scenarios!C37)) | G26: =IF($B$63="Base Case",Scenarios!D13,IF($B$63="Optimistic",Scenarios!D25,Scenarios!D37)) | H26: =IF($B$63="Base Case",Scenarios!E13,IF($B$63="Optimistic",Scenarios!E25,Scenarios!E37)) | I26: =IF($B$63="Base Case",Scenarios!F13,IF($B$63="Optimistic",Scenarios!F25,Scenarios!F37))
A27: Interest Income Rate (on Cash) | B27: 0.02 | C27: 0.02 | D27: 0.02 | E27: 0.02 | F27: 0.02 | G27: 0.02 | H27: 0.02 | I27: 0.02
A28: Short-Term Debt | B28: 50000 | C28: 50000 | D28: 50000 | E28: 50000 | F28: 50000 | G28: 50000 | H28: 50000 | I28: 50000
A29: LT Debt Issuance | B29: 0 | C29: 0 | D29: 0 | E29: 0 | F29: 0 | G29: 0 | H29: 0 | I29: 0
A30: LT Debt Repayment | B30: 0 | C30: 20000 | D30: 20000 | E30: 20000 | F30: 20000 | G30: 20000 | H30: 20000 | I30: 20000
A31: Current Portion LTD | B31: 20000 | C31: 20000 | D31: 20000 | E31: 20000 | F31: 20000 | G31: 20000 | H31: 20000 | I31: 20000
A32: Dividend Payout Ratio | B32: 0 | C32: 0.39986441 | D32: 0.46433423 | E32: =IF($B$63="Base Case",Scenarios!B14,IF($B$63="Optimistic",Scenarios!B26,Scenarios!B38)) | F32: =IF($B$63="Base Case",Scenarios!C14,IF($B$63="Optimistic",Scenarios!C26,Scenarios!C38)) | G32: =IF($B$63="Base Case",Scenarios!D14,IF($B$63="Optimistic",Scenarios!D26,Scenarios!D38)) | H32: =IF($B$63="Base Case",Scenarios!E14,IF($B$63="Optimistic",Scenarios!E26,Scenarios!E38)) | I32: =IF($B$63="Base Case",Scenarios!F14,IF($B$63="Optimistic",Scenarios!F26,Scenarios!F38))
A33: Share Repurchase Amount | B33: 0 | C33: 0 | D33: 0 | E33: 0 | F33: 0 | G33: 0 | H33: 0 | I33: 0
A34: Equity Issuance | B34: 0 | C34: 10000 | D34: 10000 | E34: 0 | F34: 0 | G34: 0 | H34: 0 | I34: 0
A35: ── BS / Equity Direct Values ──
A36: Goodwill | B36: 100000 | C36: 100000 | D36: 100000 | E36: 100000 | F36: 100000 | G36: 100000 | H36: 100000 | I36: 100000
A37: Other Current Assets | B37: 10000 | C37: 10000 | D37: 10000 | E37: 10000 | F37: 10000 | G37: 10000 | H37: 10000 | I37: 10000
A38: Other Long-Term Assets | B38: 20000 | C38: 20000 | D38: 20000 | E38: 20000 | F38: 20000 | G38: 20000 | H38: 20000 | I38: 20000
A39: Other Current Liabilities | B39: 15000 | C39: 15000 | D39: 15000 | E39: 15000 | F39: 15000 | G39: 15000 | H39: 15000 | I39: 15000
A40: Deferred Tax Liabilities | B40: 30000 | C40: 30000 | D40: 30000 | E40: 30000 | F40: 30000 | G40: 30000 | H40: 30000 | I40: 30000
...

Sheet Income Statement
A1: ="'" & 'Company Info'!B4 & "' — Income Statement" | B1: 2021 (A) | C1: 2022 (A) | D1: 2023 (A) | E1: 2024E | F1: 2025E | G1: 2026E | H1: 2027E | I1: 2028E
A2: Revenue | B2: =Assumptions!B3 | C2: =B2*(1+Assumptions!C5) | D2: =C2*(1+Assumptions!D5) | E2: =D2*(1+Assumptions!E5) | F2: =E2*(1+Assumptions!F5) | G2: =F2*(1+Assumptions!G5) | H2: =G2*(1+Assumptions!H5) | I2: =H2*(1+Assumptions!I5)
A3: Revenue Growth % | B3: =Assumptions!B5 | C3: =Assumptions!C5 | D3: =Assumptions!D5 | E3: =Assumptions!E5 | F3: =Assumptions!F5 | G3: =Assumptions!G5 | H3: =Assumptions!H5 | I3: =Assumptions!I5
A4: Cost of Goods Sold | B4: =B2*Assumptions!B6 | C4: =C2*Assumptions!C6 | D4: =D2*Assumptions!D6 | E4: =E2*Assumptions!E6 | F4: =F2*Assumptions!F6 | G4: =G2*Assumptions!G6 | H4: =H2*Assumptions!H6 | I4: =I2*Assumptions!I6
A5: Gross Profit | B5: =B2-B4 | C5: =C2-C4 | D5: =D2-D4 | E5: =E2-E4 | F5: =F2-F4 | G5: =G2-G4 | H5: =H2-H4 | I5: =I2-I4
A6: Gross Margin | B6: =IF(B2=0,0,B5/B2) | C6: =IF(C2=0,0,C5/C2) | D6: =IF(D2=0,0,D5/D2) | E6: =IF(E2=0,0,E5/E2) | F6: =IF(F2=0,0,F5/F2) | G6: =IF(G2=0,0,G5/G2) | H6: =IF(H2=0,0,H5/H2) | I6: =IF(I2=0,0,I5/I2)
A8: Operating Expenses
A9: SG&A | B9: =B2*Assumptions!B7 | C9: =C2*Assumptions!C7 | D9: =D2*Assumptions!D7 | E9: =E2*Assumptions!E7 | F9: =F2*Assumptions!F7 | G9: =G2*Assumptions!G7 | H9: =H2*Assumptions!H7 | I9: =I2*Assumptions!I7
A10: R&D | B10: =B2*Assumptions!B8 | C10: =C2*Assumptions!C8 | D10: =D2*Assumptions!D8 | E10: =E2*Assumptions!E8 | F10: =F2*Assumptions!F8 | G10: =G2*Assumptions!G8 | H10: =H2*Assumptions!H8 | I10: =I2*Assumptions!I8
A11: Depreciation | B11: =Assumptions!B48 | C11: =Assumptions!C48 | D11: =Assumptions!D48 | E11: =Assumptions!E48 | F11: =Assumptions!F48 | G11: =Assumptions!G48 | H11: =Assumptions!H48 | I11: =Assumptions!I48
A12: Amortization | B12: =Assumptions!B24 | C12: =Assumptions!C24 | D12: =Assumptions!D24 | E12: =Assumptions!E24 | F12: =Assumptions!F24 | G12: =Assumptions!G24 | H12: =Assumptions!H24 | I12: =Assumptions!I24
A13: Other OpEx | B13: =B2*Assumptions!B9 | C13: =C2*Assumptions!C9 | D13: =D2*Assumptions!D9 | E13: =E2*Assumptions!E9 | F13: =F2*Assumptions!F9 | G13: =G2*Assumptions!G9 | H13: =H2*Assumptions!H9 | I13: =I2*Assumptions!I9
A14: Stock-Based Comp | B14: =Assumptions!B13 | C14: =Assumptions!C13 | D14: =Assumptions!D13 | E14: =Assumptions!E13 | F14: =Assumptions!F13 | G14: =Assumptions!G13 | H14: =Assumptions!H13 | I14: =Assumptions!I13
A15: Total OpEx | B15: =B9+B10+B11+B12+B13+B14 | C15: =C9+C10+C11+C12+C13+C14 | D15: =D9+D10+D11+D12+D13+D14 | E15: =E9+E10+E11+E12+E13+E14 | F15: =F9+F10+F11+F12+F13+F14 | G15: =G9+G10+G11+G12+G13+G14 | H15: =H9+H10+H11+H12+H13+H14 | I15: =I9+I10+I11+I12+I13+I14
A17: EBIT | B17: =B5-B15 | C17: =C5-C15 | D17: =D5-D15 | E17: =E5-E15 | F17: =F5-F15 | G17: =G5-G15 | H17: =H5-H15 | I17: =I5-I15
A18: EBITDA | B18: =B17+B11+B12 | C18: =C17+C11+C12 | D18: =D17+D11+D12 | E18: =E17+E11+E12 | F18: =F17+F11+F12 | G18: =G17+G11+G12 | H18: =H17+H11+H12 | I18: =I17+I11+I12
A19: EBIT Margin | B19: =IF(B2=0,0,B17/B2) | C19: =IF(C2=0,0,C17/C2) | D19: =IF(D2=0,0,D17/D2) | E19: =IF(E2=0,0,E17/E2) | F19: =IF(F2=0,0,F17/F2) | G19: =IF(G2=0,0,G17/G2) | H19: =IF(H2=0,0,H17/H2) | I19: =IF(I2=0,0,I17/I2)
A21: Interest Income | B21: =Assumptions!B46 | C21: =Assumptions!C46 | D21: =Assumptions!D46 | E21: =Assumptions!E46 | F21: =Assumptions!F46 | G21: =Assumptions!G46 | H21: =Assumptions!H46 | I21: =Assumptions!I46
A22: Interest Expense | B22: =Assumptions!B47 | C22: =Assumptions!C47 | D22: =Assumptions!D47 | E22: =Assumptions!E47 | F22: =Assumptions!F47 | G22: =Assumptions!G47 | H22: =Assumptions!H47 | I22: =Assumptions!I47
A23: Other Income/Expense | B23: =Assumptions!B11 | C23: =Assumptions!C11 | D23: =Assumptions!D11 | E23: =Assumptions!E11 | F23: =Assumptions!F11 | G23: =Assumptions!G11 | H23: =Assumptions!H11 | I23: =Assumptions!I11
A24: EBT | B24: =B17+B21-B22+B23 | C24: =C17+C21-C22+C23 | D24: =D17+D21-D22+D23 | E24: =E17+E21-E22+E23 | F24: =F17+F21-F22+F23 | G24: =G17+G21-G22+G23 | H24: =H17+H21-H22+H23 | I24: =I17+I21-I22+I23
A25: Tax Expense | B25: =MAX(0,B24*Assumptions!B10) | C25: =MAX(0,C24*Assumptions!C10) | D25: =MAX(0,D24*Assumptions!D10) | E25: =MAX(0,E24*Assumptions!E10) | F25: =MAX(0,F24*Assumptions!F10) | G25: =MAX(0,G24*Assumptions!G10) | H25: =MAX(0,H24*Assumptions!H10) | I25: =MAX(0,I24*Assumptions!I10)
A26: Tax Rate | B26: =Assumptions!B10 | C26: =Assumptions!C10 | D26: =Assumptions!D10 | E26: =Assumptions!E10 | F26: =Assumptions!F10 | G26: =Assumptions!G10 | H26: =Assumptions!H10 | I26: =Assumptions!I10
A28: Net Income | B28: =B24-B25 | C28: =C24-C25 | D28: =D24-D25 | E28: =E24-E25 | F28: =F24-F25 | G28: =G24-G25 | H28: =H24-H25 | I28: =I24-I25
A29: Net Margin | B29: =IF(B2=0,0,B28/B2) | C29: =IF(C2=0,0,C28/C2) | D29: =IF(D2=0,0,D28/D2) | E29: =IF(E2=0,0,E28/E2) | F29: =IF(F2=0,0,F28/F2) | G29: =IF(G2=0,0,G28/G2) | H29: =IF(H2=0,0,H28/H2) | I29: =IF(I2=0,0,I28/I2)
A30: EPS | B30: =IF(Assumptions!B12=0,0,B28/Assumptions!B12) | C30: =IF(Assumptions!C12=0,0,C28/Assumptions!C12) | D30: =IF(Assumptions!D12=0,0,D28/Assumptions!D12) | E30: =IF(Assumptions!E12=0,0,E28/Assumptions!E12) | F30: =IF(Assumptions!F12=0,0,F28/Assumptions!F12) | G30: =IF(Assumptions!G12=0,0,G28/Assumptions!G12) | H30: =IF(Assumptions!H12=0,0,H28/Assumptions!H12) | I30: =IF(Assumptions!I12=0,0,I28/Assumptions!I12)
A31: Stock-Based Compensation | B31: =Assumptions!B13 | C31: =Assumptions!C13 | D31: =Assumptions!D13 | E31: =Assumptions!E13 | F31: =Assumptions!F13 | G31: =Assumptions!G13 | H31: =Assumptions!H13 | I31: =Assumptions!I13

Sheet Balance Sheet
A1: ="'" & 'Company Info'!B4 & "' — Balance Sheet" | B1: 2021 (A) | C1: 2022 (A) | D1: 2023 (A) | E1: 2024E | F1: 2025E | G1: 2026E | H1: 2027E | I1: 2028E
A2: ASSETS
A3: Cash & Equivalents | B3: =B40-B4-B5-B6-B7-B14 | C3: =C40-C4-C5-C6-C7-C14 | D3: =D40-D4-D5-D6-D7-D14 | E3: =E40-E4-E5-E6-E7-E14 | F3: =F40-F4-F5-F6-F7-F14 | G3: =G40-G4-G5-G6-G7-G14 | H3: =H40-H4-H5-H6-H7-H14 | I3: =I40-I4-I5-I6-I7-I14
A4: Accounts Receivable | B4: ='Income Statement'!B2*Assumptions!B15/365 | C4: ='Income Statement'!C2*Assumptions!C15/365 | D4: ='Income Statement'!D2*Assumptions!D15/365 | E4: ='Income Statement'!E2*Assumptions!E15/365 | F4: ='Income Statement'!F2*Assumptions!F15/365 | G4: ='Income Statement'!G2*Assumptions!G15/365 | H4: ='Income Statement'!H2*Assumptions!H15/365 | I4: ='Income Statement'!I2*Assumptions!I15/365
A5: Inventory | B5: ='Income Statement'!B4*Assumptions!B16/365 | C5: ='Income Statement'!C4*Assumptions!C16/365 | D5: ='Income Statement'!D4*Assumptions!D16/365 | E5: ='Income Statement'!E4*Assumptions!E16/365 | F5: ='Income Statement'!F4*Assumptions!F16/365 | G5: ='Income Statement'!G4*Assumptions!G16/365 | H5: ='Income Statement'!H4*Assumptions!H16/365 | I5: ='Income Statement'!I4*Assumptions!I16/365
A6: Prepaid Expenses | B6: ='Income Statement'!B2*Assumptions!B18 | C6: ='Income Statement'!C2*Assumptions!C18 | D6: ='Income Statement'!D2*Assumptions!D18 | E6: ='Income Statement'!E2*Assumptions!E18 | F6: ='Income Statement'!F2*Assumptions!F18 | G6: ='Income Statement'!G2*Assumptions!G18 | H6: ='Income Statement'!H2*Assumptions!H18 | I6: ='Income Statement'!I2*Assumptions!I18
A7: Other Current Assets | B7: =Assumptions!B37 | C7: =Assumptions!C37 | D7: =Assumptions!D37 | E7: =Assumptions!E37 | F7: =Assumptions!F37 | G7: =Assumptions!G37 | H7: =Assumptions!H37 | I7: =Assumptions!I37
A8: Total Current Assets | B8: =SUM(B3:B7) | C8: =SUM(C3:C7) | D8: =SUM(D3:D7) | E8: =SUM(E3:E7) | F8: =SUM(F3:F7) | G8: =SUM(G3:G7) | H8: =SUM(H3:H7) | I8: =SUM(I3:I7)
A10: Net PP&E | B10: =Assumptions!B51 | C10: =Assumptions!C51 | D10: =Assumptions!D51 | E10: =Assumptions!E51 | F10: =Assumptions!F51 | G10: =Assumptions!G51 | H10: =Assumptions!H51 | I10: =Assumptions!I51
A11: Intangibles | B11: =Assumptions!B52 | C11: =Assumptions!C52 | D11: =Assumptions!D52 | E11: =Assumptions!E52 | F11: =Assumptions!F52 | G11: =Assumptions!G52 | H11: =Assumptions!H52 | I11: =Assumptions!I52
A12: Goodwill | B12: =Assumptions!B36 | C12: =Assumptions!C36 | D12: =Assumptions!D36 | E12: =Assumptions!E36 | F12: =Assumptions!F36 | G12: =Assumptions!G36 | H12: =Assumptions!H36 | I12: =Assumptions!I36
A13: Other Long-Term Assets | B13: =Assumptions!B38 | C13: =Assumptions!C38 | D13: =Assumptions!D38 | E13: =Assumptions!E38 | F13: =Assumptions!F38 | G13: =Assumptions!G38 | H13: =Assumptions!H38 | I13: =Assumptions!I38
A14: Total Non-Current Assets | B14: =SUM(B10:B13) | C14: =SUM(C10:C13) | D14: =SUM(D10:D13) | E14: =SUM(E10:E13) | F14: =SUM(F10:F13) | G14: =SUM(G10:G13) | H14: =SUM(H10:H13) | I14: =SUM(I10:I13)
A15: Total Assets | B15: =B8+B14 | C15: =C8+C14 | D15: =D8+D14 | E15: =E8+E14 | F15: =F8+F14 | G15: =G8+G14 | H15: =H8+H14 | I15: =I8+I14
A17: LIABILITIES
A18: Accounts Payable | B18: ='Income Statement'!B4*Assumptions!B17/365 | C18: ='Income Statement'!C4*Assumptions!C17/365 | D18: ='Income Statement'!D4*Assumptions!D17/365 | E18: ='Income Statement'!E4*Assumptions!E17/365 | F18: ='Income Statement'!F4*Assumptions!F17/365 | G18: ='Income Statement'!G4*Assumptions!G17/365 | H18: ='Income Statement'!H4*Assumptions!H17/365 | I18: ='Income Statement'!I4*Assumptions!I17/365
A19: Accrued Expenses | B19: ='Income Statement'!B2*Assumptions!B19 | C19: ='Income Statement'!C2*Assumptions!C19 | D19: ='Income Statement'!D2*Assumptions!D19 | E19: ='Income Statement'!E2*Assumptions!E19 | F19: ='Income Statement'!F2*Assumptions!F19 | G19: ='Income Statement'!G2*Assumptions!G19 | H19: ='Income Statement'!H2*Assumptions!H19 | I19: ='Income Statement'!I2*Assumptions!I19
A20: Short-Term Debt | B20: =Assumptions!B28 | C20: =Assumptions!C28 | D20: =Assumptions!D28 | E20: =Assumptions!E28 | F20: =Assumptions!F28 | G20: =Assumptions!G28 | H20: =Assumptions!H28 | I20: =Assumptions!I28
A21: Current Portion LTD | B21: =Assumptions!B31 | C21: =Assumptions!C31 | D21: =Assumptions!D31 | E21: =Assumptions!E31 | F21: =Assumptions!F31 | G21: =Assumptions!G31 | H21: =Assumptions!H31 | I21: =Assumptions!I31
A22: Deferred Revenue | B22: ='Income Statement'!B2*Assumptions!B20 | C22: ='Income Statement'!C2*Assumptions!C20 | D22: ='Income Statement'!D2*Assumptions!D20 | E22: ='Income Statement'!E2*Assumptions!E20 | F22: ='Income Statement'!F2*Assumptions!F20 | G22: ='Income Statement'!G2*Assumptions!G20 | H22: ='Income Statement'!H2*Assumptions!H20 | I22: ='Income Statement'!I2*Assumptions!I20
A23: Other Current Liabilities | B23: =Assumptions!B39 | C23: =Assumptions!C39 | D23: =Assumptions!D39 | E23: =Assumptions!E39 | F23: =Assumptions!F39 | G23: =Assumptions!G39 | H23: =Assumptions!H39 | I23: =Assumptions!I39
A24: Total Current Liabilities | B24: =SUM(B18:B23) | C24: =SUM(C18:C23) | D24: =SUM(D18:D23) | E24: =SUM(E18:E23) | F24: =SUM(F18:F23) | G24: =SUM(G18:G23) | H24: =SUM(H18:H23) | I24: =SUM(I18:I23)
A26: Long-Term Debt | B26: =Assumptions!B53 | C26: =Assumptions!C53 | D26: =Assumptions!D53 | E26: =Assumptions!E53 | F26: =Assumptions!F53 | G26: =Assumptions!G53 | H26: =Assumptions!H53 | I26: =Assumptions!I53
A27: Deferred Tax Liabilities | B27: =Assumptions!B40 | C27: =Assumptions!C40 | D27: =Assumptions!D40 | E27: =Assumptions!E40 | F27: =Assumptions!F40 | G27: =Assumptions!G40 | H27: =Assumptions!H40 | I27: =Assumptions!I40
A28: Other LT Liabilities | B28: =Assumptions!B41 | C28: =Assumptions!C41 | D28: =Assumptions!D41 | E28: =Assumptions!E41 | F28: =Assumptions!F41 | G28: =Assumptions!G41 | H28: =Assumptions!H41 | I28: =Assumptions!I41
A29: Total Non-Current Liabilities | B29: =SUM(B26:B28) | C29: =SUM(C26:C28) | D29: =SUM(D26:D28) | E29: =SUM(E26:E28) | F29: =SUM(F26:F28) | G29: =SUM(G26:G28) | H29: =SUM(H26:H28) | I29: =SUM(I26:I28)
A30: Total Liabilities | B30: =B24+B29 | C30: =C24+C29 | D30: =D24+D29 | E30: =E24+E29 | F30: =F24+F29 | G30: =G24+G29 | H30: =H24+H29 | I30: =I24+I29
A32: EQUITY
A33: Common Stock | B33: =Assumptions!B42 | C33: =Assumptions!C42 | D33: =Assumptions!D42 | E33: =Assumptions!E42 | F33: =Assumptions!F42 | G33: =Assumptions!G42 | H33: =Assumptions!H42 | I33: =Assumptions!I42
A34: Additional Paid-in Capital | B34: =Assumptions!B56 | C34: =Assumptions!C56 | D34: =Assumptions!D56 | E34: =Assumptions!E56 | F34: =Assumptions!F56 | G34: =Assumptions!G56 | H34: =Assumptions!H56 | I34: =Assumptions!I56
A35: Retained Earnings | B35: =Assumptions!B54 | C35: =Assumptions!C54 | D35: =Assumptions!D54 | E35: =Assumptions!E54 | F35: =Assumptions!F54 | G35: =Assumptions!G54 | H35: =Assumptions!H54 | I35: =Assumptions!I54
A36: Treasury Stock | B36: =Assumptions!B55 | C36: =Assumptions!C55 | D36: =Assumptions!D55 | E36: =Assumptions!E55 | F36: =Assumptions!F55 | G36: =Assumptions!G55 | H36: =Assumptions!H55 | I36: =Assumptions!I55
A37: Other Comprehensive Income | B37: =Assumptions!B44 | C37: =Assumptions!C44 | D37: =Assumptions!D44 | E37: =Assumptions!E44 | F37: =Assumptions!F44 | G37: =Assumptions!G44 | H37: =Assumptions!H44 | I37: =Assumptions!I44
A38: Total Equity | B38: =SUM(B33:B37) | C38: =SUM(C33:C37) | D38: =SUM(D33:D37) | E38: =SUM(E33:E37) | F38: =SUM(F33:F37) | G38: =SUM(G33:G37) | H38: =SUM(H33:H37) | I38: =SUM(I33:I37)
A40: Total Liabilities + Equity | B40: =B30+B38 | C40: =C30+C38 | D40: =D30+D38 | E40: =E30+E38 | F40: =F30+F38 | G40: =G30+G38 | H40: =H30+H38 | I40: =I30+I38
A41: Balance Check (A − L+E) | B41: =B15-B40 | C41: =C15-C40 | D41: =D15-D40 | E41: =E15-E40 | F41: =F15-F40 | G41: =G15-G40 | H41: =H15-H40 | I41: =I15-I40
A42: Balanced? | B42: =IF(ABS(B41)<1,"✓ Balanced","✗ Imbalanced") | C42: =IF(ABS(C41)<1,"✓ Balanced","✗ Imbalanced") | D42: =IF(ABS(D41)<1,"✓ Balanced","✗ Imbalanced") | E42: =IF(ABS(E41)<1,"✓ Balanced","✗ Imbalanced") | F42: =IF(ABS(F41)<1,"✓ Balanced","✗ Imbalanced") | G42: =IF(ABS(G41)<1,"✓ Balanced","✗ Imbalanced") | H42: =IF(ABS(H41)<1,"✓ Balanced","✗ Imbalanced") | I42: =IF(ABS(I41)<1,"✓ Balanced","✗ Imbalanced")

Sheet Cash Flow Statement
A1: ="'" & 'Company Info'!B4 & "' — Cash Flow Statement" | B1: 2022 (A) | C1: 2023 (A) | D1: 2024E | E1: 2025E | F1: 2026E | G1: 2027E | H1: 2028E
A2: Operating Activities
A3: Net Income | B3: ='Income Statement'!C28 | C3: ='Income Statement'!D28 | D3: ='Income Statement'!E28 | E3: ='Income Statement'!F28 | F3: ='Income Statement'!G28 | G3: ='Income Statement'!H28 | H3: ='Income Statement'!I28
A4: Depreciation | B4: ='Income Statement'!C11 | C4: ='Income Statement'!D11 | D4: ='Income Statement'!E11 | E4: ='Income Statement'!F11 | F4: ='Income Statement'!G11 | G4: ='Income Statement'!H11 | H4: ='Income Statement'!I11
A5: Amortization | B5: ='Income Statement'!C12 | C5: ='Income Statement'!D12 | D5: ='Income Statement'!E12 | E5: ='Income Statement'!F12 | F5: ='Income Statement'!G12 | G5: ='Income Statement'!H12 | H5: ='Income Statement'!I12
A6: Stock-Based Compensation | B6: ='Income Statement'!C31 | C6: ='Income Statement'!D31 | D6: ='Income Statement'!E31 | E6: ='Income Statement'!F31 | F6: ='Income Statement'!G31 | G6: ='Income Statement'!H31 | H6: ='Income Statement'!I31
A7: Deferred Taxes | B7: ='Balance Sheet'!C27-'Balance Sheet'!B27 | C7: ='Balance Sheet'!D27-'Balance Sheet'!C27 | D7: ='Balance Sheet'!E27-'Balance Sheet'!D27 | E7: ='Balance Sheet'!F27-'Balance Sheet'!E27 | F7: ='Balance Sheet'!G27-'Balance Sheet'!F27 | G7: ='Balance Sheet'!H27-'Balance Sheet'!G27 | H7: ='Balance Sheet'!I27-'Balance Sheet'!H27
A8: Working Capital Changes
A9: Change in A/R | B9: =-('Balance Sheet'!C4-'Balance Sheet'!B4) | C9: =-('Balance Sheet'!D4-'Balance Sheet'!C4) | D9: =-('Balance Sheet'!E4-'Balance Sheet'!D4) | E9: =-('Balance Sheet'!F4-'Balance Sheet'!E4) | F9: =-('Balance Sheet'!G4-'Balance Sheet'!F4) | G9: =-('Balance Sheet'!H4-'Balance Sheet'!G4) | H9: =-('Balance Sheet'!I4-'Balance Sheet'!H4)
A10: Change in Inventory | B10: =-('Balance Sheet'!C5-'Balance Sheet'!B5) | C10: =-('Balance Sheet'!D5-'Balance Sheet'!C5) | D10: =-('Balance Sheet'!E5-'Balance Sheet'!D5) | E10: =-('Balance Sheet'!F5-'Balance Sheet'!E5) | F10: =-('Balance Sheet'!G5-'Balance Sheet'!F5) | G10: =-('Balance Sheet'!H5-'Balance Sheet'!G5) | H10: =-('Balance Sheet'!I5-'Balance Sheet'!H5)
A11: Change in Prepaid | B11: =-('Balance Sheet'!C6-'Balance Sheet'!B6) | C11: =-('Balance Sheet'!D6-'Balance Sheet'!C6) | D11: =-('Balance Sheet'!E6-'Balance Sheet'!D6) | E11: =-('Balance Sheet'!F6-'Balance Sheet'!E6) | F11: =-('Balance Sheet'!G6-'Balance Sheet'!F6) | G11: =-('Balance Sheet'!H6-'Balance Sheet'!G6) | H11: =-('Balance Sheet'!I6-'Balance Sheet'!H6)
A12: Change in A/P | B12: ='Balance Sheet'!C18-'Balance Sheet'!B18 | C12: ='Balance Sheet'!D18-'Balance Sheet'!C18 | D12: ='Balance Sheet'!E18-'Balance Sheet'!D18 | E12: ='Balance Sheet'!F18-'Balance Sheet'!E18 | F12: ='Balance Sheet'!G18-'Balance Sheet'!F18 | G12: ='Balance Sheet'!H18-'Balance Sheet'!G18 | H12: ='Balance Sheet'!I18-'Balance Sheet'!H18
A13: Change in Accrued Exp | B13: ='Balance Sheet'!C19-'Balance Sheet'!B19 | C13: ='Balance Sheet'!D19-'Balance Sheet'!C19 | D13: ='Balance Sheet'!E19-'Balance Sheet'!D19 | E13: ='Balance Sheet'!F19-'Balance Sheet'!E19 | F13: ='Balance Sheet'!G19-'Balance Sheet'!F19 | G13: ='Balance Sheet'!H19-'Balance Sheet'!G19 | H13: ='Balance Sheet'!I19-'Balance Sheet'!H19
A14: Change in Deferred Rev | B14: ='Balance Sheet'!C22-'Balance Sheet'!B22 | C14: ='Balance Sheet'!D22-'Balance Sheet'!C22 | D14: ='Balance Sheet'!E22-'Balance Sheet'!D22 | E14: ='Balance Sheet'!F22-'Balance Sheet'!E22 | F14: ='Balance Sheet'!G22-'Balance Sheet'!F22 | G14: ='Balance Sheet'!H22-'Balance Sheet'!G22 | H14: ='Balance Sheet'!I22-'Balance Sheet'!H22
A15: Total WC Change | B15: =SUM(B9:B14) | C15: =SUM(C9:C14) | D15: =SUM(D9:D14) | E15: =SUM(E9:E14) | F15: =SUM(F9:F14) | G15: =SUM(G9:G14) | H15: =SUM(H9:H14)
A16: Cash from Operations | B16: =B3+B4+B5+B6+B7+B15 | C16: =C3+C4+C5+C6+C7+C15 | D16: =D3+D4+D5+D6+D7+D15 | E16: =E3+E4+E5+E6+E7+E15 | F16: =F3+F4+F5+F6+F7+F15 | G16: =G3+G4+G5+G6+G7+G15 | H16: =H3+H4+H5+H6+H7+H15
A18: Investing Activities
A19: Capital Expenditures | B19: =-ABS('Income Statement'!C2*Assumptions!C22) | C19: =-ABS('Income Statement'!D2*Assumptions!D22) | D19: =-ABS('Income Statement'!E2*Assumptions!E22) | E19: =-ABS('Income Statement'!F2*Assumptions!F22) | F19: =-ABS('Income Statement'!G2*Assumptions!G22) | G19: =-ABS('Income Statement'!H2*Assumptions!H22) | H19: =-ABS('Income Statement'!I2*Assumptions!I22)
A20: Acquisitions | B20: =Assumptions!C60 | C20: =Assumptions!D60 | D20: =Assumptions!E60 | E20: =Assumptions!F60 | F20: =Assumptions!G60 | G20: =Assumptions!H60 | H20: =Assumptions!I60
A21: Asset Sales | B21: =Assumptions!C61 | C21: =Assumptions!D61 | D21: =Assumptions!E61 | E21: =Assumptions!F61 | F21: =Assumptions!G61 | G21: =Assumptions!H61 | H21: =Assumptions!I61
A22: Cash from Investing | B22: =B19+B20+B21 | C22: =C19+C20+C21 | D22: =D19+D20+D21 | E22: =E19+E20+E21 | F22: =F19+F20+F21 | G22: =G19+G20+G21 | H22: =H19+H20+H21
A24: Financing Activities
A25: Debt Issuance | B25: =Assumptions!C29 | C25: =Assumptions!D29 | D25: =Assumptions!E29 | E25: =Assumptions!F29 | F25: =Assumptions!G29 | G25: =Assumptions!H29 | H25: =Assumptions!I29
A26: Debt Repayment | B26: =-ABS(Assumptions!C30) | C26: =-ABS(Assumptions!D30) | D26: =-ABS(Assumptions!E30) | E26: =-ABS(Assumptions!F30) | F26: =-ABS(Assumptions!G30) | G26: =-ABS(Assumptions!H30) | H26: =-ABS(Assumptions!I30)
A27: Dividends Paid | B27: =Assumptions!C57 | C27: =Assumptions!D57 | D27: =-MAX(0,'Income Statement'!E28*Assumptions!E32) | E27: =-MAX(0,'Income Statement'!F28*Assumptions!F32) | F27: =-MAX(0,'Income Statement'!G28*Assumptions!G32) | G27: =-MAX(0,'Income Statement'!H28*Assumptions!H32) | H27: =-MAX(0,'Income Statement'!I28*Assumptions!I32)
A28: Equity Issuance | B28: =Assumptions!C58 | C28: =Assumptions!D58 | D28: =Assumptions!E34 | E28: =Assumptions!F34 | F28: =Assumptions!G34 | G28: =Assumptions!H34 | H28: =Assumptions!I34
A29: Share Repurchases | B29: =Assumptions!C59 | C29: =Assumptions!D59 | D29: =-ABS(Assumptions!E33) | E29: =-ABS(Assumptions!F33) | F29: =-ABS(Assumptions!G33) | G29: =-ABS(Assumptions!H33) | H29: =-ABS(Assumptions!I33)
A30: Cash from Financing | B30: =B25+B26+B27+B28+B29 | C30: =C25+C26+C27+C28+C29 | D30: =D25+D26+D27+D28+D29 | E30: =E25+E26+E27+E28+E29 | F30: =F25+F26+F27+F28+F29 | G30: =G25+G26+G27+G28+G29 | H30: =H25+H26+H27+H28+H29
A32: Net Change in Cash | B32: =B16+B22+B30 | C32: =C16+C22+C30 | D32: =D16+D22+D30 | E32: =E16+E22+E30 | F32: =F16+F22+F30 | G32: =G16+G22+G30 | H32: =H16+H22+H30
A33: Beginning Cash | B33: ='Balance Sheet'!B3 | C33: ='Balance Sheet'!C3 | D33: ='Balance Sheet'!D3 | E33: ='Balance Sheet'!E3 | F33: ='Balance Sheet'!F3 | G33: ='Balance Sheet'!G3 | H33: ='Balance Sheet'!H3
A34: Ending Cash | B34: =B33+B32 | C34: =C33+C32 | D34: =D33+D32 | E34: =E33+E32 | F34: =F33+F32 | G34: =G33+G32 | H34: =H33+H32
A36: Free Cash Flow | B36: =B16+B19 | C36: =C16+C19 | D36: =D16+D19 | E36: =E16+E19 | F36: =F16+F19 | G36: =G16+G19 | H36: =H16+H19
A38: Reconciliation Check | B38: =IF(ABS(B34-'Balance Sheet'!C3)<0.01,"✓ Reconciles","✗ Error") | C38: =IF(ABS(C34-'Balance Sheet'!D3)<0.01,"✓ Reconciles","✗ Error") | D38: =IF(ABS(D34-'Balance Sheet'!E3)<0.01,"✓ Reconciles","✗ Error") | E38: =IF(ABS(E34-'Balance Sheet'!F3)<0.01,"✓ Reconciles","✗ Error") | F38: =IF(ABS(F34-'Balance Sheet'!G3)<0.01,"✓ Reconciles","✗ Error") | G38: =IF(ABS(G34-'Balance Sheet'!H3)<0.01,"✓ Reconciles","✗ Error") | H38: =IF(ABS(H34-'Balance Sheet'!I3)<0.01,"✓ Reconciles","✗ Error")

Sheet Ratios
A1: ="'" & 'Company Info'!B4 & "' — Financial Ratios" | B1: 2021 (A) | C1: 2022 (A) | D1: 2023 (A) | E1: 2024E | F1: 2025E | G1: 2026E | H1: 2027E | I1: 2028E
A2: ── Profitability ──
A3: Gross Margin | B3: =IF('Income Statement'!B2=0,0,'Income Statement'!B5/'Income Statement'!B2) | C3: =IF('Income Statement'!C2=0,0,'Income Statement'!C5/'Income Statement'!C2) | D3: =IF('Income Statement'!D2=0,0,'Income Statement'!D5/'Income Statement'!D2) | E3: =IF('Income Statement'!E2=0,0,'Income Statement'!E5/'Income Statement'!E2) | F3: =IF('Income Statement'!F2=0,0,'Income Statement'!F5/'Income Statement'!F2) | G3: =IF('Income Statement'!G2=0,0,'Income Statement'!G5/'Income Statement'!G2) | H3: =IF('Income Statement'!H2=0,0,'Income Statement'!H5/'Income Statement'!H2) | I3: =IF('Income Statement'!I2=0,0,'Income Statement'!I5/'Income Statement'!I2)
A4: Operating Margin | B4: =IF('Income Statement'!B2=0,0,'Income Statement'!B17/'Income Statement'!B2) | C4: =IF('Income Statement'!C2=0,0,'Income Statement'!C17/'Income Statement'!C2) | D4: =IF('Income Statement'!D2=0,0,'Income Statement'!D17/'Income Statement'!D2) | E4: =IF('Income Statement'!E2=0,0,'Income Statement'!E17/'Income Statement'!E2) | F4: =IF('Income Statement'!F2=0,0,'Income Statement'!F17/'Income Statement'!F2) | G4: =IF('Income Statement'!G2=0,0,'Income Statement'!G17/'Income Statement'!G2) | H4: =IF('Income Statement'!H2=0,0,'Income Statement'!H17/'Income Statement'!H2) | I4: =IF('Income Statement'!I2=0,0,'Income Statement'!I17/'Income Statement'!I2)
A5: Net Margin | B5: =IF('Income Statement'!B2=0,0,'Income Statement'!B28/'Income Statement'!B2) | C5: =IF('Income Statement'!C2=0,0,'Income Statement'!C28/'Income Statement'!C2) | D5: =IF('Income Statement'!D2=0,0,'Income Statement'!D28/'Income Statement'!D2) | E5: =IF('Income Statement'!E2=0,0,'Income Statement'!E28/'Income Statement'!E2) | F5: =IF('Income Statement'!F2=0,0,'Income Statement'!F28/'Income Statement'!F2) | G5: =IF('Income Statement'!G2=0,0,'Income Statement'!G28/'Income Statement'!G2) | H5: =IF('Income Statement'!H2=0,0,'Income Statement'!H28/'Income Statement'!H2) | I5: =IF('Income Statement'!I2=0,0,'Income Statement'!I28/'Income Statement'!I2)
A6: ROA | B6: =IF('Balance Sheet'!B15=0,0,'Income Statement'!B28/'Balance Sheet'!B15) | C6: =IF('Balance Sheet'!C15=0,0,'Income Statement'!C28/'Balance Sheet'!C15) | D6: =IF('Balance Sheet'!D15=0,0,'Income Statement'!D28/'Balance Sheet'!D15) | E6: =IF('Balance Sheet'!E15=0,0,'Income Statement'!E28/'Balance Sheet'!E15) | F6: =IF('Balance Sheet'!F15=0,0,'Income Statement'!F28/'Balance Sheet'!F15) | G6: =IF('Balance Sheet'!G15=0,0,'Income Statement'!G28/'Balance Sheet'!G15) | H6: =IF('Balance Sheet'!H15=0,0,'Income Statement'!H28/'Balance Sheet'!H15) | I6: =IF('Balance Sheet'!I15=0,0,'Income Statement'!I28/'Balance Sheet'!I15)
A7: ROE | B7: =IF('Balance Sheet'!B38=0,0,'Income Statement'!B28/'Balance Sheet'!B38) | C7: =IF('Balance Sheet'!C38=0,0,'Income Statement'!C28/'Balance Sheet'!C38) | D7: =IF('Balance Sheet'!D38=0,0,'Income Statement'!D28/'Balance Sheet'!D38) | E7: =IF('Balance Sheet'!E38=0,0,'Income Statement'!E28/'Balance Sheet'!E38) | F7: =IF('Balance Sheet'!F38=0,0,'Income Statement'!F28/'Balance Sheet'!F38) | G7: =IF('Balance Sheet'!G38=0,0,'Income Statement'!G28/'Balance Sheet'!G38) | H7: =IF('Balance Sheet'!H38=0,0,'Income Statement'!H28/'Balance Sheet'!H38) | I7: =IF('Balance Sheet'!I38=0,0,'Income Statement'!I28/'Balance Sheet'!I38)
A8: ── Liquidity ──
A9: Current Ratio | B9: =IF('Balance Sheet'!B24=0,0,'Balance Sheet'!B8/'Balance Sheet'!B24) | C9: =IF('Balance Sheet'!C24=0,0,'Balance Sheet'!C8/'Balance Sheet'!C24) | D9: =IF('Balance Sheet'!D24=0,0,'Balance Sheet'!D8/'Balance Sheet'!D24) | E9: =IF('Balance Sheet'!E24=0,0,'Balance Sheet'!E8/'Balance Sheet'!E24) | F9: =IF('Balance Sheet'!F24=0,0,'Balance Sheet'!F8/'Balance Sheet'!F24) | G9: =IF('Balance Sheet'!G24=0,0,'Balance Sheet'!G8/'Balance Sheet'!G24) | H9: =IF('Balance Sheet'!H24=0,0,'Balance Sheet'!H8/'Balance Sheet'!H24) | I9: =IF('Balance Sheet'!I24=0,0,'Balance Sheet'!I8/'Balance Sheet'!I24)
A10: Debt to Equity | B10: =IF('Balance Sheet'!B38=0,0,'Balance Sheet'!B30/'Balance Sheet'!B38) | C10: =IF('Balance Sheet'!C38=0,0,'Balance Sheet'!C30/'Balance Sheet'!C38) | D10: =IF('Balance Sheet'!D38=0,0,'Balance Sheet'!D30/'Balance Sheet'!D38) | E10: =IF('Balance Sheet'!E38=0,0,'Balance Sheet'!E30/'Balance Sheet'!E38) | F10: =IF('Balance Sheet'!F38=0,0,'Balance Sheet'!F30/'Balance Sheet'!F38) | G10: =IF('Balance Sheet'!G38=0,0,'Balance Sheet'!G30/'Balance Sheet'!G38) | H10: =IF('Balance Sheet'!H38=0,0,'Balance Sheet'!H30/'Balance Sheet'!H38) | I10: =IF('Balance Sheet'!I38=0,0,'Balance Sheet'!I30/'Balance Sheet'!I38)
A11: ── Efficiency ──
A12: Asset Turnover | B12: =IF('Balance Sheet'!B15=0,0,'Income Statement'!B2/'Balance Sheet'!B15) | C12: =IF('Balance Sheet'!C15=0,0,'Income Statement'!C2/'Balance Sheet'!C15) | D12: =IF('Balance Sheet'!D15=0,0,'Income Statement'!D2/'Balance Sheet'!D15) | E12: =IF('Balance Sheet'!E15=0,0,'Income Statement'!E2/'Balance Sheet'!E15) | F12: =IF('Balance Sheet'!F15=0,0,'Income Statement'!F2/'Balance Sheet'!F15) | G12: =IF('Balance Sheet'!G15=0,0,'Income Statement'!G2/'Balance Sheet'!G15) | H12: =IF('Balance Sheet'!H15=0,0,'Income Statement'!H2/'Balance Sheet'!H15) | I12: =IF('Balance Sheet'!I15=0,0,'Income Statement'!I2/'Balance Sheet'!I15)

Sheet Working Capital
A1: ="'" & 'Company Info'!B4 & "' — Working Capital Schedule" | B1: 2021 (A) | C1: 2022 (A) | D1: 2023 (A) | E1: 2024E | F1: 2025E | G1: 2026E | H1: 2027E | I1: 2028E
A2: EFFICIENCY METRICS
A3: Days Sales Outstanding (DSO) | B3: =Assumptions!B15 | C3: =Assumptions!C15 | D3: =Assumptions!D15 | E3: =Assumptions!E15 | F3: =Assumptions!F15 | G3: =Assumptions!G15 | H3: =Assumptions!H15 | I3: =Assumptions!I15
A4: Days Inventory Outstanding (DIO) | B4: =Assumptions!B16 | C4: =Assumptions!C16 | D4: =Assumptions!D16 | E4: =Assumptions!E16 | F4: =Assumptions!F16 | G4: =Assumptions!G16 | H4: =Assumptions!H16 | I4: =Assumptions!I16
A5: Days Payables Outstanding (DPO) | B5: =Assumptions!B17 | C5: =Assumptions!C17 | D5: =Assumptions!D17 | E5: =Assumptions!E17 | F5: =Assumptions!F17 | G5: =Assumptions!G17 | H5: =Assumptions!H17 | I5: =Assumptions!I17
A6: Cash Conversion Cycle (days) | B6: =B3+B4-B5 | C6: =C3+C4-C5 | D6: =D3+D4-D5 | E6: =E3+E4-E5 | F6: =F3+F4-F5 | G6: =G3+G4-G5 | H6: =H3+H4-H5 | I6: =I3+I4-I5
A8: CURRENT ASSETS (excl. Cash)
A9: Accounts Receivable | B9: ='Balance Sheet'!B4 | C9: ='Balance Sheet'!C4 | D9: ='Balance Sheet'!D4 | E9: ='Balance Sheet'!E4 | F9: ='Balance Sheet'!F4 | G9: ='Balance Sheet'!G4 | H9: ='Balance Sheet'!H4 | I9: ='Balance Sheet'!I4
A10: Inventory | B10: ='Balance Sheet'!B5 | C10: ='Balance Sheet'!C5 | D10: ='Balance Sheet'!D5 | E10: ='Balance Sheet'!E5 | F10: ='Balance Sheet'!F5 | G10: ='Balance Sheet'!G5 | H10: ='Balance Sheet'!H5 | I10: ='Balance Sheet'!I5
A11: Prepaid Expenses | B11: ='Balance Sheet'!B6 | C11: ='Balance Sheet'!C6 | D11: ='Balance Sheet'!D6 | E11: ='Balance Sheet'!E6 | F11: ='Balance Sheet'!F6 | G11: ='Balance Sheet'!G6 | H11: ='Balance Sheet'!H6 | I11: ='Balance Sheet'!I6
A12: Other Current Assets | B12: ='Balance Sheet'!B7 | C12: ='Balance Sheet'!C7 | D12: ='Balance Sheet'!D7 | E12: ='Balance Sheet'!E7 | F12: ='Balance Sheet'!F7 | G12: ='Balance Sheet'!G7 | H12: ='Balance Sheet'!H7 | I12: ='Balance Sheet'!I7
A14: CURRENT LIABILITIES (excl. Debt)
A15: Accounts Payable | B15: ='Balance Sheet'!B18 | C15: ='Balance Sheet'!C18 | D15: ='Balance Sheet'!D18 | E15: ='Balance Sheet'!E18 | F15: ='Balance Sheet'!F18 | G15: ='Balance Sheet'!G18 | H15: ='Balance Sheet'!H18 | I15: ='Balance Sheet'!I18
A16: Accrued Expenses | B16: ='Balance Sheet'!B19 | C16: ='Balance Sheet'!C19 | D16: ='Balance Sheet'!D19 | E16: ='Balance Sheet'!E19 | F16: ='Balance Sheet'!F19 | G16: ='Balance Sheet'!G19 | H16: ='Balance Sheet'!H19 | I16: ='Balance Sheet'!I19
A17: Deferred Revenue | B17: ='Balance Sheet'!B22 | C17: ='Balance Sheet'!C22 | D17: ='Balance Sheet'!D22 | E17: ='Balance Sheet'!E22 | F17: ='Balance Sheet'!F22 | G17: ='Balance Sheet'!G22 | H17: ='Balance Sheet'!H22 | I17: ='Balance Sheet'!I22
A18: Other Current Liabilities | B18: ='Balance Sheet'!B23 | C18: ='Balance Sheet'!C23 | D18: ='Balance Sheet'!D23 | E18: ='Balance Sheet'!E23 | F18: ='Balance Sheet'!F23 | G18: ='Balance Sheet'!G23 | H18: ='Balance Sheet'!H23 | I18: ='Balance Sheet'!I23
A20: Net Working Capital | B20: =(B9+B10+B11+B12)-(B15+B16+B17+B18) | C20: =(C9+C10+C11+C12)-(C15+C16+C17+C18) | D20: =(D9+D10+D11+D12)-(D15+D16+D17+D18) | E20: =(E9+E10+E11+E12)-(E15+E16+E17+E18) | F20: =(F9+F10+F11+F12)-(F15+F16+F17+F18) | G20: =(G9+G10+G11+G12)-(G15+G16+G17+G18) | H20: =(H9+H10+H11+H12)-(H15+H16+H17+H18) | I20: =(I9+I10+I11+I12)-(I15+I16+I17+I18)
A21: NWC Change | B21: =0 | C21: =C20-B20 | D21: =D20-C20 | E21: =E20-D20 | F21: =F20-E20 | G21: =G20-F20 | H21: =H20-G20 | I21: =I20-H20
A22: NWC % of Revenue | B22: =IF('Income Statement'!B2=0,0,B20/'Income Statement'!B2) | C22: =IF('Income Statement'!C2=0,0,C20/'Income Statement'!C2) | D22: =IF('Income Statement'!D2=0,0,D20/'Income Statement'!D2) | E22: =IF('Income Statement'!E2=0,0,E20/'Income Statement'!E2) | F22: =IF('Income Statement'!F2=0,0,F20/'Income Statement'!F2) | G22: =IF('Income Statement'!G2=0,0,G20/'Income Statement'!G2) | H22: =IF('Income Statement'!H2=0,0,H20/'Income Statement'!H2) | I22: =IF('Income Statement'!I2=0,0,I20/'Income Statement'!I2)

Sheet Depreciation Schedule
A1: ="'" & 'Company Info'!B4 & "' — PP&E Rollforward" | B1: 2021 (A) | C1: 2022 (A) | D1: 2023 (A) | E1: 2024E | F1: 2025E | G1: 2026E | H1: 2027E | I1: 2028E
A2: GROSS PP&E
A3: Beginning Gross PP&E | C3: =Assumptions!B49 | D3: =Assumptions!C49 | E3: =Assumptions!D49 | F3: =Assumptions!E49 | G3: =Assumptions!F49 | H3: =Assumptions!G49 | I3: =Assumptions!H49
A4: (+) Capital Expenditures | C4: =ABS('Income Statement'!C2*Assumptions!C22) | D4: =ABS('Income Statement'!D2*Assumptions!D22) | E4: =ABS('Income Statement'!E2*Assumptions!E22) | F4: =ABS('Income Statement'!F2*Assumptions!F22) | G4: =ABS('Income Statement'!G2*Assumptions!G22) | H4: =ABS('Income Statement'!H2*Assumptions!H22) | I4: =ABS('Income Statement'!I2*Assumptions!I22)
A5: Ending Gross PP&E | B5: =Assumptions!B49 | C5: =Assumptions!C49 | D5: =Assumptions!D49 | E5: =Assumptions!E49 | F5: =Assumptions!F49 | G5: =Assumptions!G49 | H5: =Assumptions!H49 | I5: =Assumptions!I49
A7: ACCUMULATED DEPRECIATION
A8: Beginning Accum. Depreciation | C8: =Assumptions!B50 | D8: =Assumptions!C50 | E8: =Assumptions!D50 | F8: =Assumptions!E50 | G8: =Assumptions!F50 | H8: =Assumptions!G50 | I8: =Assumptions!H50
A9: (+) Depreciation Expense | B9: ='Income Statement'!B11 | C9: ='Income Statement'!C11 | D9: ='Income Statement'!D11 | E9: ='Income Statement'!E11 | F9: ='Income Statement'!F11 | G9: ='Income Statement'!G11 | H9: ='Income Statement'!H11 | I9: ='Income Statement'!I11
A10: Ending Accum. Depreciation | B10: =Assumptions!B50 | C10: =Assumptions!C50 | D10: =Assumptions!D50 | E10: =Assumptions!E50 | F10: =Assumptions!F50 | G10: =Assumptions!G50 | H10: =Assumptions!H50 | I10: =Assumptions!I50
A12: Net PP&E | B12: ='Balance Sheet'!B10 | C12: ='Balance Sheet'!C10 | D12: ='Balance Sheet'!D10 | E12: ='Balance Sheet'!E10 | F12: ='Balance Sheet'!F10 | G12: ='Balance Sheet'!G10 | H12: ='Balance Sheet'!H10 | I12: ='Balance Sheet'!I10
A14: KEY METRICS
A15: CapEx % of Revenue | C15: =IF('Income Statement'!C2=0,0,C4/'Income Statement'!C2) | D15: =IF('Income Statement'!D2=0,0,D4/'Income Statement'!D2) | E15: =IF('Income Statement'!E2=0,0,E4/'Income Statement'!E2) | F15: =IF('Income Statement'!F2=0,0,F4/'Income Statement'!F2) | G15: =IF('Income Statement'!G2=0,0,G4/'Income Statement'!G2) | H15: =IF('Income Statement'!H2=0,0,H4/'Income Statement'!H2) | I15: =IF('Income Statement'!I2=0,0,I4/'Income Statement'!I2)
A16: Depreciation Rate (% Gross PP&E) | B16: =IF(B5=0,0,B9/B5) | C16: =IF(C5=0,0,C9/C5) | D16: =IF(D5=0,0,D9/D5) | E16: =IF(E5=0,0,E9/E5) | F16: =IF(F5=0,0,F9/F5) | G16: =IF(G5=0,0,G9/G5) | H16: =IF(H5=0,0,H9/H5) | I16: =IF(I5=0,0,I9/I5)
A17: Implied Useful Life (yrs) | B17: =IF(B16=0,0,1/B16) | C17: =IF(C16=0,0,1/C16) | D17: =IF(D16=0,0,1/D16) | E17: =IF(E16=0,0,1/E16) | F17: =IF(F16=0,0,1/F16) | G17: =IF(G16=0,0,1/G16) | H17: =IF(H16=0,0,1/H16) | I17: =IF(I16=0,0,1/I16)
A19: INTANGIBLES
A20: Amortization Expense | B20: ='Income Statement'!B12 | C20: ='Income Statement'!C12 | D20: ='Income Statement'!D12 | E20: ='Income Statement'!E12 | F20: ='Income Statement'!F12 | G20: ='Income Statement'!G12 | H20: ='Income Statement'!H12 | I20: ='Income Statement'!I12
A21: Net Intangibles | B21: ='Balance Sheet'!B11 | C21: ='Balance Sheet'!C11 | D21: ='Balance Sheet'!D11 | E21: ='Balance Sheet'!E11 | F21: ='Balance Sheet'!F11 | G21: ='Balance Sheet'!G11 | H21: ='Balance Sheet'!H11 | I21: ='Balance Sheet'!I11

Sheet Debt Schedule
A1: ="'" & 'Company Info'!B4 & "' — Debt Schedule" | B1: 2021 (A) | C1: 2022 (A) | D1: 2023 (A) | E1: 2024E | F1: 2025E | G1: 2026E | H1: 2027E | I1: 2028E
A2: LONG-TERM DEBT ROLLFORWARD
A3: Beginning Long-Term Debt | C3: =Assumptions!B53 | D3: =Assumptions!C53 | E3: =Assumptions!D53 | F3: =Assumptions!E53 | G3: =Assumptions!F53 | H3: =Assumptions!G53 | I3: =Assumptions!H53
A4: (+) New Issuance | C4: =Assumptions!C29 | D4: =Assumptions!D29 | E4: =Assumptions!E29 | F4: =Assumptions!F29 | G4: =Assumptions!G29 | H4: =Assumptions!H29 | I4: =Assumptions!I29
A5: (-) Repayments | C5: =-ABS(Assumptions!C30) | D5: =-ABS(Assumptions!D30) | E5: =-ABS(Assumptions!E30) | F5: =-ABS(Assumptions!F30) | G5: =-ABS(Assumptions!G30) | H5: =-ABS(Assumptions!H30) | I5: =-ABS(Assumptions!I30)
A6: Ending Long-Term Debt | B6: =Assumptions!B53 | C6: =Assumptions!C53 | D6: =Assumptions!D53 | E6: =Assumptions!E53 | F6: =Assumptions!F53 | G6: =Assumptions!G53 | H6: =Assumptions!H53 | I6: =Assumptions!I53
A8: DEBT SUMMARY
A9: Short-Term Debt | B9: ='Balance Sheet'!B20 | C9: ='Balance Sheet'!C20 | D9: ='Balance Sheet'!D20 | E9: ='Balance Sheet'!E20 | F9: ='Balance Sheet'!F20 | G9: ='Balance Sheet'!G20 | H9: ='Balance Sheet'!H20 | I9: ='Balance Sheet'!I20
A10: Current Portion of LTD | B10: ='Balance Sheet'!B21 | C10: ='Balance Sheet'!C21 | D10: ='Balance Sheet'!D21 | E10: ='Balance Sheet'!E21 | F10: ='Balance Sheet'!F21 | G10: ='Balance Sheet'!G21 | H10: ='Balance Sheet'!H21 | I10: ='Balance Sheet'!I21
A11: Long-Term Debt | B11: ='Balance Sheet'!B26 | C11: ='Balance Sheet'!C26 | D11: ='Balance Sheet'!D26 | E11: ='Balance Sheet'!E26 | F11: ='Balance Sheet'!F26 | G11: ='Balance Sheet'!G26 | H11: ='Balance Sheet'!H26 | I11: ='Balance Sheet'!I26
A12: Total Debt | B12: =B9+B10+B11 | C12: =C9+C10+C11 | D12: =D9+D10+D11 | E12: =E9+E10+E11 | F12: =F9+F10+F11 | G12: =G9+G10+G11 | H12: =H9+H10+H11 | I12: =I9+I10+I11
A14: INTEREST ANALYSIS
A15: Average Debt Balance | B15: =B12 | C15: =(C12+B12)/2 | D15: =(D12+C12)/2 | E15: =(E12+D12)/2 | F15: =(F12+E12)/2 | G15: =(G12+F12)/2 | H15: =(H12+G12)/2 | I15: =(I12+H12)/2
A16: Interest Expense | B16: ='Income Statement'!B22 | C16: ='Income Statement'!C22 | D16: ='Income Statement'!D22 | E16: ='Income Statement'!E22 | F16: ='Income Statement'!F22 | G16: ='Income Statement'!G22 | H16: ='Income Statement'!H22 | I16: ='Income Statement'!I22
A17: Interest Income | B17: ='Income Statement'!B21 | C17: ='Income Statement'!C21 | D17: ='Income Statement'!D21 | E17: ='Income Statement'!E21 | F17: ='Income Statement'!F21 | G17: ='Income Statement'!G21 | H17: ='Income Statement'!H21 | I17: ='Income Statement'!I21
A18: Net Interest | B18: =B16-B17 | C18: =C16-C17 | D18: =D16-D17 | E18: =E16-E17 | F18: =F16-F17 | G18: =G16-G17 | H18: =H16-H17 | I18: =I16-I17
A20: LEVERAGE RATIOS
A21: Interest Coverage (EBIT / Int Exp) | B21: =IF(B16=0,0,'Income Statement'!B17/B16) | C21: =IF(C16=0,0,'Income Statement'!C17/C16) | D21: =IF(D16=0,0,'Income Statement'!D17/D16) | E21: =IF(E16=0,0,'Income Statement'!E17/E16) | F21: =IF(F16=0,0,'Income Statement'!F17/F16) | G21: =IF(G16=0,0,'Income Statement'!G17/G16) | H21: =IF(H16=0,0,'Income Statement'!H17/H16) | I21: =IF(I16=0,0,'Income Statement'!I17/I16)
A22: Debt / Equity | B22: =IF('Balance Sheet'!B38=0,0,B12/'Balance Sheet'!B38) | C22: =IF('Balance Sheet'!C38=0,0,C12/'Balance Sheet'!C38) | D22: =IF('Balance Sheet'!D38=0,0,D12/'Balance Sheet'!D38) | E22: =IF('Balance Sheet'!E38=0,0,E12/'Balance Sheet'!E38) | F22: =IF('Balance Sheet'!F38=0,0,F12/'Balance Sheet'!F38) | G22: =IF('Balance Sheet'!G38=0,0,G12/'Balance Sheet'!G38) | H22: =IF('Balance Sheet'!H38=0,0,H12/'Balance Sheet'!H38) | I22: =IF('Balance Sheet'!I38=0,0,I12/'Balance Sheet'!I38)
A23: Debt / Total Assets | B23: =IF('Balance Sheet'!B15=0,0,B12/'Balance Sheet'!B15) | C23: =IF('Balance Sheet'!C15=0,0,C12/'Balance Sheet'!C15) | D23: =IF('Balance Sheet'!D15=0,0,D12/'Balance Sheet'!D15) | E23: =IF('Balance Sheet'!E15=0,0,E12/'Balance Sheet'!E15) | F23: =IF('Balance Sheet'!F15=0,0,F12/'Balance Sheet'!F15) | G23: =IF('Balance Sheet'!G15=0,0,G12/'Balance Sheet'!G15) | H23: =IF('Balance Sheet'!H15=0,0,H12/'Balance Sheet'!H15) | I23: =IF('Balance Sheet'!I15=0,0,I12/'Balance Sheet'!I15)
