Workbook

Sheet Dashboard
A1: Demo Company Inc.
A2: FINANCIAL MODEL DASHBOARD · E£ (Egyptian Pound) · CONFIDENTIAL
A4: 📊 SCENARIO CONTROL
A5: Active Scenario | B5: Select Scenario →
A6: ▼ Scenario Selector | B6: Base Case | E6: =IF(B6="Base Case","Central planning — stable market | Revenue 10%→5% | COGS 60%",IF(B6="Optimistic","Optimistic case — strong execution | Revenue 15%→8% | COGS 55%","Conservative case — headwinds | Revenue 5%→2% | COGS 63%")) -> Central planning — stable market | Revenue 10%→5% | COGS 60%
A8: 📈 KEY METRICS — ACTIVE SCENARIO
B9: 2024 | C9: 2025 | D9: 2026E | E9: 2027E | F9: 2028E | G9: 2029E | H9: 2030E
A10: 📗 INCOME STATEMENT
A11: Revenue (E£) | B11: =IF(Dashboard!$B$6="Base Case",Scenarios!B67,IF(Dashboard!$B$6="Optimistic",Scenarios!B153,Scenarios!B239)) -> 850000 | C11: =IF(Dashboard!$B$6="Base Case",Scenarios!C67,IF(Dashboard!$B$6="Optimistic",Scenarios!C153,Scenarios!C239)) -> 950000 | D11: =IF(Dashboard!$B$6="Base Case",Scenarios!D67,IF(Dashboard!$B$6="Optimistic",Scenarios!D153,Scenarios!D239)) -> 1045000 | E11: =IF(Dashboard!$B$6="Base Case",Scenarios!E67,IF(Dashboard!$B$6="Optimistic",Scenarios!E153,Scenarios!E239)) -> 1128600 | F11: =IF(Dashboard!$B$6="Base Case",Scenarios!F67,IF(Dashboard!$B$6="Optimistic",Scenarios!F153,Scenarios!F239)) -> 1207602 | G11: =IF(Dashboard!$B$6="Base Case",Scenarios!G67,IF(Dashboard!$B$6="Optimistic",Scenarios!G153,Scenarios!G239)) -> 1280058.1 | H11: =IF(Dashboard!$B$6="Base Case",Scenarios!H67,IF(Dashboard!$B$6="Optimistic",Scenarios!H153,Scenarios!H239)) -> 1344061
A12: Revenue Growth % | B12: =IF(Dashboard!$B$6="Base Case",Scenarios!B68,IF(Dashboard!$B$6="Optimistic",Scenarios!B154,Scenarios!B240)) -> 0 | C12: =IF(Dashboard!$B$6="Base Case",Scenarios!C68,IF(Dashboard!$B$6="Optimistic",Scenarios!C154,Scenarios!C240)) -> 0.11764706 | D12: =IF(Dashboard!$B$6="Base Case",Scenarios!D68,IF(Dashboard!$B$6="Optimistic",Scenarios!D154,Scenarios!D240)) -> 0.1 | E12: =IF(Dashboard!$B$6="Base Case",Scenarios!E68,IF(Dashboard!$B$6="Optimistic",Scenarios!E154,Scenarios!E240)) -> 0.08 | F12: =IF(Dashboard!$B$6="Base Case",Scenarios!F68,IF(Dashboard!$B$6="Optimistic",Scenarios!F154,Scenarios!F240)) -> 0.07 | G12: =IF(Dashboard!$B$6="Base Case",Scenarios!G68,IF(Dashboard!$B$6="Optimistic",Scenarios!G154,Scenarios!G240)) -> 0.06 | H12: =IF(Dashboard!$B$6="Base Case",Scenarios!H68,IF(Dashboard!$B$6="Optimistic",Scenarios!H154,Scenarios!H240)) -> 0.05
A13: Gross Profit (E£) | B13: =IF(Dashboard!$B$6="Base Case",Scenarios!B69,IF(Dashboard!$B$6="Optimistic",Scenarios!B155,Scenarios!B241)) -> 340000 | C13: =IF(Dashboard!$B$6="Base Case",Scenarios!C69,IF(Dashboard!$B$6="Optimistic",Scenarios!C155,Scenarios!C241)) -> 380000 | D13: =IF(Dashboard!$B$6="Base Case",Scenarios!D69,IF(Dashboard!$B$6="Optimistic",Scenarios!D155,Scenarios!D241)) -> 418000 | E13: =IF(Dashboard!$B$6="Base Case",Scenarios!E69,IF(Dashboard!$B$6="Optimistic",Scenarios!E155,Scenarios!E241)) -> 451440 | F13: =IF(Dashboard!$B$6="Base Case",Scenarios!F69,IF(Dashboard!$B$6="Optimistic",Scenarios!F155,Scenarios!F241)) -> 483040.8 | G13: =IF(Dashboard!$B$6="Base Case",Scenarios!G69,IF(Dashboard!$B$6="Optimistic",Scenarios!G155,Scenarios!G241)) -> 512023.25 | H13: =IF(Dashboard!$B$6="Base Case",Scenarios!H69,IF(Dashboard!$B$6="Optimistic",Scenarios!H155,Scenarios!H241)) -> 537624.41
A14: Gross Margin % | B14: =IF(Dashboard!$B$6="Base Case",Scenarios!B70,IF(Dashboard!$B$6="Optimistic",Scenarios!B156,Scenarios!B242)) -> 0.4 | C14: =IF(Dashboard!$B$6="Base Case",Scenarios!C70,IF(Dashboard!$B$6="Optimistic",Scenarios!C156,Scenarios!C242)) -> 0.4 | D14: =IF(Dashboard!$B$6="Base Case",Scenarios!D70,IF(Dashboard!$B$6="Optimistic",Scenarios!D156,Scenarios!D242)) -> 0.4 | E14: =IF(Dashboard!$B$6="Base Case",Scenarios!E70,IF(Dashboard!$B$6="Optimistic",Scenarios!E156,Scenarios!E242)) -> 0.4 | F14: =IF(Dashboard!$B$6="Base Case",Scenarios!F70,IF(Dashboard!$B$6="Optimistic",Scenarios!F156,Scenarios!F242)) -> 0.4 | G14: =IF(Dashboard!$B$6="Base Case",Scenarios!G70,IF(Dashboard!$B$6="Optimistic",Scenarios!G156,Scenarios!G242)) -> 0.4 | H14: =IF(Dashboard!$B$6="Base Case",Scenarios!H70,IF(Dashboard!$B$6="Optimistic",Scenarios!H156,Scenarios!H242)) -> 0.4
A15: EBITDA (E£) | B15: =IF(Dashboard!$B$6="Base Case",Scenarios!B71,IF(Dashboard!$B$6="Optimistic",Scenarios!B157,Scenarios!B243)) -> 153000 | C15: =IF(Dashboard!$B$6="Base Case",Scenarios!C71,IF(Dashboard!$B$6="Optimistic",Scenarios!C157,Scenarios!C243)) -> 171000 | D15: =IF(Dashboard!$B$6="Base Case",Scenarios!D71,IF(Dashboard!$B$6="Optimistic",Scenarios!D157,Scenarios!D243)) -> 240350 | E15: =IF(Dashboard!$B$6="Base Case",Scenarios!E71,IF(Dashboard!$B$6="Optimistic",Scenarios!E157,Scenarios!E243)) -> 259578 | F15: =IF(Dashboard!$B$6="Base Case",Scenarios!F71,IF(Dashboard!$B$6="Optimistic",Scenarios!F157,Scenarios!F243)) -> 277748.46 | G15: =IF(Dashboard!$B$6="Base Case",Scenarios!G71,IF(Dashboard!$B$6="Optimistic",Scenarios!G157,Scenarios!G243)) -> 294413.37 | H15: =IF(Dashboard!$B$6="Base Case",Scenarios!H71,IF(Dashboard!$B$6="Optimistic",Scenarios!H157,Scenarios!H243)) -> 309134.04
A16: EBIT (E£) | B16: =IF(Dashboard!$B$6="Base Case",Scenarios!B72,IF(Dashboard!$B$6="Optimistic",Scenarios!B158,Scenarios!B244)) -> 120000 | C16: =IF(Dashboard!$B$6="Base Case",Scenarios!C72,IF(Dashboard!$B$6="Optimistic",Scenarios!C158,Scenarios!C244)) -> 134000 | D16: =IF(Dashboard!$B$6="Base Case",Scenarios!D72,IF(Dashboard!$B$6="Optimistic",Scenarios!D158,Scenarios!D244)) -> 194237.5 | E16: =IF(Dashboard!$B$6="Base Case",Scenarios!E72,IF(Dashboard!$B$6="Optimistic",Scenarios!E158,Scenarios!E244)) -> 208031.5 | F16: =IF(Dashboard!$B$6="Base Case",Scenarios!F72,IF(Dashboard!$B$6="Optimistic",Scenarios!F158,Scenarios!F244)) -> 220361.46 | G16: =IF(Dashboard!$B$6="Base Case",Scenarios!G72,IF(Dashboard!$B$6="Optimistic",Scenarios!G158,Scenarios!G244)) -> 230807.21 | H16: =IF(Dashboard!$B$6="Base Case",Scenarios!H72,IF(Dashboard!$B$6="Optimistic",Scenarios!H158,Scenarios!H244)) -> 238967.58
A17: EBIT Margin % | B17: =IF(Dashboard!$B$6="Base Case",Scenarios!B73,IF(Dashboard!$B$6="Optimistic",Scenarios!B159,Scenarios!B245)) -> 0.14117647 | C17: =IF(Dashboard!$B$6="Base Case",Scenarios!C73,IF(Dashboard!$B$6="Optimistic",Scenarios!C159,Scenarios!C245)) -> 0.14105263 | D17: =IF(Dashboard!$B$6="Base Case",Scenarios!D73,IF(Dashboard!$B$6="Optimistic",Scenarios!D159,Scenarios!D245)) -> 0.18587321 | E17: =IF(Dashboard!$B$6="Base Case",Scenarios!E73,IF(Dashboard!$B$6="Optimistic",Scenarios!E159,Scenarios!E245)) -> 0.18432704 | F17: =IF(Dashboard!$B$6="Base Case",Scenarios!F73,IF(Dashboard!$B$6="Optimistic",Scenarios!F159,Scenarios!F245)) -> 0.18247854 | G17: =IF(Dashboard!$B$6="Base Case",Scenarios!G73,IF(Dashboard!$B$6="Optimistic",Scenarios!G159,Scenarios!G245)) -> 0.18030995 | H17: =IF(Dashboard!$B$6="Base Case",Scenarios!H73,IF(Dashboard!$B$6="Optimistic",Scenarios!H159,Scenarios!H245)) -> 0.17779519
A18: Net Income (E£) | B18: =IF(Dashboard!$B$6="Base Case",Scenarios!B74,IF(Dashboard!$B$6="Optimistic",Scenarios!B160,Scenarios!B246)) -> 84087.5 | C18: =IF(Dashboard!$B$6="Base Case",Scenarios!C74,IF(Dashboard!$B$6="Optimistic",Scenarios!C160,Scenarios!C246)) -> 96100 | D18: =IF(Dashboard!$B$6="Base Case",Scenarios!D74,IF(Dashboard!$B$6="Optimistic",Scenarios!D160,Scenarios!D246)) -> 147993.7 | E18: =IF(Dashboard!$B$6="Base Case",Scenarios!E74,IF(Dashboard!$B$6="Optimistic",Scenarios!E160,Scenarios!E246)) -> 179824.99 | F18: =IF(Dashboard!$B$6="Base Case",Scenarios!F74,IF(Dashboard!$B$6="Optimistic",Scenarios!F160,Scenarios!F246)) -> 200453.05 | G18: =IF(Dashboard!$B$6="Base Case",Scenarios!G74,IF(Dashboard!$B$6="Optimistic",Scenarios!G160,Scenarios!G246)) -> 215020.22 | H18: =IF(Dashboard!$B$6="Base Case",Scenarios!H74,IF(Dashboard!$B$6="Optimistic",Scenarios!H160,Scenarios!H246)) -> 231471.1
A19: Net Margin % | B19: =IF(Dashboard!$B$6="Base Case",Scenarios!B75,IF(Dashboard!$B$6="Optimistic",Scenarios!B161,Scenarios!B247)) -> 0.098926471 | C19: =IF(Dashboard!$B$6="Base Case",Scenarios!C75,IF(Dashboard!$B$6="Optimistic",Scenarios!C161,Scenarios!C247)) -> 0.10115789 | D19: =IF(Dashboard!$B$6="Base Case",Scenarios!D75,IF(Dashboard!$B$6="Optimistic",Scenarios!D161,Scenarios!D247)) -> 0.14162077 | E19: =IF(Dashboard!$B$6="Base Case",Scenarios!E75,IF(Dashboard!$B$6="Optimistic",Scenarios!E161,Scenarios!E247)) -> 0.15933456 | F19: =IF(Dashboard!$B$6="Base Case",Scenarios!F75,IF(Dashboard!$B$6="Optimistic",Scenarios!F161,Scenarios!F247)) -> 0.16599264 | G19: =IF(Dashboard!$B$6="Base Case",Scenarios!G75,IF(Dashboard!$B$6="Optimistic",Scenarios!G161,Scenarios!G247)) -> 0.16797692 | H19: =IF(Dashboard!$B$6="Base Case",Scenarios!H75,IF(Dashboard!$B$6="Optimistic",Scenarios!H161,Scenarios!H247)) -> 0.1722177
A20: EPS (E£) | B20: =IF(Dashboard!$B$6="Base Case",Scenarios!B76,IF(Dashboard!$B$6="Optimistic",Scenarios!B162,Scenarios!B248)) -> 0.840875 | C20: =IF(Dashboard!$B$6="Base Case",Scenarios!C76,IF(Dashboard!$B$6="Optimistic",Scenarios!C162,Scenarios!C248)) -> 0.961 | D20: =IF(Dashboard!$B$6="Base Case",Scenarios!D76,IF(Dashboard!$B$6="Optimistic",Scenarios!D162,Scenarios!D248)) -> 1.3319433 | E20: =IF(Dashboard!$B$6="Base Case",Scenarios!E76,IF(Dashboard!$B$6="Optimistic",Scenarios!E162,Scenarios!E248)) -> 1.6184249 | F20: =IF(Dashboard!$B$6="Base Case",Scenarios!F76,IF(Dashboard!$B$6="Optimistic",Scenarios!F162,Scenarios!F248)) -> 1.8040774 | G20: =IF(Dashboard!$B$6="Base Case",Scenarios!G76,IF(Dashboard!$B$6="Optimistic",Scenarios!G162,Scenarios!G248)) -> 1.935182 | H20: =IF(Dashboard!$B$6="Base Case",Scenarios!H76,IF(Dashboard!$B$6="Optimistic",Scenarios!H162,Scenarios!H248)) -> 2.0832399
A21: 💵 CASH FLOW
A22: CFO (E£) | B22: — | C22: =IF(Dashboard!$B$6="Base Case",Scenarios!C77,IF(Dashboard!$B$6="Optimistic",Scenarios!C163,Scenarios!C249)) -> 126417 | D22: =IF(Dashboard!$B$6="Base Case",Scenarios!D77,IF(Dashboard!$B$6="Optimistic",Scenarios!D163,Scenarios!D249)) -> 319424.67 | E22: =IF(Dashboard!$B$6="Base Case",Scenarios!E77,IF(Dashboard!$B$6="Optimistic",Scenarios!E163,Scenarios!E249)) -> 236316.49 | F22: =IF(Dashboard!$B$6="Base Case",Scenarios!F77,IF(Dashboard!$B$6="Optimistic",Scenarios!F163,Scenarios!F249)) -> 262513.07 | G22: =IF(Dashboard!$B$6="Base Case",Scenarios!G77,IF(Dashboard!$B$6="Optimistic",Scenarios!G163,Scenarios!G249)) -> 282912.21 | H22: =IF(Dashboard!$B$6="Base Case",Scenarios!H77,IF(Dashboard!$B$6="Optimistic",Scenarios!H163,Scenarios!H249)) -> 305423.37
A23: Free Cash Flow (E£) | B23: — | C23: =IF(Dashboard!$B$6="Base Case",Scenarios!C78,IF(Dashboard!$B$6="Optimistic",Scenarios!C164,Scenarios!C250)) -> 81417 | D23: =IF(Dashboard!$B$6="Base Case",Scenarios!D78,IF(Dashboard!$B$6="Optimistic",Scenarios!D164,Scenarios!D250)) -> 267174.67 | E23: =IF(Dashboard!$B$6="Base Case",Scenarios!E78,IF(Dashboard!$B$6="Optimistic",Scenarios!E164,Scenarios!E250)) -> 179886.49 | F23: =IF(Dashboard!$B$6="Base Case",Scenarios!F78,IF(Dashboard!$B$6="Optimistic",Scenarios!F164,Scenarios!F250)) -> 202132.97 | G23: =IF(Dashboard!$B$6="Base Case",Scenarios!G78,IF(Dashboard!$B$6="Optimistic",Scenarios!G164,Scenarios!G250)) -> 218909.3 | H23: =IF(Dashboard!$B$6="Base Case",Scenarios!H78,IF(Dashboard!$B$6="Optimistic",Scenarios!H164,Scenarios!H250)) -> 238220.32
A24: Ending Cash (E£) | B24: — | C24: =IF(Dashboard!$B$6="Base Case",Scenarios!C79,IF(Dashboard!$B$6="Optimistic",Scenarios!C165,Scenarios!C251)) -> 200000 | D24: =IF(Dashboard!$B$6="Base Case",Scenarios!D79,IF(Dashboard!$B$6="Optimistic",Scenarios!D165,Scenarios!D251)) -> 413917 | E24: =IF(Dashboard!$B$6="Base Case",Scenarios!E79,IF(Dashboard!$B$6="Optimistic",Scenarios!E165,Scenarios!E251)) -> 527268.24 | F24: =IF(Dashboard!$B$6="Base Case",Scenarios!F79,IF(Dashboard!$B$6="Optimistic",Scenarios!F165,Scenarios!F251)) -> 655233.58 | G24: =IF(Dashboard!$B$6="Base Case",Scenarios!G79,IF(Dashboard!$B$6="Optimistic",Scenarios!G165,Scenarios!G251)) -> 794585.4 | H24: =IF(Dashboard!$B$6="Base Case",Scenarios!H79,IF(Dashboard!$B$6="Optimistic",Scenarios!H165,Scenarios!H251)) -> 947161.42
A25: 🏦 BALANCE SHEET
A26: Total Assets (E£) | B26: =IF(Dashboard!$B$6="Base Case",Scenarios!B80,IF(Dashboard!$B$6="Optimistic",Scenarios!B166,Scenarios!B252)) -> 717213 | C26: =IF(Dashboard!$B$6="Base Case",Scenarios!C80,IF(Dashboard!$B$6="Optimistic",Scenarios!C166,Scenarios!C252)) -> 768472 | D26: =IF(Dashboard!$B$6="Base Case",Scenarios!D80,IF(Dashboard!$B$6="Optimistic",Scenarios!D166,Scenarios!D252)) -> 1013189.4 | E26: =IF(Dashboard!$B$6="Base Case",Scenarios!E80,IF(Dashboard!$B$6="Optimistic",Scenarios!E166,Scenarios!E252)) -> 1147274.9 | F26: =IF(Dashboard!$B$6="Base Case",Scenarios!F80,IF(Dashboard!$B$6="Optimistic",Scenarios!F166,Scenarios!F252)) -> 1293212.3 | G26: =IF(Dashboard!$B$6="Base Case",Scenarios!G80,IF(Dashboard!$B$6="Optimistic",Scenarios!G166,Scenarios!G252)) -> 1446698.8 | H26: =IF(Dashboard!$B$6="Base Case",Scenarios!H80,IF(Dashboard!$B$6="Optimistic",Scenarios!H166,Scenarios!H252)) -> 1608446.5
A27: Total Debt (E£) | B27: =IF(Dashboard!$B$6="Base Case",Scenarios!B81,IF(Dashboard!$B$6="Optimistic",Scenarios!B167,Scenarios!B253)) -> 300000 | C27: =IF(Dashboard!$B$6="Base Case",Scenarios!C81,IF(Dashboard!$B$6="Optimistic",Scenarios!C167,Scenarios!C253)) -> 280000 | D27: =IF(Dashboard!$B$6="Base Case",Scenarios!D81,IF(Dashboard!$B$6="Optimistic",Scenarios!D167,Scenarios!D253)) -> 280000 | E27: =IF(Dashboard!$B$6="Base Case",Scenarios!E81,IF(Dashboard!$B$6="Optimistic",Scenarios!E167,Scenarios!E253)) -> 280000 | F27: =IF(Dashboard!$B$6="Base Case",Scenarios!F81,IF(Dashboard!$B$6="Optimistic",Scenarios!F167,Scenarios!F253)) -> 280000 | G27: =IF(Dashboard!$B$6="Base Case",Scenarios!G81,IF(Dashboard!$B$6="Optimistic",Scenarios!G167,Scenarios!G253)) -> 280000 | H27: =IF(Dashboard!$B$6="Base Case",Scenarios!H81,IF(Dashboard!$B$6="Optimistic",Scenarios!H167,Scenarios!H253)) -> 280000
A28: Total Equity (E£) | B28: =IF(Dashboard!$B$6="Base Case",Scenarios!B82,IF(Dashboard!$B$6="Optimistic",Scenarios!B168,Scenarios!B254)) -> 248823 | C28: =IF(Dashboard!$B$6="Base Case",Scenarios!C82,IF(Dashboard!$B$6="Optimistic",Scenarios!C168,Scenarios!C254)) -> 308506 | D28: =IF(Dashboard!$B$6="Base Case",Scenarios!D82,IF(Dashboard!$B$6="Optimistic",Scenarios!D168,Scenarios!D254)) -> 403242.03 | E28: =IF(Dashboard!$B$6="Base Case",Scenarios!E82,IF(Dashboard!$B$6="Optimistic",Scenarios!E168,Scenarios!E254)) -> 516531.78 | F28: =IF(Dashboard!$B$6="Base Case",Scenarios!F82,IF(Dashboard!$B$6="Optimistic",Scenarios!F168,Scenarios!F254)) -> 642817.19 | G28: =IF(Dashboard!$B$6="Base Case",Scenarios!G82,IF(Dashboard!$B$6="Optimistic",Scenarios!G168,Scenarios!G254)) -> 778279.93 | H28: =IF(Dashboard!$B$6="Base Case",Scenarios!H82,IF(Dashboard!$B$6="Optimistic",Scenarios!H168,Scenarios!H254)) -> 924106.73
A29: Cash (E£) | B29: =IF(Dashboard!$B$6="Base Case",Scenarios!B83,IF(Dashboard!$B$6="Optimistic",Scenarios!B169,Scenarios!B255)) -> 175000 | C29: =IF(Dashboard!$B$6="Base Case",Scenarios!C83,IF(Dashboard!$B$6="Optimistic",Scenarios!C169,Scenarios!C255)) -> 200000 | D29: =IF(Dashboard!$B$6="Base Case",Scenarios!D83,IF(Dashboard!$B$6="Optimistic",Scenarios!D169,Scenarios!D255)) -> 413917 | E29: =IF(Dashboard!$B$6="Base Case",Scenarios!E83,IF(Dashboard!$B$6="Optimistic",Scenarios!E169,Scenarios!E255)) -> 527268.24 | F29: =IF(Dashboard!$B$6="Base Case",Scenarios!F83,IF(Dashboard!$B$6="Optimistic",Scenarios!F169,Scenarios!F255)) -> 655233.58 | G29: =IF(Dashboard!$B$6="Base Case",Scenarios!G83,IF(Dashboard!$B$6="Optimistic",Scenarios!G169,Scenarios!G255)) -> 794585.4 | H29: =IF(Dashboard!$B$6="Base Case",Scenarios!H83,IF(Dashboard!$B$6="Optimistic",Scenarios!H169,Scenarios!H255)) -> 947161.42
A30: 📊 KEY RATIOS
A31: Current Ratio | B31: =IF(Dashboard!$B$6="Base Case",Scenarios!B84,IF(Dashboard!$B$6="Optimistic",Scenarios!B170,Scenarios!B256)) -> 1.8551339 | C31: =IF(Dashboard!$B$6="Base Case",Scenarios!C84,IF(Dashboard!$B$6="Optimistic",Scenarios!C170,Scenarios!C256)) -> 1.966866 | D31: =IF(Dashboard!$B$6="Base Case",Scenarios!D84,IF(Dashboard!$B$6="Optimistic",Scenarios!D170,Scenarios!D256)) -> 1.8033242 | E31: =IF(Dashboard!$B$6="Base Case",Scenarios!E84,IF(Dashboard!$B$6="Optimistic",Scenarios!E170,Scenarios!E256)) -> 2.0540479 | F31: =IF(Dashboard!$B$6="Base Case",Scenarios!F84,IF(Dashboard!$B$6="Optimistic",Scenarios!F170,Scenarios!F256)) -> 2.3202115 | G31: =IF(Dashboard!$B$6="Base Case",Scenarios!G84,IF(Dashboard!$B$6="Optimistic",Scenarios!G170,Scenarios!G256)) -> 2.5960313 | H31: =IF(Dashboard!$B$6="Base Case",Scenarios!H84,IF(Dashboard!$B$6="Optimistic",Scenarios!H170,Scenarios!H256)) -> 2.8902554
A32: Debt / Equity | B32: =IF(Dashboard!$B$6="Base Case",Scenarios!B85,IF(Dashboard!$B$6="Optimistic",Scenarios!B171,Scenarios!B257)) -> 1.2056763 | C32: =IF(Dashboard!$B$6="Base Case",Scenarios!C85,IF(Dashboard!$B$6="Optimistic",Scenarios!C171,Scenarios!C257)) -> 0.90759985 | D32: =IF(Dashboard!$B$6="Base Case",Scenarios!D85,IF(Dashboard!$B$6="Optimistic",Scenarios!D171,Scenarios!D257)) -> 0.69437206 | E32: =IF(Dashboard!$B$6="Base Case",Scenarios!E85,IF(Dashboard!$B$6="Optimistic",Scenarios!E171,Scenarios!E257)) -> 0.54207701 | F32: =IF(Dashboard!$B$6="Base Case",Scenarios!F85,IF(Dashboard!$B$6="Optimistic",Scenarios!F171,Scenarios!F257)) -> 0.43558262 | G32: =IF(Dashboard!$B$6="Base Case",Scenarios!G85,IF(Dashboard!$B$6="Optimistic",Scenarios!G171,Scenarios!G257)) -> 0.35976772 | H32: =IF(Dashboard!$B$6="Base Case",Scenarios!H85,IF(Dashboard!$B$6="Optimistic",Scenarios!H171,Scenarios!H257)) -> 0.3029953
A33: ROE % | B33: =IF(Dashboard!$B$6="Base Case",Scenarios!B86,IF(Dashboard!$B$6="Optimistic",Scenarios!B172,Scenarios!B258)) -> 0.33794103 | C33: =IF(Dashboard!$B$6="Base Case",Scenarios!C86,IF(Dashboard!$B$6="Optimistic",Scenarios!C172,Scenarios!C258)) -> 0.34485914 | D33: =IF(Dashboard!$B$6="Base Case",Scenarios!D86,IF(Dashboard!$B$6="Optimistic",Scenarios!D172,Scenarios!D258)) -> 0.41585981 | E33: =IF(Dashboard!$B$6="Base Case",Scenarios!E86,IF(Dashboard!$B$6="Optimistic",Scenarios!E172,Scenarios!E258)) -> 0.39102003 | F33: =IF(Dashboard!$B$6="Base Case",Scenarios!F86,IF(Dashboard!$B$6="Optimistic",Scenarios!F172,Scenarios!F258)) -> 0.34580278 | G33: =IF(Dashboard!$B$6="Base Case",Scenarios!G86,IF(Dashboard!$B$6="Optimistic",Scenarios!G172,Scenarios!G258)) -> 0.30261158 | H33: =IF(Dashboard!$B$6="Base Case",Scenarios!H86,IF(Dashboard!$B$6="Optimistic",Scenarios!H172,Scenarios!H258)) -> 0.27193717
A34: ROIC % | B34: =IF(Dashboard!$B$6="Base Case",Scenarios!B87,IF(Dashboard!$B$6="Optimistic",Scenarios!B173,Scenarios!B259)) -> 0.24878084 | C34: =IF(Dashboard!$B$6="Base Case",Scenarios!C87,IF(Dashboard!$B$6="Optimistic",Scenarios!C173,Scenarios!C259)) -> 0.27245454 | D34: =IF(Dashboard!$B$6="Base Case",Scenarios!D87,IF(Dashboard!$B$6="Optimistic",Scenarios!D173,Scenarios!D259)) -> 0.45766787 | E34: =IF(Dashboard!$B$6="Base Case",Scenarios!E87,IF(Dashboard!$B$6="Optimistic",Scenarios!E173,Scenarios!E259)) -> 0.59869229 | F34: =IF(Dashboard!$B$6="Base Case",Scenarios!F87,IF(Dashboard!$B$6="Optimistic",Scenarios!F173,Scenarios!F259)) -> 0.63623372 | G34: =IF(Dashboard!$B$6="Base Case",Scenarios!G87,IF(Dashboard!$B$6="Optimistic",Scenarios!G173,Scenarios!G259)) -> 0.67337831 | H34: =IF(Dashboard!$B$6="Base Case",Scenarios!H87,IF(Dashboard!$B$6="Optimistic",Scenarios!H173,Scenarios!H259)) -> 0.71143182
A35: ROA % | B35: =IF(Dashboard!$B$6="Base Case",Scenarios!B88,IF(Dashboard!$B$6="Optimistic",Scenarios!B174,Scenarios!B260)) -> 0.11724202 | C35: =IF(Dashboard!$B$6="Base Case",Scenarios!C88,IF(Dashboard!$B$6="Optimistic",Scenarios!C174,Scenarios!C260)) -> 0.12936793 | D35: =IF(Dashboard!$B$6="Base Case",Scenarios!D88,IF(Dashboard!$B$6="Optimistic",Scenarios!D174,Scenarios!D260)) -> 0.16613 | E35: =IF(Dashboard!$B$6="Base Case",Scenarios!E88,IF(Dashboard!$B$6="Optimistic",Scenarios!E174,Scenarios!E260)) -> 0.16646884 | F35: =IF(Dashboard!$B$6="Base Case",Scenarios!F88,IF(Dashboard!$B$6="Optimistic",Scenarios!F174,Scenarios!F260)) -> 0.16427297 | G35: =IF(Dashboard!$B$6="Base Case",Scenarios!G88,IF(Dashboard!$B$6="Optimistic",Scenarios!G174,Scenarios!G260)) -> 0.15695416 | H35: =IF(Dashboard!$B$6="Base Case",Scenarios!H88,IF(Dashboard!$B$6="Optimistic",Scenarios!H174,Scenarios!H260)) -> 0.1515287
A38: ⚖️ SCENARIO COMPARISON — Terminal Year
A39: Metric | B39: Active Scenario
A40: Revenue | B40: =IF(Dashboard!$B$6="Base Case",Scenarios!H67,IF(Dashboard!$B$6="Optimistic",Scenarios!H153,Scenarios!H239)) -> 1344061
A41: EBITDA | B41: =IF(Dashboard!$B$6="Base Case",Scenarios!H71,IF(Dashboard!$B$6="Optimistic",Scenarios!H157,Scenarios!H243)) -> 309134.04
A42: Net Income | B42: =IF(Dashboard!$B$6="Base Case",Scenarios!H74,IF(Dashboard!$B$6="Optimistic",Scenarios!H160,Scenarios!H246)) -> 231471.1
A43: Free Cash Flow | B43: =IF(Dashboard!$B$6="Base Case",Scenarios!H78,IF(Dashboard!$B$6="Optimistic",Scenarios!H164,Scenarios!H250)) -> 238220.32
A44: Cash Balance | B44: =IF(Dashboard!$B$6="Base Case",Scenarios!H83,IF(Dashboard!$B$6="Optimistic",Scenarios!H169,Scenarios!H255)) -> 947161.42
...

Sheet Company Info
A1: COMPANY INFORMATION & MODEL CONFIGURATION
A3: SECTION 1 — COMPANY IDENTIFICATION
A4: Company Name | B4: Demo Company Inc. | C4: ← Edit
A5: Legal Entity Type | B5: Société Anonyme (S.A.E.) | C5: ← Edit
A6: Industry / Sector | B6: Technology / Software | C6: ← Edit
A7: Founded Year | B7: 2010 | C7: ← Edit
A8: Commercial Register No. | B8: 12345-Cairo-2010 | C8: Auto
A9: Tax Identification No. | B9: 123-456-789 | C9: Auto
A10: Headquarters Address | B10: 5 El-Nile Street, Zamalek, Cairo, Egypt | C10: Auto
A12: SECTION 2 — FINANCIAL MODEL CONFIGURATION
A13: Reporting Currency | B13: Egyptian Pound (EGP) | C13: Auto
A14: Currency Symbol | B14: E£ | C14: Auto
A15: Fiscal Year End | B15: December 31 | C15: ← Edit
A16: Historical Period | B16: 2024 – 2025 (Actual) | C16: Auto
A17: Projection Period | B17: 2026E – 2030E (5 Years) | C17: Auto
A18: Model Version | B18: 3SM-v8 | Apr 2026 | C18: Auto
A19: Last Updated | B19: April 26, 2026 | C19: Auto
A21: SECTION 3 — EGYPT REGULATORY / TAX
A22: Corporate Income Tax Rate | B22: 0.225 | C22: Auto
A23: VAT Rate (Standard) | B23: 0.14 | C23: Auto
A24: Dividend Withholding Tax | B24: 0.1 | C24: Auto
A25: CBE Policy Rate (Discount) | B25: 0.195 | C25: Auto
A26: Risk-Free Rate (12M T-Bill) | B26: 0.235 | C26: Auto
A27: Financial Year Note | B27: July 1 – June 30 (Note: model uses Dec) | C27: Auto
A29: SECTION 4 — REPORT & PREPARER INFORMATION
A30: Prepared By | B30: Financial Modeling Team | C30: ← Edit
A31: Reviewed By | B31: CFO | C31: ← Edit
A32: Preparation Date | B32: April 26, 2026 | C32: Auto
A33: Purpose | B33: Internal Planning & Analysis | C33: ← Edit
A34: Confidentiality | B34: CONFIDENTIAL — Internal Use Only | C34: ← Edit
A35: Contact Email | B35: finance@democompany.com | C35: ← Edit
A37: Note: All financial rates are driven by the WOLF engine. To update rates, use "Refresh Rates" in the engine dashboard, then re-export.

Sheet Scenarios
A1: SCENARIO DATA — COMPLETE ENGINE VALUES
A2: This sheet stores the full engine-computed data for each scenario. All projection columns in Assumptions reference this sheet via IF formulas.
A4: ▎ BASE CASE · Moderate growth with stable margins
A5: Assumption / Computed Value | B5: 2024 | C5: 2025 | D5: 2026E | E5: 2027E | F5: 2028E | G5: 2029E | H5: 2030E
A6: ── Income Statement Drivers ──
A7: Revenue (Year 1 Historical) | B7: 850000 | C7: 0 | D7: 0 | E7: 0 | F7: 0 | G7: 0 | H7: 0
A8: Revenue Growth Rate | B8: 0 | C8: 0.11764706 | D8: 0.1 | E8: 0.08 | F8: 0.07 | G8: 0.06 | H8: 0.05
A9: COGS % of Revenue | B9: 0.6 | C9: 0.6 | D9: 0.6 | E9: 0.6 | F9: 0.6 | G9: 0.6 | H9: 0.6
A10: SG&A % of Revenue | B10: 0.15 | C10: 0.15 | D10: 0.15 | E10: 0.15 | F10: 0.15 | G10: 0.15 | H10: 0.15
A11: R&D % of Revenue | B11: 0.05 | C11: 0.05 | D11: 0 | E11: 0 | F11: 0 | G11: 0 | H11: 0
A12: Other OpEx % of Revenue | B12: 0.02 | C12: 0.02 | D12: 0.02 | E12: 0.02 | F12: 0.02 | G12: 0.02 | H12: 0.02
A13: Tax Rate | B13: 0.225 | C13: 0.225 | D13: 0.225 | E13: 0.225 | F13: 0.225 | G13: 0.225 | H13: 0.225
A14: Other Income / Expense | B14: 0 | C14: 0 | D14: 0 | E14: 0 | F14: 0 | G14: 0 | H14: 0
A15: Shares Outstanding | B15: 100000 | C15: 100000 | D15: 100000 | E15: 100000 | F15: 100000 | G15: 100000 | H15: 100000
A16: Stock-Based Comp Amount | B16: 0 | C16: 0 | D16: 0 | E16: 0 | F16: 0 | G16: 0 | H16: 0
A17: EPD Rate (Employee Profit Sharing) | B17: 0.1 | C17: 0.1 | D17: 0.1 | E17: 0.1 | F17: 0.1 | G17: 0.1 | H17: 0.1
A18: Issued (Paid-Up) Capital | B18: 10000 | C18: 10000 | D18: 10000 | E18: 10000 | F18: 10000 | G18: 10000 | H18: 10000
A19: ── Balance Sheet / WC Drivers ──
A20: DSO (Days) | B20: 45 | C20: 45 | D20: 45 | E20: 45 | F20: 45 | G20: 45 | H20: 45
A21: DIO (Days) | B21: 30 | C21: 30 | D21: 30 | E21: 30 | F21: 30 | G21: 30 | H21: 30
A22: DPO (Days) | B22: 40 | C22: 40 | D22: 40 | E22: 40 | F22: 40 | G22: 40 | H22: 40
A23: Prepaid % of Revenue | B23: 0.01 | C23: 0.01 | D23: 0.01 | E23: 0.01 | F23: 0.01 | G23: 0.01 | H23: 0.01
A24: Accrued Exp % of Revenue | B24: 0.03 | C24: 0.03 | D24: 0.03 | E24: 0.03 | F24: 0.03 | G24: 0.03 | H24: 0.03
A25: Deferred Rev % of Revenue | B25: 0.02 | C25: 0.02 | D25: 0.02 | E25: 0.02 | F25: 0.02 | G25: 0.02 | H25: 0.02
A26: ── CapEx & Depreciation ──
A27: CapEx % of Revenue | B27: 0 | C27: 0.047368 | D27: 0.05 | E27: 0.05 | F27: 0.05 | G27: 0.05 | H27: 0.05
A28: Depreciation Rate (% Gross PPE) | B28: 0.082352941 | C28: 0.083116883 | D28: 0.1 | E28: 0.1 | F28: 0.1 | G28: 0.1 | H28: 0.1
A29: Amortization Amount | B29: 5000 | C29: 5000 | D29: 5000 | E29: 5000 | F29: 5000 | G29: 5000 | H29: 5000
A30: ── Debt & Financing ──
A31: Interest Rate (on Debt) | B31: 0.22 | C31: 0.22 | D31: 0.22 | E31: 0.2 | F31: 0.18 | G31: 0.17 | H31: 0.16
A32: Interest Income Rate (on Cash) | B32: 0.19 | C32: 0.19 | D32: 0.19 | E32: 0.17 | F32: 0.15 | G32: 0.13 | H32: 0.12
A33: Short-Term Debt | B33: 50000 | C33: 50000 | D33: 50000 | E33: 50000 | F33: 50000 | G33: 50000 | H33: 50000
A34: LT Debt Issuance | B34: 0 | C34: 0 | D34: 0 | E34: 0 | F34: 0 | G34: 0 | H34: 0
A35: LT Debt Repayment | B35: 0 | C35: 20000 | D35: 0 | E35: 0 | F35: 0 | G35: 0 | H35: 0
A36: Current Portion LTD | B36: 20000 | C36: 20000 | D36: 20000 | E36: 20000 | F36: 20000 | G36: 20000 | H36: 20000
A37: Dividend Payout Ratio | B37: 0 | C37: 0.48300728 | D37: 0.3 | E37: 0.3 | F37: 0.3 | G37: 0.3 | H37: 0.3
A38: Share Repurchase Amount | B38: 0 | C38: 0 | D38: 0 | E38: 0 | F38: 0 | G38: 0 | H38: 0
A39: Equity Issuance | B39: 0 | C39: 10000 | D39: 0 | E39: 0 | F39: 0 | G39: 0 | H39: 0
A40: ── VAT Settings ──
A41: Enable VAT | B41: 1 | C41: 1 | D41: 1 | E41: 1 | F41: 1 | G41: 1 | H41: 1
...

Sheet Assumptions
A1: Assumption | B1: 2024 | C1: 2025 | D1: 2026E | E1: 2027E | F1: 2028E | G1: 2029E | H1: 2030E
A2: ── Income Statement Drivers ──
A3: Revenue (Year 1 Historical) | B3: 850000 | D3: =IF(Assumptions!$B$67="Base Case",Scenarios!D7,IF(Assumptions!$B$67="Optimistic",Scenarios!D93,Scenarios!D179)) -> 0 | E3: =IF(Assumptions!$B$67="Base Case",Scenarios!E7,IF(Assumptions!$B$67="Optimistic",Scenarios!E93,Scenarios!E179)) -> 0 | F3: =IF(Assumptions!$B$67="Base Case",Scenarios!F7,IF(Assumptions!$B$67="Optimistic",Scenarios!F93,Scenarios!F179)) -> 0 | G3: =IF(Assumptions!$B$67="Base Case",Scenarios!G7,IF(Assumptions!$B$67="Optimistic",Scenarios!G93,Scenarios!G179)) -> 0 | H3: =IF(Assumptions!$B$67="Base Case",Scenarios!H7,IF(Assumptions!$B$67="Optimistic",Scenarios!H93,Scenarios!H179)) -> 0
A4: Revenue Growth Rate | D4: =IF(Assumptions!$B$67="Base Case",Scenarios!D8,IF(Assumptions!$B$67="Optimistic",Scenarios!D94,Scenarios!D180)) -> 0.1 | E4: =IF(Assumptions!$B$67="Base Case",Scenarios!E8,IF(Assumptions!$B$67="Optimistic",Scenarios!E94,Scenarios!E180)) -> 0.08 | F4: =IF(Assumptions!$B$67="Base Case",Scenarios!F8,IF(Assumptions!$B$67="Optimistic",Scenarios!F94,Scenarios!F180)) -> 0.07 | G4: =IF(Assumptions!$B$67="Base Case",Scenarios!G8,IF(Assumptions!$B$67="Optimistic",Scenarios!G94,Scenarios!G180)) -> 0.06 | H4: =IF(Assumptions!$B$67="Base Case",Scenarios!H8,IF(Assumptions!$B$67="Optimistic",Scenarios!H94,Scenarios!H180)) -> 0.05
A5: COGS % of Revenue | D5: =IF(Assumptions!$B$67="Base Case",Scenarios!D9,IF(Assumptions!$B$67="Optimistic",Scenarios!D95,Scenarios!D181)) -> 0.6 | E5: =IF(Assumptions!$B$67="Base Case",Scenarios!E9,IF(Assumptions!$B$67="Optimistic",Scenarios!E95,Scenarios!E181)) -> 0.6 | F5: =IF(Assumptions!$B$67="Base Case",Scenarios!F9,IF(Assumptions!$B$67="Optimistic",Scenarios!F95,Scenarios!F181)) -> 0.6 | G5: =IF(Assumptions!$B$67="Base Case",Scenarios!G9,IF(Assumptions!$B$67="Optimistic",Scenarios!G95,Scenarios!G181)) -> 0.6 | H5: =IF(Assumptions!$B$67="Base Case",Scenarios!H9,IF(Assumptions!$B$67="Optimistic",Scenarios!H95,Scenarios!H181)) -> 0.6
A6: SG&A % of Revenue | D6: =IF(Assumptions!$B$67="Base Case",Scenarios!D10,IF(Assumptions!$B$67="Optimistic",Scenarios!D96,Scenarios!D182)) -> 0.15 | E6: =IF(Assumptions!$B$67="Base Case",Scenarios!E10,IF(Assumptions!$B$67="Optimistic",Scenarios!E96,Scenarios!E182)) -> 0.15 | F6: =IF(Assumptions!$B$67="Base Case",Scenarios!F10,IF(Assumptions!$B$67="Optimistic",Scenarios!F96,Scenarios!F182)) -> 0.15 | G6: =IF(Assumptions!$B$67="Base Case",Scenarios!G10,IF(Assumptions!$B$67="Optimistic",Scenarios!G96,Scenarios!G182)) -> 0.15 | H6: =IF(Assumptions!$B$67="Base Case",Scenarios!H10,IF(Assumptions!$B$67="Optimistic",Scenarios!H96,Scenarios!H182)) -> 0.15
A7: R&D % of Revenue | D7: =IF(Assumptions!$B$67="Base Case",Scenarios!D11,IF(Assumptions!$B$67="Optimistic",Scenarios!D97,Scenarios!D183)) -> 0 | E7: =IF(Assumptions!$B$67="Base Case",Scenarios!E11,IF(Assumptions!$B$67="Optimistic",Scenarios!E97,Scenarios!E183)) -> 0 | F7: =IF(Assumptions!$B$67="Base Case",Scenarios!F11,IF(Assumptions!$B$67="Optimistic",Scenarios!F97,Scenarios!F183)) -> 0 | G7: =IF(Assumptions!$B$67="Base Case",Scenarios!G11,IF(Assumptions!$B$67="Optimistic",Scenarios!G97,Scenarios!G183)) -> 0 | H7: =IF(Assumptions!$B$67="Base Case",Scenarios!H11,IF(Assumptions!$B$67="Optimistic",Scenarios!H97,Scenarios!H183)) -> 0
A8: Other OpEx % of Revenue | D8: =IF(Assumptions!$B$67="Base Case",Scenarios!D12,IF(Assumptions!$B$67="Optimistic",Scenarios!D98,Scenarios!D184)) -> 0.02 | E8: =IF(Assumptions!$B$67="Base Case",Scenarios!E12,IF(Assumptions!$B$67="Optimistic",Scenarios!E98,Scenarios!E184)) -> 0.02 | F8: =IF(Assumptions!$B$67="Base Case",Scenarios!F12,IF(Assumptions!$B$67="Optimistic",Scenarios!F98,Scenarios!F184)) -> 0.02 | G8: =IF(Assumptions!$B$67="Base Case",Scenarios!G12,IF(Assumptions!$B$67="Optimistic",Scenarios!G98,Scenarios!G184)) -> 0.02 | H8: =IF(Assumptions!$B$67="Base Case",Scenarios!H12,IF(Assumptions!$B$67="Optimistic",Scenarios!H98,Scenarios!H184)) -> 0.02
A9: Tax Rate | D9: =IF(Assumptions!$B$67="Base Case",Scenarios!D13,IF(Assumptions!$B$67="Optimistic",Scenarios!D99,Scenarios!D185)) -> 0.225 | E9: =IF(Assumptions!$B$67="Base Case",Scenarios!E13,IF(Assumptions!$B$67="Optimistic",Scenarios!E99,Scenarios!E185)) -> 0.225 | F9: =IF(Assumptions!$B$67="Base Case",Scenarios!F13,IF(Assumptions!$B$67="Optimistic",Scenarios!F99,Scenarios!F185)) -> 0.225 | G9: =IF(Assumptions!$B$67="Base Case",Scenarios!G13,IF(Assumptions!$B$67="Optimistic",Scenarios!G99,Scenarios!G185)) -> 0.225 | H9: =IF(Assumptions!$B$67="Base Case",Scenarios!H13,IF(Assumptions!$B$67="Optimistic",Scenarios!H99,Scenarios!H185)) -> 0.225
A10: VAT Enabled (1=Yes) | D10: =IF(Assumptions!$B$67="Base Case",Scenarios!D41,IF(Assumptions!$B$67="Optimistic",Scenarios!D127,Scenarios!D213)) -> 1 | E10: =IF(Assumptions!$B$67="Base Case",Scenarios!E41,IF(Assumptions!$B$67="Optimistic",Scenarios!E127,Scenarios!E213)) -> 1 | F10: =IF(Assumptions!$B$67="Base Case",Scenarios!F41,IF(Assumptions!$B$67="Optimistic",Scenarios!F127,Scenarios!F213)) -> 1 | G10: =IF(Assumptions!$B$67="Base Case",Scenarios!G41,IF(Assumptions!$B$67="Optimistic",Scenarios!G127,Scenarios!G213)) -> 1 | H10: =IF(Assumptions!$B$67="Base Case",Scenarios!H41,IF(Assumptions!$B$67="Optimistic",Scenarios!H127,Scenarios!H213)) -> 1
A11: VAT Rate | D11: =IF(Assumptions!$B$67="Base Case",Scenarios!D42,IF(Assumptions!$B$67="Optimistic",Scenarios!D128,Scenarios!D214)) -> 0.14 | E11: =IF(Assumptions!$B$67="Base Case",Scenarios!E42,IF(Assumptions!$B$67="Optimistic",Scenarios!E128,Scenarios!E214)) -> 0.14 | F11: =IF(Assumptions!$B$67="Base Case",Scenarios!F42,IF(Assumptions!$B$67="Optimistic",Scenarios!F128,Scenarios!F214)) -> 0.14 | G11: =IF(Assumptions!$B$67="Base Case",Scenarios!G42,IF(Assumptions!$B$67="Optimistic",Scenarios!G128,Scenarios!G214)) -> 0.14 | H11: =IF(Assumptions!$B$67="Base Case",Scenarios!H42,IF(Assumptions!$B$67="Optimistic",Scenarios!H128,Scenarios!H214)) -> 0.14
A12: Other Income / Expense | D12: =IF(Assumptions!$B$67="Base Case",Scenarios!D14,IF(Assumptions!$B$67="Optimistic",Scenarios!D100,Scenarios!D186)) -> 0 | E12: =IF(Assumptions!$B$67="Base Case",Scenarios!E14,IF(Assumptions!$B$67="Optimistic",Scenarios!E100,Scenarios!E186)) -> 0 | F12: =IF(Assumptions!$B$67="Base Case",Scenarios!F14,IF(Assumptions!$B$67="Optimistic",Scenarios!F100,Scenarios!F186)) -> 0 | G12: =IF(Assumptions!$B$67="Base Case",Scenarios!G14,IF(Assumptions!$B$67="Optimistic",Scenarios!G100,Scenarios!G186)) -> 0 | H12: =IF(Assumptions!$B$67="Base Case",Scenarios!H14,IF(Assumptions!$B$67="Optimistic",Scenarios!H100,Scenarios!H186)) -> 0
A13: Shares Outstanding | D13: =IF(Assumptions!$B$67="Base Case",Scenarios!D15,IF(Assumptions!$B$67="Optimistic",Scenarios!D101,Scenarios!D187)) -> 100000 | E13: =IF(Assumptions!$B$67="Base Case",Scenarios!E15,IF(Assumptions!$B$67="Optimistic",Scenarios!E101,Scenarios!E187)) -> 100000 | F13: =IF(Assumptions!$B$67="Base Case",Scenarios!F15,IF(Assumptions!$B$67="Optimistic",Scenarios!F101,Scenarios!F187)) -> 100000 | G13: =IF(Assumptions!$B$67="Base Case",Scenarios!G15,IF(Assumptions!$B$67="Optimistic",Scenarios!G101,Scenarios!G187)) -> 100000 | H13: =IF(Assumptions!$B$67="Base Case",Scenarios!H15,IF(Assumptions!$B$67="Optimistic",Scenarios!H101,Scenarios!H187)) -> 100000
A14: Stock-Based Comp Amount | D14: =IF(Assumptions!$B$67="Base Case",Scenarios!D16,IF(Assumptions!$B$67="Optimistic",Scenarios!D102,Scenarios!D188)) -> 0 | E14: =IF(Assumptions!$B$67="Base Case",Scenarios!E16,IF(Assumptions!$B$67="Optimistic",Scenarios!E102,Scenarios!E188)) -> 0 | F14: =IF(Assumptions!$B$67="Base Case",Scenarios!F16,IF(Assumptions!$B$67="Optimistic",Scenarios!F102,Scenarios!F188)) -> 0 | G14: =IF(Assumptions!$B$67="Base Case",Scenarios!G16,IF(Assumptions!$B$67="Optimistic",Scenarios!G102,Scenarios!G188)) -> 0 | H14: =IF(Assumptions!$B$67="Base Case",Scenarios!H16,IF(Assumptions!$B$67="Optimistic",Scenarios!H102,Scenarios!H188)) -> 0
A15: ── Balance Sheet / WC Drivers ──
A16: DSO (Days) | D16: =IF(Assumptions!$B$67="Base Case",Scenarios!D20,IF(Assumptions!$B$67="Optimistic",Scenarios!D106,Scenarios!D192)) -> 45 | E16: =IF(Assumptions!$B$67="Base Case",Scenarios!E20,IF(Assumptions!$B$67="Optimistic",Scenarios!E106,Scenarios!E192)) -> 45 | F16: =IF(Assumptions!$B$67="Base Case",Scenarios!F20,IF(Assumptions!$B$67="Optimistic",Scenarios!F106,Scenarios!F192)) -> 45 | G16: =IF(Assumptions!$B$67="Base Case",Scenarios!G20,IF(Assumptions!$B$67="Optimistic",Scenarios!G106,Scenarios!G192)) -> 45 | H16: =IF(Assumptions!$B$67="Base Case",Scenarios!H20,IF(Assumptions!$B$67="Optimistic",Scenarios!H106,Scenarios!H192)) -> 45
A17: DIO (Days) | D17: =IF(Assumptions!$B$67="Base Case",Scenarios!D21,IF(Assumptions!$B$67="Optimistic",Scenarios!D107,Scenarios!D193)) -> 30 | E17: =IF(Assumptions!$B$67="Base Case",Scenarios!E21,IF(Assumptions!$B$67="Optimistic",Scenarios!E107,Scenarios!E193)) -> 30 | F17: =IF(Assumptions!$B$67="Base Case",Scenarios!F21,IF(Assumptions!$B$67="Optimistic",Scenarios!F107,Scenarios!F193)) -> 30 | G17: =IF(Assumptions!$B$67="Base Case",Scenarios!G21,IF(Assumptions!$B$67="Optimistic",Scenarios!G107,Scenarios!G193)) -> 30 | H17: =IF(Assumptions!$B$67="Base Case",Scenarios!H21,IF(Assumptions!$B$67="Optimistic",Scenarios!H107,Scenarios!H193)) -> 30
A18: DPO (Days) | D18: =IF(Assumptions!$B$67="Base Case",Scenarios!D22,IF(Assumptions!$B$67="Optimistic",Scenarios!D108,Scenarios!D194)) -> 40 | E18: =IF(Assumptions!$B$67="Base Case",Scenarios!E22,IF(Assumptions!$B$67="Optimistic",Scenarios!E108,Scenarios!E194)) -> 40 | F18: =IF(Assumptions!$B$67="Base Case",Scenarios!F22,IF(Assumptions!$B$67="Optimistic",Scenarios!F108,Scenarios!F194)) -> 40 | G18: =IF(Assumptions!$B$67="Base Case",Scenarios!G22,IF(Assumptions!$B$67="Optimistic",Scenarios!G108,Scenarios!G194)) -> 40 | H18: =IF(Assumptions!$B$67="Base Case",Scenarios!H22,IF(Assumptions!$B$67="Optimistic",Scenarios!H108,Scenarios!H194)) -> 40
A19: Prepaid % of Revenue | D19: =IF(Assumptions!$B$67="Base Case",Scenarios!D23,IF(Assumptions!$B$67="Optimistic",Scenarios!D109,Scenarios!D195)) -> 0.01 | E19: =IF(Assumptions!$B$67="Base Case",Scenarios!E23,IF(Assumptions!$B$67="Optimistic",Scenarios!E109,Scenarios!E195)) -> 0.01 | F19: =IF(Assumptions!$B$67="Base Case",Scenarios!F23,IF(Assumptions!$B$67="Optimistic",Scenarios!F109,Scenarios!F195)) -> 0.01 | G19: =IF(Assumptions!$B$67="Base Case",Scenarios!G23,IF(Assumptions!$B$67="Optimistic",Scenarios!G109,Scenarios!G195)) -> 0.01 | H19: =IF(Assumptions!$B$67="Base Case",Scenarios!H23,IF(Assumptions!$B$67="Optimistic",Scenarios!H109,Scenarios!H195)) -> 0.01
A20: Accrued Exp % of Revenue | D20: =IF(Assumptions!$B$67="Base Case",Scenarios!D24,IF(Assumptions!$B$67="Optimistic",Scenarios!D110,Scenarios!D196)) -> 0.03 | E20: =IF(Assumptions!$B$67="Base Case",Scenarios!E24,IF(Assumptions!$B$67="Optimistic",Scenarios!E110,Scenarios!E196)) -> 0.03 | F20: =IF(Assumptions!$B$67="Base Case",Scenarios!F24,IF(Assumptions!$B$67="Optimistic",Scenarios!F110,Scenarios!F196)) -> 0.03 | G20: =IF(Assumptions!$B$67="Base Case",Scenarios!G24,IF(Assumptions!$B$67="Optimistic",Scenarios!G110,Scenarios!G196)) -> 0.03 | H20: =IF(Assumptions!$B$67="Base Case",Scenarios!H24,IF(Assumptions!$B$67="Optimistic",Scenarios!H110,Scenarios!H196)) -> 0.03
A21: Deferred Rev % of Revenue | D21: =IF(Assumptions!$B$67="Base Case",Scenarios!D25,IF(Assumptions!$B$67="Optimistic",Scenarios!D111,Scenarios!D197)) -> 0.02 | E21: =IF(Assumptions!$B$67="Base Case",Scenarios!E25,IF(Assumptions!$B$67="Optimistic",Scenarios!E111,Scenarios!E197)) -> 0.02 | F21: =IF(Assumptions!$B$67="Base Case",Scenarios!F25,IF(Assumptions!$B$67="Optimistic",Scenarios!F111,Scenarios!F197)) -> 0.02 | G21: =IF(Assumptions!$B$67="Base Case",Scenarios!G25,IF(Assumptions!$B$67="Optimistic",Scenarios!G111,Scenarios!G197)) -> 0.02 | H21: =IF(Assumptions!$B$67="Base Case",Scenarios!H25,IF(Assumptions!$B$67="Optimistic",Scenarios!H111,Scenarios!H197)) -> 0.02
A22: ── CapEx & Depreciation Drivers ──
A23: CapEx % of Revenue | D23: =IF(Assumptions!$B$67="Base Case",Scenarios!D27,IF(Assumptions!$B$67="Optimistic",Scenarios!D113,Scenarios!D199)) -> 0.05 | E23: =IF(Assumptions!$B$67="Base Case",Scenarios!E27,IF(Assumptions!$B$67="Optimistic",Scenarios!E113,Scenarios!E199)) -> 0.05 | F23: =IF(Assumptions!$B$67="Base Case",Scenarios!F27,IF(Assumptions!$B$67="Optimistic",Scenarios!F113,Scenarios!F199)) -> 0.05 | G23: =IF(Assumptions!$B$67="Base Case",Scenarios!G27,IF(Assumptions!$B$67="Optimistic",Scenarios!G113,Scenarios!G199)) -> 0.05 | H23: =IF(Assumptions!$B$67="Base Case",Scenarios!H27,IF(Assumptions!$B$67="Optimistic",Scenarios!H113,Scenarios!H199)) -> 0.05
A24: Depreciation Rate (% Gross PPE) | D24: =IF(Assumptions!$B$67="Base Case",Scenarios!D28,IF(Assumptions!$B$67="Optimistic",Scenarios!D114,Scenarios!D200)) -> 0.094025157 | E24: =IF(Assumptions!$B$67="Base Case",Scenarios!E28,IF(Assumptions!$B$67="Optimistic",Scenarios!E114,Scenarios!E200)) -> 0.094284759 | F24: =IF(Assumptions!$B$67="Base Case",Scenarios!F28,IF(Assumptions!$B$67="Optimistic",Scenarios!F114,Scenarios!F200)) -> 0.094551124 | G24: =IF(Assumptions!$B$67="Base Case",Scenarios!G28,IF(Assumptions!$B$67="Optimistic",Scenarios!G114,Scenarios!G200)) -> 0.094822299 | H24: =IF(Assumptions!$B$67="Base Case",Scenarios!H28,IF(Assumptions!$B$67="Optimistic",Scenarios!H114,Scenarios!H200)) -> 0.095096572
A25: Amortization Amount | D25: =IF(Assumptions!$B$67="Base Case",Scenarios!D29,IF(Assumptions!$B$67="Optimistic",Scenarios!D115,Scenarios!D201)) -> 5000 | E25: =IF(Assumptions!$B$67="Base Case",Scenarios!E29,IF(Assumptions!$B$67="Optimistic",Scenarios!E115,Scenarios!E201)) -> 5000 | F25: =IF(Assumptions!$B$67="Base Case",Scenarios!F29,IF(Assumptions!$B$67="Optimistic",Scenarios!F115,Scenarios!F201)) -> 5000 | G25: =IF(Assumptions!$B$67="Base Case",Scenarios!G29,IF(Assumptions!$B$67="Optimistic",Scenarios!G115,Scenarios!G201)) -> 5000 | H25: =IF(Assumptions!$B$67="Base Case",Scenarios!H29,IF(Assumptions!$B$67="Optimistic",Scenarios!H115,Scenarios!H201)) -> 5000
A26: ── Debt & Financing ──
A27: Interest Rate (on Debt) | D27: =IF(Assumptions!$B$67="Base Case",Scenarios!D31,IF(Assumptions!$B$67="Optimistic",Scenarios!D117,Scenarios!D203)) -> 0.22 | E27: =IF(Assumptions!$B$67="Base Case",Scenarios!E31,IF(Assumptions!$B$67="Optimistic",Scenarios!E117,Scenarios!E203)) -> 0.2 | F27: =IF(Assumptions!$B$67="Base Case",Scenarios!F31,IF(Assumptions!$B$67="Optimistic",Scenarios!F117,Scenarios!F203)) -> 0.18 | G27: =IF(Assumptions!$B$67="Base Case",Scenarios!G31,IF(Assumptions!$B$67="Optimistic",Scenarios!G117,Scenarios!G203)) -> 0.17 | H27: =IF(Assumptions!$B$67="Base Case",Scenarios!H31,IF(Assumptions!$B$67="Optimistic",Scenarios!H117,Scenarios!H203)) -> 0.16
A28: Interest Income Rate (on Cash) | D28: =IF(Assumptions!$B$67="Base Case",Scenarios!D32,IF(Assumptions!$B$67="Optimistic",Scenarios!D118,Scenarios!D204)) -> 0.19 | E28: =IF(Assumptions!$B$67="Base Case",Scenarios!E32,IF(Assumptions!$B$67="Optimistic",Scenarios!E118,Scenarios!E204)) -> 0.17 | F28: =IF(Assumptions!$B$67="Base Case",Scenarios!F32,IF(Assumptions!$B$67="Optimistic",Scenarios!F118,Scenarios!F204)) -> 0.15 | G28: =IF(Assumptions!$B$67="Base Case",Scenarios!G32,IF(Assumptions!$B$67="Optimistic",Scenarios!G118,Scenarios!G204)) -> 0.13 | H28: =IF(Assumptions!$B$67="Base Case",Scenarios!H32,IF(Assumptions!$B$67="Optimistic",Scenarios!H118,Scenarios!H204)) -> 0.12
A29: EPD Rate (Employee Profit Sharing) | D29: =IF(Assumptions!$B$67="Base Case",Scenarios!D17,IF(Assumptions!$B$67="Optimistic",Scenarios!D103,Scenarios!D189)) -> 0.1 | E29: =IF(Assumptions!$B$67="Base Case",Scenarios!E17,IF(Assumptions!$B$67="Optimistic",Scenarios!E103,Scenarios!E189)) -> 0.1 | F29: =IF(Assumptions!$B$67="Base Case",Scenarios!F17,IF(Assumptions!$B$67="Optimistic",Scenarios!F103,Scenarios!F189)) -> 0.1 | G29: =IF(Assumptions!$B$67="Base Case",Scenarios!G17,IF(Assumptions!$B$67="Optimistic",Scenarios!G103,Scenarios!G189)) -> 0.1 | H29: =IF(Assumptions!$B$67="Base Case",Scenarios!H17,IF(Assumptions!$B$67="Optimistic",Scenarios!H103,Scenarios!H189)) -> 0.1
A30: Short-Term Debt | D30: =IF(Assumptions!$B$67="Base Case",Scenarios!D33,IF(Assumptions!$B$67="Optimistic",Scenarios!D119,Scenarios!D205)) -> 50000 | E30: =IF(Assumptions!$B$67="Base Case",Scenarios!E33,IF(Assumptions!$B$67="Optimistic",Scenarios!E119,Scenarios!E205)) -> 50000 | F30: =IF(Assumptions!$B$67="Base Case",Scenarios!F33,IF(Assumptions!$B$67="Optimistic",Scenarios!F119,Scenarios!F205)) -> 50000 | G30: =IF(Assumptions!$B$67="Base Case",Scenarios!G33,IF(Assumptions!$B$67="Optimistic",Scenarios!G119,Scenarios!G205)) -> 50000 | H30: =IF(Assumptions!$B$67="Base Case",Scenarios!H33,IF(Assumptions!$B$67="Optimistic",Scenarios!H119,Scenarios!H205)) -> 50000
A31: LT Debt Issuance | D31: =IF(Assumptions!$B$67="Base Case",Scenarios!D34,IF(Assumptions!$B$67="Optimistic",Scenarios!D120,Scenarios!D206)) -> 0 | E31: =IF(Assumptions!$B$67="Base Case",Scenarios!E34,IF(Assumptions!$B$67="Optimistic",Scenarios!E120,Scenarios!E206)) -> 0 | F31: =IF(Assumptions!$B$67="Base Case",Scenarios!F34,IF(Assumptions!$B$67="Optimistic",Scenarios!F120,Scenarios!F206)) -> 0 | G31: =IF(Assumptions!$B$67="Base Case",Scenarios!G34,IF(Assumptions!$B$67="Optimistic",Scenarios!G120,Scenarios!G206)) -> 0 | H31: =IF(Assumptions!$B$67="Base Case",Scenarios!H34,IF(Assumptions!$B$67="Optimistic",Scenarios!H120,Scenarios!H206)) -> 0
A32: LT Debt Repayment | D32: =IF(Assumptions!$B$67="Base Case",Scenarios!D35,IF(Assumptions!$B$67="Optimistic",Scenarios!D121,Scenarios!D207)) -> 0 | E32: =IF(Assumptions!$B$67="Base Case",Scenarios!E35,IF(Assumptions!$B$67="Optimistic",Scenarios!E121,Scenarios!E207)) -> 0 | F32: =IF(Assumptions!$B$67="Base Case",Scenarios!F35,IF(Assumptions!$B$67="Optimistic",Scenarios!F121,Scenarios!F207)) -> 0 | G32: =IF(Assumptions!$B$67="Base Case",Scenarios!G35,IF(Assumptions!$B$67="Optimistic",Scenarios!G121,Scenarios!G207)) -> 0 | H32: =IF(Assumptions!$B$67="Base Case",Scenarios!H35,IF(Assumptions!$B$67="Optimistic",Scenarios!H121,Scenarios!H207)) -> 0
A33: Current Portion LTD | D33: =IF(Assumptions!$B$67="Base Case",Scenarios!D36,IF(Assumptions!$B$67="Optimistic",Scenarios!D122,Scenarios!D208)) -> 20000 | E33: =IF(Assumptions!$B$67="Base Case",Scenarios!E36,IF(Assumptions!$B$67="Optimistic",Scenarios!E122,Scenarios!E208)) -> 20000 | F33: =IF(Assumptions!$B$67="Base Case",Scenarios!F36,IF(Assumptions!$B$67="Optimistic",Scenarios!F122,Scenarios!F208)) -> 20000 | G33: =IF(Assumptions!$B$67="Base Case",Scenarios!G36,IF(Assumptions!$B$67="Optimistic",Scenarios!G122,Scenarios!G208)) -> 20000 | H33: =IF(Assumptions!$B$67="Base Case",Scenarios!H36,IF(Assumptions!$B$67="Optimistic",Scenarios!H122,Scenarios!H208)) -> 20000
A34: Dividend Payout Ratio | D34: =IF(Assumptions!$B$67="Base Case",Scenarios!D37,IF(Assumptions!$B$67="Optimistic",Scenarios!D123,Scenarios!D209)) -> 0.3 | E34: =IF(Assumptions!$B$67="Base Case",Scenarios!E37,IF(Assumptions!$B$67="Optimistic",Scenarios!E123,Scenarios!E209)) -> 0.3 | F34: =IF(Assumptions!$B$67="Base Case",Scenarios!F37,IF(Assumptions!$B$67="Optimistic",Scenarios!F123,Scenarios!F209)) -> 0.3 | G34: =IF(Assumptions!$B$67="Base Case",Scenarios!G37,IF(Assumptions!$B$67="Optimistic",Scenarios!G123,Scenarios!G209)) -> 0.3 | H34: =IF(Assumptions!$B$67="Base Case",Scenarios!H37,IF(Assumptions!$B$67="Optimistic",Scenarios!H123,Scenarios!H209)) -> 0.3
A35: Share Repurchase Amount | D35: =IF(Assumptions!$B$67="Base Case",Scenarios!D38,IF(Assumptions!$B$67="Optimistic",Scenarios!D124,Scenarios!D210)) -> 0 | E35: =IF(Assumptions!$B$67="Base Case",Scenarios!E38,IF(Assumptions!$B$67="Optimistic",Scenarios!E124,Scenarios!E210)) -> 0 | F35: =IF(Assumptions!$B$67="Base Case",Scenarios!F38,IF(Assumptions!$B$67="Optimistic",Scenarios!F124,Scenarios!F210)) -> 0 | G35: =IF(Assumptions!$B$67="Base Case",Scenarios!G38,IF(Assumptions!$B$67="Optimistic",Scenarios!G124,Scenarios!G210)) -> 0 | H35: =IF(Assumptions!$B$67="Base Case",Scenarios!H38,IF(Assumptions!$B$67="Optimistic",Scenarios!H124,Scenarios!H210)) -> 0
A36: Legal Reserve % | D36: 0.05 | E36: 0.05 | F36: 0.05 | G36: 0.05 | H36: 0.05
A37: Paid-Up Capital | D37: =IF(Assumptions!$B$67="Base Case",Scenarios!D18,IF(Assumptions!$B$67="Optimistic",Scenarios!D104,Scenarios!D190)) -> 10000 | E37: =IF(Assumptions!$B$67="Base Case",Scenarios!E18,IF(Assumptions!$B$67="Optimistic",Scenarios!E104,Scenarios!E190)) -> 10000 | F37: =IF(Assumptions!$B$67="Base Case",Scenarios!F18,IF(Assumptions!$B$67="Optimistic",Scenarios!F104,Scenarios!F190)) -> 10000 | G37: =IF(Assumptions!$B$67="Base Case",Scenarios!G18,IF(Assumptions!$B$67="Optimistic",Scenarios!G104,Scenarios!G190)) -> 10000 | H37: =IF(Assumptions!$B$67="Base Case",Scenarios!H18,IF(Assumptions!$B$67="Optimistic",Scenarios!H104,Scenarios!H190)) -> 10000
A38: Dividend WHT Rate | D38: 0.1 | E38: 0.1 | F38: 0.1 | G38: 0.1 | H38: 0.1
A39: Equity Issuance | D39: =IF(Assumptions!$B$67="Base Case",Scenarios!D39,IF(Assumptions!$B$67="Optimistic",Scenarios!D125,Scenarios!D211)) -> 0 | E39: =IF(Assumptions!$B$67="Base Case",Scenarios!E39,IF(Assumptions!$B$67="Optimistic",Scenarios!E125,Scenarios!E211)) -> 0 | F39: =IF(Assumptions!$B$67="Base Case",Scenarios!F39,IF(Assumptions!$B$67="Optimistic",Scenarios!F125,Scenarios!F211)) -> 0 | G39: =IF(Assumptions!$B$67="Base Case",Scenarios!G39,IF(Assumptions!$B$67="Optimistic",Scenarios!G125,Scenarios!G211)) -> 0 | H39: =IF(Assumptions!$B$67="Base Case",Scenarios!H39,IF(Assumptions!$B$67="Optimistic",Scenarios!H125,Scenarios!H211)) -> 0
A40: ── BS / Equity Direct Values ──
...

Sheet Income Statement
A1: Demo Company Inc. — Income Statement | B1: 2024 (A) | C1: 2025 (A) | D1: 2026E | E1: 2027E | F1: 2028E | G1: 2029E | H1: 2030E
A2: Revenue | B2: ='Historical Data'!B4 -> 850000 | C2: ='Historical Data'!C4 -> 950000 | D2: =C2*(1+Assumptions!D4) -> 1045000 | E2: =D2*(1+Assumptions!E4) -> 1128600 | F2: =E2*(1+Assumptions!F4) -> 1207602 | G2: =F2*(1+Assumptions!G4) -> 1280058.1 | H2: =G2*(1+Assumptions!H4) -> 1344061
A3: Revenue Growth % | B3: =0 -> 0 | C3: =IF('Historical Data'!B4=0,0,('Historical Data'!C4-'Historical Data'!B4)/'Historical Data'!B4) -> 0.11764706 | D3: =Assumptions!D4 -> 0.1 | E3: =Assumptions!E4 -> 0.08 | F3: =Assumptions!F4 -> 0.07 | G3: =Assumptions!G4 -> 0.06 | H3: =Assumptions!H4 -> 0.05
A4: Cost of Goods Sold | B4: =B2*IF('Historical Data'!B4=0,0,'Historical Data'!B5/'Historical Data'!B4) -> 510000 | C4: =C2*IF('Historical Data'!C4=0,0,'Historical Data'!C5/'Historical Data'!C4) -> 570000 | D4: =D2*Assumptions!D5 -> 627000 | E4: =E2*Assumptions!E5 -> 677160 | F4: =F2*Assumptions!F5 -> 724561.2 | G4: =G2*Assumptions!G5 -> 768034.87 | H4: =H2*Assumptions!H5 -> 806436.62
A5: Gross Profit | B5: =B2-B4 -> 340000 | C5: =C2-C4 -> 380000 | D5: =D2-D4 -> 418000 | E5: =E2-E4 -> 451440 | F5: =F2-F4 -> 483040.8 | G5: =G2-G4 -> 512023.25 | H5: =H2-H4 -> 537624.41
A6: Gross Margin | B6: =IF(B2=0,0,B5/B2) -> 0.4 | C6: =IF(C2=0,0,C5/C2) -> 0.4 | D6: =IF(D2=0,0,D5/D2) -> 0.4 | E6: =IF(E2=0,0,E5/E2) -> 0.4 | F6: =IF(F2=0,0,F5/F2) -> 0.4 | G6: =IF(G2=0,0,G5/G2) -> 0.4 | H6: =IF(H2=0,0,H5/H2) -> 0.4
A8: Operating Expenses
A9: SG&A | B9: =B2*IF('Historical Data'!B4=0,0,'Historical Data'!B7/'Historical Data'!B4) -> 127500 | C9: =C2*IF('Historical Data'!C4=0,0,'Historical Data'!C7/'Historical Data'!C4) -> 142500 | D9: =D2*Assumptions!D6 -> 156750 | E9: =E2*Assumptions!E6 -> 169290 | F9: =F2*Assumptions!F6 -> 181140.3 | G9: =G2*Assumptions!G6 -> 192008.72 | H9: =H2*Assumptions!H6 -> 201609.15
A10: R&D | B10: =B2*IF('Historical Data'!B4=0,0,'Historical Data'!B8/'Historical Data'!B4) -> 42500 | C10: =C2*IF('Historical Data'!C4=0,0,'Historical Data'!C8/'Historical Data'!C4) -> 47500 | D10: =D2*Assumptions!D7 -> 0 | E10: =E2*Assumptions!E7 -> 0 | F10: =F2*Assumptions!F7 -> 0 | G10: =G2*Assumptions!G7 -> 0 | H10: =H2*Assumptions!H7 -> 0
A11: Depreciation | B11: ='Historical Data'!B9 -> 28000 | C11: ='Historical Data'!C9 -> 32000 | D11: =(Assumptions!C54+'Income Statement'!D2*Assumptions!D23/2)*Assumptions!D24 -> 41112.5 | E11: =(Assumptions!D54+'Income Statement'!E2*Assumptions!E23/2)*Assumptions!E24 -> 46546.5 | F11: =(Assumptions!E54+'Income Statement'!F2*Assumptions!F23/2)*Assumptions!F24 -> 52387.005 | G11: =(Assumptions!F54+'Income Statement'!G2*Assumptions!G23/2)*Assumptions!G24 -> 58606.155 | H11: =(Assumptions!G54+'Income Statement'!H2*Assumptions!H23/2)*Assumptions!H24 -> 65166.453
A12: Amortization | B12: ='Historical Data'!B10 -> 5000 | C12: ='Historical Data'!C10 -> 5000 | D12: =Assumptions!D25 -> 5000 | E12: =Assumptions!E25 -> 5000 | F12: =Assumptions!F25 -> 5000 | G12: =Assumptions!G25 -> 5000 | H12: =Assumptions!H25 -> 5000
A13: Other OpEx | B13: =B2*IF('Historical Data'!B4=0,0,'Historical Data'!B11/'Historical Data'!B4) -> 17000 | C13: =C2*IF('Historical Data'!C4=0,0,'Historical Data'!C11/'Historical Data'!C4) -> 19000 | D13: =D2*Assumptions!D8 -> 20900 | E13: =E2*Assumptions!E8 -> 22572 | F13: =F2*Assumptions!F8 -> 24152.04 | G13: =G2*Assumptions!G8 -> 25601.162 | H13: =H2*Assumptions!H8 -> 26881.221
A14: Stock-Based Comp | B14: ='Historical Data'!B21 -> 0 | C14: ='Historical Data'!C21 -> 0 | D14: =Assumptions!D14 -> 0 | E14: =Assumptions!E14 -> 0 | F14: =Assumptions!F14 -> 0 | G14: =Assumptions!G14 -> 0 | H14: =Assumptions!H14 -> 0
A15: Total OpEx | B15: =B9+B10+B11+B12+B13+B14 -> 220000 | C15: =C9+C10+C11+C12+C13+C14 -> 246000 | D15: =D9+D10+D11+D12+D13+D14 -> 223762.5 | E15: =E9+E10+E11+E12+E13+E14 -> 243408.5 | F15: =F9+F10+F11+F12+F13+F14 -> 262679.35 | G15: =G9+G10+G11+G12+G13+G14 -> 281216.04 | H15: =H9+H10+H11+H12+H13+H14 -> 298656.83
A17: EBIT | B17: =B5-B15 -> 120000 | C17: =C5-C15 -> 134000 | D17: =D5-D15 -> 194237.5 | E17: =E5-E15 -> 208031.5 | F17: =F5-F15 -> 220361.46 | G17: =G5-G15 -> 230807.21 | H17: =H5-H15 -> 238967.58
A18: EBITDA | B18: =B17+B11+B12 -> 153000 | C18: =C17+C11+C12 -> 171000 | D18: =D17+D11+D12 -> 240350 | E18: =E17+E11+E12 -> 259578 | F18: =F17+F11+F12 -> 277748.46 | G18: =G17+G11+G12 -> 294413.37 | H18: =H17+H11+H12 -> 309134.04
A19: EBIT Margin | B19: =IF(B2=0,0,B17/B2) -> 0.14117647 | C19: =IF(C2=0,0,C17/C2) -> 0.14105263 | D19: =IF(D2=0,0,D17/D2) -> 0.18587321 | E19: =IF(E2=0,0,E17/E2) -> 0.18432704 | F19: =IF(F2=0,0,F17/F2) -> 0.18247854 | G19: =IF(G2=0,0,G17/G2) -> 0.18030995 | H19: =IF(H2=0,0,H17/H2) -> 0.17779519
A21: Interest Income | B21: ='Historical Data'!B15 -> 2500 | C21: ='Historical Data'!C15 -> 3000 | D21: =Assumptions!D51 -> 58322.115 | E21: =Assumptions!E51 -> 80000.745 | F21: =Assumptions!F51 -> 88687.637 | G21: =Assumptions!G51 -> 94238.234 | H21: =Assumptions!H51 -> 104504.81
A22: Interest Expense | B22: ='Historical Data'!B14 -> 14000 | C22: ='Historical Data'!C14 -> 13000 | D22: =Assumptions!D52 -> 61600 | E22: =Assumptions!E52 -> 56000 | F22: =Assumptions!F52 -> 50400 | G22: =Assumptions!G52 -> 47600 | H22: =Assumptions!H52 -> 44800
A23: Other Income/Expense | B23: ='Historical Data'!B19 -> 0 | C23: ='Historical Data'!C19 -> 0 | D23: =Assumptions!D12 -> 0 | E23: =Assumptions!E12 -> 0 | F23: =Assumptions!F12 -> 0 | G23: =Assumptions!G12 -> 0 | H23: =Assumptions!H12 -> 0
A24: EBT | B24: =B17+B21-B22+B23 -> 108500 | C24: =C17+C21-C22+C23 -> 124000 | D24: =D17+D21-D22+D23 -> 190959.61 | E24: =E17+E21-E22+E23 -> 232032.24 | F24: =F17+F21-F22+F23 -> 258649.09 | G24: =G17+G21-G22+G23 -> 277445.45 | H24: =H17+H21-H22+H23 -> 298672.39
A25: Tax Expense | B25: =MAX(0,B24*IF('Historical Data'!B16=0,0,'Historical Data'!B17/'Historical Data'!B16)) -> 24412.5 | C25: =MAX(0,C24*IF('Historical Data'!C16=0,0,'Historical Data'!C17/'Historical Data'!C16)) -> 27900 | D25: =MAX(0,D24*Assumptions!D9) -> 42965.913 | E25: =MAX(0,E24*Assumptions!E9) -> 52207.255 | F25: =MAX(0,F24*Assumptions!F9) -> 58196.046 | G25: =MAX(0,G24*Assumptions!G9) -> 62425.225 | H25: =MAX(0,H24*Assumptions!H9) -> 67201.288
A26: Tax Rate | B26: =IF('Historical Data'!B16=0,0,'Historical Data'!B17/'Historical Data'!B16) -> 0.225 | C26: =IF('Historical Data'!C16=0,0,'Historical Data'!C17/'Historical Data'!C16) -> 0.225 | D26: =Assumptions!D9 -> 0.225 | E26: =Assumptions!E9 -> 0.225 | F26: =Assumptions!F9 -> 0.225 | G26: =Assumptions!G9 -> 0.225 | H26: =Assumptions!H9 -> 0.225
A28: Net Income | B28: =B24-B25 -> 84087.5 | C28: =C24-C25 -> 96100 | D28: =D24-D25 -> 147993.7 | E28: =E24-E25 -> 179824.99 | F28: =F24-F25 -> 200453.05 | G28: =G24-G25 -> 215020.22 | H28: =H24-H25 -> 231471.1
A29: Employee Profit Sharing (EPD) | B29: =0 -> 0 | C29: =0 -> 0 | D29: =MAX(0,D28*Assumptions!D29) -> 14799.37 | E29: =MAX(0,E28*Assumptions!E29) -> 17982.499 | F29: =MAX(0,F28*Assumptions!F29) -> 20045.305 | G29: =MAX(0,G28*Assumptions!G29) -> 21502.022 | H29: =MAX(0,H28*Assumptions!H29) -> 23147.11
A30: Net Income After EPD | B30: =B28-B29 -> 84087.5 | C30: =C28-C29 -> 96100 | D30: =D28-D29 -> 133194.33 | E30: =E28-E29 -> 161842.49 | F30: =F28-F29 -> 180407.74 | G30: =G28-G29 -> 193518.2 | H30: =H28-H29 -> 208323.99
A31: Legal Reserve Addition (5% NI) | B31: ='Historical Data'!B47 -> 0 | C31: ='Historical Data'!C47-'Historical Data'!B47 -> 0 | D31: =Assumptions!D62-'Historical Data'!C47 -> 5000 | E31: =Assumptions!E62-Assumptions!D62 -> 0 | F31: =Assumptions!F62-Assumptions!E62 -> 0 | G31: =Assumptions!G62-Assumptions!F62 -> 0 | H31: =Assumptions!H62-Assumptions!G62 -> 0
A32: Cumulative Legal Reserve | B32: ='Historical Data'!B47 -> 0 | C32: ='Historical Data'!C47 -> 0 | D32: =Assumptions!D62 -> 5000 | E32: =Assumptions!E62 -> 5000 | F32: =Assumptions!F62 -> 5000 | G32: =Assumptions!G62 -> 5000 | H32: =Assumptions!H62 -> 5000
A33: Distributable Profit | B33: =B28-B29-B31 -> 84087.5 | C33: =C28-C29-C31 -> 96100 | D33: =D28-D29-D31 -> 128194.33 | E33: =E28-E29-E31 -> 161842.49 | F33: =F28-F29-F31 -> 180407.74 | G33: =G28-G29-G31 -> 193518.2 | H33: =H28-H29-H31 -> 208323.99
A34: Gross Dividends | B34: =0 -> 0 | C34: =0 -> 0 | D34: =MAX(0,D33*Assumptions!D34) -> 38458.299 | E34: =MAX(0,E33*Assumptions!E34) -> 48552.747 | F34: =MAX(0,F33*Assumptions!F34) -> 54122.322 | G34: =MAX(0,G33*Assumptions!G34) -> 58055.46 | H34: =MAX(0,H33*Assumptions!H34) -> 62497.198
A35: Dividend WHT (10%) | B35: =B34*Assumptions!B38 -> 0 | C35: =C34*Assumptions!C38 -> 0 | D35: =D34*Assumptions!D38 -> 3845.8299 | E35: =E34*Assumptions!E38 -> 4855.2747 | F35: =F34*Assumptions!F38 -> 5412.2322 | G35: =G34*Assumptions!G38 -> 5805.546 | H35: =H34*Assumptions!H38 -> 6249.7198
A36: Net Dividends | B36: =B34-B35 -> 0 | C36: =C34-C35 -> 0 | D36: =D34-D35 -> 34612.469 | E36: =E34-E35 -> 43697.473 | F36: =F34-F35 -> 48710.09 | G36: =G34-G35 -> 52249.914 | H36: =H34-H35 -> 56247.478
A37: Addition to Retained Earnings | B37: 84087.5 | C37: 49683 | D37: =D33-D34 -> 89736.032 | E37: =E33-E34 -> 113289.74 | F37: =F33-F34 -> 126285.42 | G37: =G33-G34 -> 135462.74 | H37: =H33-H34 -> 145826.8
A39: Net Margin | B39: =IF(B2=0,0,B28/B2) -> 0.098926471 | C39: =IF(C2=0,0,C28/C2) -> 0.10115789 | D39: =IF(D2=0,0,D28/D2) -> 0.14162077 | E39: =IF(E2=0,0,E28/E2) -> 0.15933456 | F39: =IF(F2=0,0,F28/F2) -> 0.16599264 | G39: =IF(G2=0,0,G28/G2) -> 0.16797692 | H39: =IF(H2=0,0,H28/H2) -> 0.1722177
A40: EPS | B40: =IF('Historical Data'!B20=0,0,B30/'Historical Data'!B20) -> 0.840875 | C40: =IF('Historical Data'!C20=0,0,C30/'Historical Data'!C20) -> 0.961 | D40: =IF(Assumptions!D13=0,0,D30/Assumptions!D13) -> 1.3319433 | E40: =IF(Assumptions!E13=0,0,E30/Assumptions!E13) -> 1.6184249 | F40: =IF(Assumptions!F13=0,0,F30/Assumptions!F13) -> 1.8040774 | G40: =IF(Assumptions!G13=0,0,G30/Assumptions!G13) -> 1.935182 | H40: =IF(Assumptions!H13=0,0,H30/Assumptions!H13) -> 2.0832399
A42: MEMO ITEMS
A43: NOPAT | B43: =B17*(1-IF('Historical Data'!B16=0,0,'Historical Data'!B17/'Historical Data'!B16)) -> 93000 | C43: =C17*(1-IF('Historical Data'!C16=0,0,'Historical Data'!C17/'Historical Data'!C16)) -> 103850 | D43: =D17*(1-Assumptions!D9) -> 150534.06 | E43: =E17*(1-Assumptions!E9) -> 161224.41 | F43: =F17*(1-Assumptions!F9) -> 170780.13 | G43: =G17*(1-Assumptions!G9) -> 178875.59 | H43: =H17*(1-Assumptions!H9) -> 185199.88
A44: FCFF | B44: 0 | C44: 0 | D44: =IF(Dashboard!$B$6="Base Case",'_Calc_Base'!D34,IF(Dashboard!$B$6="Optimistic",'_Calc_Opt'!D34,'_Calc_Con'!D34)) -> 134245.03 | E44: =IF(Dashboard!$B$6="Base Case",'_Calc_Base'!E34,IF(Dashboard!$B$6="Optimistic",'_Calc_Opt'!E34,'_Calc_Con'!E34)) -> 147408.31 | F44: =IF(Dashboard!$B$6="Base Case",'_Calc_Base'!F34,IF(Dashboard!$B$6="Optimistic",'_Calc_Opt'!F34,'_Calc_Con'!F34)) -> 159345.72 | G44: =IF(Dashboard!$B$6="Base Case",'_Calc_Base'!G34,IF(Dashboard!$B$6="Optimistic",'_Calc_Opt'!G34,'_Calc_Con'!G34)) -> 170736.95 | H44: =IF(Dashboard!$B$6="Base Case",'_Calc_Base'!H34,IF(Dashboard!$B$6="Optimistic",'_Calc_Opt'!H34,'_Calc_Con'!H34)) -> 181324.61
A45: Disallowed Interest (Thin-Cap) | B45: 0 | C45: 0 | D45: 0 | E45: 0 | F45: 0 | G45: 0 | H45: 0
A46: Adjusted Taxable Income | B46: 108500 | C46: 124000 | D46: 190959.61 | E46: 232032.24 | F46: 258649.09 | G46: 277445.45 | H46: 298672.39
...

Sheet Balance Sheet
