Workbook

Sheet Company Info
A1: COMPANY INFORMATION & MODEL CONFIGURATION
A3: SECTION 1 — COMPANY IDENTIFICATION
A4: Company Name | B4: TestCo | C4: ← Edit
A5: Legal Entity Type | B5: Société Anonyme (S.A.E.) | C5: ← Edit
A6: Industry / Sector | B6: Technology / Software | C6: ← Edit
A7: Founded Year | B7: 2010 | C7: ← Edit
A8: Commercial Register No. | B8: 12345-Cairo-2010 | C8: Auto
A9: Tax Identification No. | B9: 123-456-789 | C9: Auto
A10: Headquarters Address | B10: 5 El-Nile Street, Zamalek, Cairo, Egypt | C10: Auto
A12: SECTION 2 — FINANCIAL MODEL CONFIGURATION
A13: Reporting Currency | B13: Egyptian Pound (EGP) | C13: Auto
A14: Currency Symbol | B14: E£ | C14: Auto
A15: Fiscal Year End | B15: December 31 | C15: ← Edit
A16: Historical Period | B16: 2021 – 2023 (Actual) | C16: Auto
A17: Projection Period | B17: 2024E – 2028E (5 Years) | C17: Auto
A18: Revenue Projection Base (E£) | B18: 1000000 | C18: ← Edit
A19: Model Version | B19: v2.0 | Feb 2026 | C19: Auto
A20: Last Updated | B20: February 20, 2026 | C20: Auto
A22: SECTION 3 — EGYPT REGULATORY / TAX
A23: Corporate Income Tax Rate | B23: 0.225 | C23: ← Edit
A24: VAT Rate (Standard) | B24: 0.14 | C24: ← Edit
A25: Dividend Withholding Tax | B25: 0.1 | C25: ← Edit
A26: CBE Policy Rate (Reference) | B26: 0.2725 | C26: ← Edit
A27: Financial Year Note | B27: July 1 – June 30 (Note: model uses Dec) | C27: Auto
A29: SECTION 4 — REPORT & PREPARER INFORMATION
A30: Prepared By | B30: Financial Modeling Team | C30: ← Edit
A31: Reviewed By | B31: CFO | C31: ← Edit
A32: Preparation Date | B32: February 20, 2026 | C32: ← Edit
A33: Purpose | B33: Internal Planning & Analysis | C33: ← Edit
A34: Confidentiality | B34: CONFIDENTIAL — Internal Use Only | C34: ← Edit
A35: Contact Email | B35: finance@democompany.com | C35: ← Edit
A37: Note: Blue-text cells are editable inputs. Company Name (B4) flows to Dashboard and all sheet headers.

Sheet Scenarios
A1: SCENARIO DATA — COMPLETE ENGINE VALUES
A2: This sheet stores the full engine-computed data for each scenario. All projection columns in Assumptions reference this sheet via IF formulas.
A4: ▎ BASE CASE · Moderate growth with stable margins
A5: Assumption / Computed Value | B5: 2023 | C5: 2024 | D5: 2025E | E5: 2026E | F5: 2027E | G5: 2028E | H5: 2029E
A6: ── Income Statement Drivers ──
A7: Revenue Base (Historical) | B7: 850000 | C7: 0 | D7: 0 | E7: 0 | F7: 0 | G7: 0 | H7: 0
A8: Revenue Base (Projection) | B8: 1000000 | C8: 0 | D8: 0 | E8: 0 | F8: 0 | G8: 0 | H8: 0
A9: Revenue Growth Rate | B9: 0 | C9: 0.11764706 | D9: 0.1 | E9: 0.08 | F9: 0.07 | G9: 0.06 | H9: 0.05
A10: COGS % of Revenue | B10: 0.6 | C10: 0.6 | D10: 0.6 | E10: 0.6 | F10: 0.6 | G10: 0.6 | H10: 0.6
A11: SG&A % of Revenue | B11: 0.15 | C11: 0.15 | D11: 0.15 | E11: 0.15 | F11: 0.15 | G11: 0.15 | H11: 0.15
A12: R&D % of Revenue | B12: 0.05 | C12: 0.05 | D12: 0.05 | E12: 0.05 | F12: 0.05 | G12: 0.05 | H12: 0.05
A13: Other OpEx % of Revenue | B13: 0.02 | C13: 0.02 | D13: 0.02 | E13: 0.02 | F13: 0.02 | G13: 0.02 | H13: 0.02
A14: Tax Rate | B14: 0.25230415 | C14: 0.25201613 | D14: 0.25 | E14: 0.25 | F14: 0.25 | G14: 0.25 | H14: 0.25
A15: Other Income / Expense | B15: 0 | C15: 0 | D15: 0 | E15: 0 | F15: 0 | G15: 0 | H15: 0
A16: Shares Outstanding | B16: 100000 | C16: 100000 | D16: 100000 | E16: 100000 | F16: 100000 | G16: 100000 | H16: 100000
A17: Stock-Based Comp Amount | B17: 0 | C17: 0 | D17: 10000 | E17: 10000 | F17: 10000 | G17: 10000 | H17: 10000
A18: ── Balance Sheet / WC Drivers ──
A19: DSO (Days) | B19: 45.000206 | C19: 44.999889 | D19: 45 | E19: 45 | F19: 45 | G19: 45 | H19: 45
A20: DIO (Days) | B20: 30.000137 | C20: 29.999798 | D20: 30 | E20: 30 | F20: 30 | G20: 30 | H20: 30
A21: DPO (Days) | B21: 39.999706 | C21: 40.000158 | D21: 40 | E21: 40 | F21: 40 | G21: 40 | H21: 40
A22: Prepaid % of Revenue | B22: 0.01 | C22: 0.01 | D22: 0.01 | E22: 0.01 | F22: 0.01 | G22: 0.01 | H22: 0.01
A23: Accrued Exp % of Revenue | B23: 0.03 | C23: 0.03 | D23: 0.03 | E23: 0.03 | F23: 0.03 | G23: 0.03 | H23: 0.03
A24: Deferred Rev % of Revenue | B24: 0.02 | C24: 0.02 | D24: 0.02 | E24: 0.02 | F24: 0.02 | G24: 0.02 | H24: 0.02
A25: ── CapEx & Depreciation ──
A26: CapEx % of Revenue | B26: 0 | C26: 0.047368421 | D26: 0.05 | E26: 0.05 | F26: 0.05 | G26: 0.05 | H26: 0.05
A27: Depreciation Rate (% Gross PPE) | B27: 0.082352941 | C27: 0.083116883 | D27: 0.1 | E27: 0.1 | F27: 0.1 | G27: 0.1 | H27: 0.1
A28: Amortization Amount | B28: 5000 | C28: 5000 | D28: 5000 | E28: 5000 | F28: 5000 | G28: 5000 | H28: 5000
A29: ── Debt & Financing ──
A30: Interest Rate (on Debt) | B30: 0.05 | C30: 0.05 | D30: 0.05 | E30: 0.05 | F30: 0.05 | G30: 0.05 | H30: 0.05
A31: Interest Income Rate (on Cash) | B31: 0.02 | C31: 0.02 | D31: 0.02 | E31: 0.02 | F31: 0.02 | G31: 0.02 | H31: 0.02
A32: Short-Term Debt | B32: 50000 | C32: 50000 | D32: 50000 | E32: 50000 | F32: 50000 | G32: 50000 | H32: 50000
A33: LT Debt Issuance | B33: 0 | C33: 0 | D33: 0 | E33: 0 | F33: 0 | G33: 0 | H33: 0
A34: LT Debt Repayment | B34: 0 | C34: 20000 | D34: 20000 | E34: 20000 | F34: 20000 | G34: 20000 | H34: 20000
A35: Current Portion LTD | B35: 20000 | C35: 20000 | D35: 20000 | E35: 20000 | F35: 20000 | G35: 20000 | H35: 20000
A36: Dividend Payout Ratio | B36: 0 | C36: 0.46433423 | D36: 0.3 | E36: 0.3 | F36: 0.3 | G36: 0.3 | H36: 0.3
A37: Share Repurchase Amount | B37: 0 | C37: 0 | D37: 0 | E37: 0 | F37: 0 | G37: 0 | H37: 0
A38: Equity Issuance | B38: 0 | C38: 10000 | D38: 0 | E38: 0 | F38: 0 | G38: 0 | H38: 0
A39: ── BS / Equity Direct Values ──
A40: Goodwill | B40: 100000 | C40: 100000 | D40: 100000 | E40: 100000 | F40: 100000 | G40: 100000 | H40: 100000
A41: Other Current Assets | B41: 10000 | C41: 10000 | D41: 10000 | E41: 10000 | F41: 10000 | G41: 10000 | H41: 10000
...

Sheet Assumptions
A1: Assumption | B1: 2023 | C1: 2024 | D1: 2025E | E1: 2026E | F1: 2027E | G1: 2028E | H1: 2029E
A2: ── Income Statement Drivers ──
A3: Revenue Base (Historical) | B3: 850000 | D3: =IF(Assumptions!$B$64="Base Case",Scenarios!D7,IF(Assumptions!$B$64="Optimistic",Scenarios!D70,Scenarios!D133)) -> 0 | E3: =IF(Assumptions!$B$64="Base Case",Scenarios!E7,IF(Assumptions!$B$64="Optimistic",Scenarios!E70,Scenarios!E133)) -> 0 | F3: =IF(Assumptions!$B$64="Base Case",Scenarios!F7,IF(Assumptions!$B$64="Optimistic",Scenarios!F70,Scenarios!F133)) -> 0 | G3: =IF(Assumptions!$B$64="Base Case",Scenarios!G7,IF(Assumptions!$B$64="Optimistic",Scenarios!G70,Scenarios!G133)) -> 0 | H3: =IF(Assumptions!$B$64="Base Case",Scenarios!H7,IF(Assumptions!$B$64="Optimistic",Scenarios!H70,Scenarios!H133)) -> 0
A4: Revenue Base (Projection) | B4: 1000000 | D4: =IF(Assumptions!$B$64="Base Case",Scenarios!D8,IF(Assumptions!$B$64="Optimistic",Scenarios!D71,Scenarios!D134)) -> 0 | E4: =IF(Assumptions!$B$64="Base Case",Scenarios!E8,IF(Assumptions!$B$64="Optimistic",Scenarios!E71,Scenarios!E134)) -> 0 | F4: =IF(Assumptions!$B$64="Base Case",Scenarios!F8,IF(Assumptions!$B$64="Optimistic",Scenarios!F71,Scenarios!F134)) -> 0 | G4: =IF(Assumptions!$B$64="Base Case",Scenarios!G8,IF(Assumptions!$B$64="Optimistic",Scenarios!G71,Scenarios!G134)) -> 0 | H4: =IF(Assumptions!$B$64="Base Case",Scenarios!H8,IF(Assumptions!$B$64="Optimistic",Scenarios!H71,Scenarios!H134)) -> 0
A5: Revenue Growth Rate | B5: 0 | C5: 0.11764706 | D5: =IF(Assumptions!$B$64="Base Case",Scenarios!D9,IF(Assumptions!$B$64="Optimistic",Scenarios!D72,Scenarios!D135)) -> 0.1 | E5: =IF(Assumptions!$B$64="Base Case",Scenarios!E9,IF(Assumptions!$B$64="Optimistic",Scenarios!E72,Scenarios!E135)) -> 0.08 | F5: =IF(Assumptions!$B$64="Base Case",Scenarios!F9,IF(Assumptions!$B$64="Optimistic",Scenarios!F72,Scenarios!F135)) -> 0.07 | G5: =IF(Assumptions!$B$64="Base Case",Scenarios!G9,IF(Assumptions!$B$64="Optimistic",Scenarios!G72,Scenarios!G135)) -> 0.06 | H5: =IF(Assumptions!$B$64="Base Case",Scenarios!H9,IF(Assumptions!$B$64="Optimistic",Scenarios!H72,Scenarios!H135)) -> 0.05
A6: COGS % of Revenue | B6: 0.6 | C6: 0.6 | D6: =IF(Assumptions!$B$64="Base Case",Scenarios!D10,IF(Assumptions!$B$64="Optimistic",Scenarios!D73,Scenarios!D136)) -> 0.6 | E6: =IF(Assumptions!$B$64="Base Case",Scenarios!E10,IF(Assumptions!$B$64="Optimistic",Scenarios!E73,Scenarios!E136)) -> 0.6 | F6: =IF(Assumptions!$B$64="Base Case",Scenarios!F10,IF(Assumptions!$B$64="Optimistic",Scenarios!F73,Scenarios!F136)) -> 0.6 | G6: =IF(Assumptions!$B$64="Base Case",Scenarios!G10,IF(Assumptions!$B$64="Optimistic",Scenarios!G73,Scenarios!G136)) -> 0.6 | H6: =IF(Assumptions!$B$64="Base Case",Scenarios!H10,IF(Assumptions!$B$64="Optimistic",Scenarios!H73,Scenarios!H136)) -> 0.6
A7: SG&A % of Revenue | B7: 0.15 | C7: 0.15 | D7: =IF(Assumptions!$B$64="Base Case",Scenarios!D11,IF(Assumptions!$B$64="Optimistic",Scenarios!D74,Scenarios!D137)) -> 0.15 | E7: =IF(Assumptions!$B$64="Base Case",Scenarios!E11,IF(Assumptions!$B$64="Optimistic",Scenarios!E74,Scenarios!E137)) -> 0.15 | F7: =IF(Assumptions!$B$64="Base Case",Scenarios!F11,IF(Assumptions!$B$64="Optimistic",Scenarios!F74,Scenarios!F137)) -> 0.15 | G7: =IF(Assumptions!$B$64="Base Case",Scenarios!G11,IF(Assumptions!$B$64="Optimistic",Scenarios!G74,Scenarios!G137)) -> 0.15 | H7: =IF(Assumptions!$B$64="Base Case",Scenarios!H11,IF(Assumptions!$B$64="Optimistic",Scenarios!H74,Scenarios!H137)) -> 0.15
A8: R&D % of Revenue | B8: 0.05 | C8: 0.05 | D8: =IF(Assumptions!$B$64="Base Case",Scenarios!D12,IF(Assumptions!$B$64="Optimistic",Scenarios!D75,Scenarios!D138)) -> 0.05 | E8: =IF(Assumptions!$B$64="Base Case",Scenarios!E12,IF(Assumptions!$B$64="Optimistic",Scenarios!E75,Scenarios!E138)) -> 0.05 | F8: =IF(Assumptions!$B$64="Base Case",Scenarios!F12,IF(Assumptions!$B$64="Optimistic",Scenarios!F75,Scenarios!F138)) -> 0.05 | G8: =IF(Assumptions!$B$64="Base Case",Scenarios!G12,IF(Assumptions!$B$64="Optimistic",Scenarios!G75,Scenarios!G138)) -> 0.05 | H8: =IF(Assumptions!$B$64="Base Case",Scenarios!H12,IF(Assumptions!$B$64="Optimistic",Scenarios!H75,Scenarios!H138)) -> 0.05
A9: Other OpEx % of Revenue | B9: 0.02 | C9: 0.02 | D9: =IF(Assumptions!$B$64="Base Case",Scenarios!D13,IF(Assumptions!$B$64="Optimistic",Scenarios!D76,Scenarios!D139)) -> 0.02 | E9: =IF(Assumptions!$B$64="Base Case",Scenarios!E13,IF(Assumptions!$B$64="Optimistic",Scenarios!E76,Scenarios!E139)) -> 0.02 | F9: =IF(Assumptions!$B$64="Base Case",Scenarios!F13,IF(Assumptions!$B$64="Optimistic",Scenarios!F76,Scenarios!F139)) -> 0.02 | G9: =IF(Assumptions!$B$64="Base Case",Scenarios!G13,IF(Assumptions!$B$64="Optimistic",Scenarios!G76,Scenarios!G139)) -> 0.02 | H9: =IF(Assumptions!$B$64="Base Case",Scenarios!H13,IF(Assumptions!$B$64="Optimistic",Scenarios!H76,Scenarios!H139)) -> 0.02
A10: Tax Rate | B10: 0.25230415 | C10: 0.25201613 | D10: =IF(Assumptions!$B$64="Base Case",Scenarios!D14,IF(Assumptions!$B$64="Optimistic",Scenarios!D77,Scenarios!D140)) -> 0.25 | E10: =IF(Assumptions!$B$64="Base Case",Scenarios!E14,IF(Assumptions!$B$64="Optimistic",Scenarios!E77,Scenarios!E140)) -> 0.25 | F10: =IF(Assumptions!$B$64="Base Case",Scenarios!F14,IF(Assumptions!$B$64="Optimistic",Scenarios!F77,Scenarios!F140)) -> 0.25 | G10: =IF(Assumptions!$B$64="Base Case",Scenarios!G14,IF(Assumptions!$B$64="Optimistic",Scenarios!G77,Scenarios!G140)) -> 0.25 | H10: =IF(Assumptions!$B$64="Base Case",Scenarios!H14,IF(Assumptions!$B$64="Optimistic",Scenarios!H77,Scenarios!H140)) -> 0.25
A11: Other Income / Expense | B11: 0 | C11: 0 | D11: =IF(Assumptions!$B$64="Base Case",Scenarios!D15,IF(Assumptions!$B$64="Optimistic",Scenarios!D78,Scenarios!D141)) -> 0 | E11: =IF(Assumptions!$B$64="Base Case",Scenarios!E15,IF(Assumptions!$B$64="Optimistic",Scenarios!E78,Scenarios!E141)) -> 0 | F11: =IF(Assumptions!$B$64="Base Case",Scenarios!F15,IF(Assumptions!$B$64="Optimistic",Scenarios!F78,Scenarios!F141)) -> 0 | G11: =IF(Assumptions!$B$64="Base Case",Scenarios!G15,IF(Assumptions!$B$64="Optimistic",Scenarios!G78,Scenarios!G141)) -> 0 | H11: =IF(Assumptions!$B$64="Base Case",Scenarios!H15,IF(Assumptions!$B$64="Optimistic",Scenarios!H78,Scenarios!H141)) -> 0
A12: Shares Outstanding | B12: 100000 | C12: 100000 | D12: =IF(Assumptions!$B$64="Base Case",Scenarios!D16,IF(Assumptions!$B$64="Optimistic",Scenarios!D79,Scenarios!D142)) -> 100000 | E12: =IF(Assumptions!$B$64="Base Case",Scenarios!E16,IF(Assumptions!$B$64="Optimistic",Scenarios!E79,Scenarios!E142)) -> 100000 | F12: =IF(Assumptions!$B$64="Base Case",Scenarios!F16,IF(Assumptions!$B$64="Optimistic",Scenarios!F79,Scenarios!F142)) -> 100000 | G12: =IF(Assumptions!$B$64="Base Case",Scenarios!G16,IF(Assumptions!$B$64="Optimistic",Scenarios!G79,Scenarios!G142)) -> 100000 | H12: =IF(Assumptions!$B$64="Base Case",Scenarios!H16,IF(Assumptions!$B$64="Optimistic",Scenarios!H79,Scenarios!H142)) -> 100000
A13: Stock-Based Comp Amount | B13: 0 | C13: 0 | D13: =IF(Assumptions!$B$64="Base Case",Scenarios!D17,IF(Assumptions!$B$64="Optimistic",Scenarios!D80,Scenarios!D143)) -> 10000 | E13: =IF(Assumptions!$B$64="Base Case",Scenarios!E17,IF(Assumptions!$B$64="Optimistic",Scenarios!E80,Scenarios!E143)) -> 10000 | F13: =IF(Assumptions!$B$64="Base Case",Scenarios!F17,IF(Assumptions!$B$64="Optimistic",Scenarios!F80,Scenarios!F143)) -> 10000 | G13: =IF(Assumptions!$B$64="Base Case",Scenarios!G17,IF(Assumptions!$B$64="Optimistic",Scenarios!G80,Scenarios!G143)) -> 10000 | H13: =IF(Assumptions!$B$64="Base Case",Scenarios!H17,IF(Assumptions!$B$64="Optimistic",Scenarios!H80,Scenarios!H143)) -> 10000
A14: ── Balance Sheet / WC Drivers ──
A15: DSO (Days) | B15: 45.000206 | C15: 44.999889 | D15: =IF(Assumptions!$B$64="Base Case",Scenarios!D19,IF(Assumptions!$B$64="Optimistic",Scenarios!D82,Scenarios!D145)) -> 45 | E15: =IF(Assumptions!$B$64="Base Case",Scenarios!E19,IF(Assumptions!$B$64="Optimistic",Scenarios!E82,Scenarios!E145)) -> 45 | F15: =IF(Assumptions!$B$64="Base Case",Scenarios!F19,IF(Assumptions!$B$64="Optimistic",Scenarios!F82,Scenarios!F145)) -> 45 | G15: =IF(Assumptions!$B$64="Base Case",Scenarios!G19,IF(Assumptions!$B$64="Optimistic",Scenarios!G82,Scenarios!G145)) -> 45 | H15: =IF(Assumptions!$B$64="Base Case",Scenarios!H19,IF(Assumptions!$B$64="Optimistic",Scenarios!H82,Scenarios!H145)) -> 45
A16: DIO (Days) | B16: 30.000137 | C16: 29.999798 | D16: =IF(Assumptions!$B$64="Base Case",Scenarios!D20,IF(Assumptions!$B$64="Optimistic",Scenarios!D83,Scenarios!D146)) -> 30 | E16: =IF(Assumptions!$B$64="Base Case",Scenarios!E20,IF(Assumptions!$B$64="Optimistic",Scenarios!E83,Scenarios!E146)) -> 30 | F16: =IF(Assumptions!$B$64="Base Case",Scenarios!F20,IF(Assumptions!$B$64="Optimistic",Scenarios!F83,Scenarios!F146)) -> 30 | G16: =IF(Assumptions!$B$64="Base Case",Scenarios!G20,IF(Assumptions!$B$64="Optimistic",Scenarios!G83,Scenarios!G146)) -> 30 | H16: =IF(Assumptions!$B$64="Base Case",Scenarios!H20,IF(Assumptions!$B$64="Optimistic",Scenarios!H83,Scenarios!H146)) -> 30
A17: DPO (Days) | B17: 39.999706 | C17: 40.000158 | D17: =IF(Assumptions!$B$64="Base Case",Scenarios!D21,IF(Assumptions!$B$64="Optimistic",Scenarios!D84,Scenarios!D147)) -> 40 | E17: =IF(Assumptions!$B$64="Base Case",Scenarios!E21,IF(Assumptions!$B$64="Optimistic",Scenarios!E84,Scenarios!E147)) -> 40 | F17: =IF(Assumptions!$B$64="Base Case",Scenarios!F21,IF(Assumptions!$B$64="Optimistic",Scenarios!F84,Scenarios!F147)) -> 40 | G17: =IF(Assumptions!$B$64="Base Case",Scenarios!G21,IF(Assumptions!$B$64="Optimistic",Scenarios!G84,Scenarios!G147)) -> 40 | H17: =IF(Assumptions!$B$64="Base Case",Scenarios!H21,IF(Assumptions!$B$64="Optimistic",Scenarios!H84,Scenarios!H147)) -> 40
A18: Prepaid % of Revenue | B18: 0.01 | C18: 0.01 | D18: =IF(Assumptions!$B$64="Base Case",Scenarios!D22,IF(Assumptions!$B$64="Optimistic",Scenarios!D85,Scenarios!D148)) -> 0.01 | E18: =IF(Assumptions!$B$64="Base Case",Scenarios!E22,IF(Assumptions!$B$64="Optimistic",Scenarios!E85,Scenarios!E148)) -> 0.01 | F18: =IF(Assumptions!$B$64="Base Case",Scenarios!F22,IF(Assumptions!$B$64="Optimistic",Scenarios!F85,Scenarios!F148)) -> 0.01 | G18: =IF(Assumptions!$B$64="Base Case",Scenarios!G22,IF(Assumptions!$B$64="Optimistic",Scenarios!G85,Scenarios!G148)) -> 0.01 | H18: =IF(Assumptions!$B$64="Base Case",Scenarios!H22,IF(Assumptions!$B$64="Optimistic",Scenarios!H85,Scenarios!H148)) -> 0.01
A19: Accrued Exp % of Revenue | B19: 0.03 | C19: 0.03 | D19: =IF(Assumptions!$B$64="Base Case",Scenarios!D23,IF(Assumptions!$B$64="Optimistic",Scenarios!D86,Scenarios!D149)) -> 0.03 | E19: =IF(Assumptions!$B$64="Base Case",Scenarios!E23,IF(Assumptions!$B$64="Optimistic",Scenarios!E86,Scenarios!E149)) -> 0.03 | F19: =IF(Assumptions!$B$64="Base Case",Scenarios!F23,IF(Assumptions!$B$64="Optimistic",Scenarios!F86,Scenarios!F149)) -> 0.03 | G19: =IF(Assumptions!$B$64="Base Case",Scenarios!G23,IF(Assumptions!$B$64="Optimistic",Scenarios!G86,Scenarios!G149)) -> 0.03 | H19: =IF(Assumptions!$B$64="Base Case",Scenarios!H23,IF(Assumptions!$B$64="Optimistic",Scenarios!H86,Scenarios!H149)) -> 0.03
A20: Deferred Rev % of Revenue | B20: 0.02 | C20: 0.02 | D20: =IF(Assumptions!$B$64="Base Case",Scenarios!D24,IF(Assumptions!$B$64="Optimistic",Scenarios!D87,Scenarios!D150)) -> 0.02 | E20: =IF(Assumptions!$B$64="Base Case",Scenarios!E24,IF(Assumptions!$B$64="Optimistic",Scenarios!E87,Scenarios!E150)) -> 0.02 | F20: =IF(Assumptions!$B$64="Base Case",Scenarios!F24,IF(Assumptions!$B$64="Optimistic",Scenarios!F87,Scenarios!F150)) -> 0.02 | G20: =IF(Assumptions!$B$64="Base Case",Scenarios!G24,IF(Assumptions!$B$64="Optimistic",Scenarios!G87,Scenarios!G150)) -> 0.02 | H20: =IF(Assumptions!$B$64="Base Case",Scenarios!H24,IF(Assumptions!$B$64="Optimistic",Scenarios!H87,Scenarios!H150)) -> 0.02
A21: ── CapEx & Depreciation Drivers ──
A22: CapEx % of Revenue | B22: 0 | C22: 0.047368421 | D22: =IF(Assumptions!$B$64="Base Case",Scenarios!D26,IF(Assumptions!$B$64="Optimistic",Scenarios!D89,Scenarios!D152)) -> 0.05 | E22: =IF(Assumptions!$B$64="Base Case",Scenarios!E26,IF(Assumptions!$B$64="Optimistic",Scenarios!E89,Scenarios!E152)) -> 0.05 | F22: =IF(Assumptions!$B$64="Base Case",Scenarios!F26,IF(Assumptions!$B$64="Optimistic",Scenarios!F89,Scenarios!F152)) -> 0.05 | G22: =IF(Assumptions!$B$64="Base Case",Scenarios!G26,IF(Assumptions!$B$64="Optimistic",Scenarios!G89,Scenarios!G152)) -> 0.05 | H22: =IF(Assumptions!$B$64="Base Case",Scenarios!H26,IF(Assumptions!$B$64="Optimistic",Scenarios!H89,Scenarios!H152)) -> 0.05
A23: Depreciation Rate (% Gross PPE) | B23: 0.082352941 | C23: 0.083116883 | D23: =IF(Assumptions!$B$64="Base Case",Scenarios!D27,IF(Assumptions!$B$64="Optimistic",Scenarios!D90,Scenarios!D153)) -> 0.1 | E23: =IF(Assumptions!$B$64="Base Case",Scenarios!E27,IF(Assumptions!$B$64="Optimistic",Scenarios!E90,Scenarios!E153)) -> 0.1 | F23: =IF(Assumptions!$B$64="Base Case",Scenarios!F27,IF(Assumptions!$B$64="Optimistic",Scenarios!F90,Scenarios!F153)) -> 0.1 | G23: =IF(Assumptions!$B$64="Base Case",Scenarios!G27,IF(Assumptions!$B$64="Optimistic",Scenarios!G90,Scenarios!G153)) -> 0.1 | H23: =IF(Assumptions!$B$64="Base Case",Scenarios!H27,IF(Assumptions!$B$64="Optimistic",Scenarios!H90,Scenarios!H153)) -> 0.1
A24: Amortization Amount | B24: 5000 | C24: 5000 | D24: =IF(Assumptions!$B$64="Base Case",Scenarios!D28,IF(Assumptions!$B$64="Optimistic",Scenarios!D91,Scenarios!D154)) -> 5000 | E24: =IF(Assumptions!$B$64="Base Case",Scenarios!E28,IF(Assumptions!$B$64="Optimistic",Scenarios!E91,Scenarios!E154)) -> 5000 | F24: =IF(Assumptions!$B$64="Base Case",Scenarios!F28,IF(Assumptions!$B$64="Optimistic",Scenarios!F91,Scenarios!F154)) -> 5000 | G24: =IF(Assumptions!$B$64="Base Case",Scenarios!G28,IF(Assumptions!$B$64="Optimistic",Scenarios!G91,Scenarios!G154)) -> 5000 | H24: =IF(Assumptions!$B$64="Base Case",Scenarios!H28,IF(Assumptions!$B$64="Optimistic",Scenarios!H91,Scenarios!H154)) -> 5000
A25: ── Debt & Financing ──
A26: Interest Rate (on Debt) | B26: 0.05 | C26: 0.05 | D26: =IF(Assumptions!$B$64="Base Case",Scenarios!D30,IF(Assumptions!$B$64="Optimistic",Scenarios!D93,Scenarios!D156)) -> 0.05 | E26: =IF(Assumptions!$B$64="Base Case",Scenarios!E30,IF(Assumptions!$B$64="Optimistic",Scenarios!E93,Scenarios!E156)) -> 0.05 | F26: =IF(Assumptions!$B$64="Base Case",Scenarios!F30,IF(Assumptions!$B$64="Optimistic",Scenarios!F93,Scenarios!F156)) -> 0.05 | G26: =IF(Assumptions!$B$64="Base Case",Scenarios!G30,IF(Assumptions!$B$64="Optimistic",Scenarios!G93,Scenarios!G156)) -> 0.05 | H26: =IF(Assumptions!$B$64="Base Case",Scenarios!H30,IF(Assumptions!$B$64="Optimistic",Scenarios!H93,Scenarios!H156)) -> 0.05
A27: Interest Income Rate (on Cash) | B27: 0.02 | C27: 0.02 | D27: =IF(Assumptions!$B$64="Base Case",Scenarios!D31,IF(Assumptions!$B$64="Optimistic",Scenarios!D94,Scenarios!D157)) -> 0.02 | E27: =IF(Assumptions!$B$64="Base Case",Scenarios!E31,IF(Assumptions!$B$64="Optimistic",Scenarios!E94,Scenarios!E157)) -> 0.02 | F27: =IF(Assumptions!$B$64="Base Case",Scenarios!F31,IF(Assumptions!$B$64="Optimistic",Scenarios!F94,Scenarios!F157)) -> 0.02 | G27: =IF(Assumptions!$B$64="Base Case",Scenarios!G31,IF(Assumptions!$B$64="Optimistic",Scenarios!G94,Scenarios!G157)) -> 0.02 | H27: =IF(Assumptions!$B$64="Base Case",Scenarios!H31,IF(Assumptions!$B$64="Optimistic",Scenarios!H94,Scenarios!H157)) -> 0.02
A28: Short-Term Debt | B28: 50000 | C28: 50000 | D28: =IF(Assumptions!$B$64="Base Case",Scenarios!D32,IF(Assumptions!$B$64="Optimistic",Scenarios!D95,Scenarios!D158)) -> 50000 | E28: =IF(Assumptions!$B$64="Base Case",Scenarios!E32,IF(Assumptions!$B$64="Optimistic",Scenarios!E95,Scenarios!E158)) -> 50000 | F28: =IF(Assumptions!$B$64="Base Case",Scenarios!F32,IF(Assumptions!$B$64="Optimistic",Scenarios!F95,Scenarios!F158)) -> 50000 | G28: =IF(Assumptions!$B$64="Base Case",Scenarios!G32,IF(Assumptions!$B$64="Optimistic",Scenarios!G95,Scenarios!G158)) -> 50000 | H28: =IF(Assumptions!$B$64="Base Case",Scenarios!H32,IF(Assumptions!$B$64="Optimistic",Scenarios!H95,Scenarios!H158)) -> 50000
A29: LT Debt Issuance | B29: 0 | C29: 0 | D29: =IF(Assumptions!$B$64="Base Case",Scenarios!D33,IF(Assumptions!$B$64="Optimistic",Scenarios!D96,Scenarios!D159)) -> 0 | E29: =IF(Assumptions!$B$64="Base Case",Scenarios!E33,IF(Assumptions!$B$64="Optimistic",Scenarios!E96,Scenarios!E159)) -> 0 | F29: =IF(Assumptions!$B$64="Base Case",Scenarios!F33,IF(Assumptions!$B$64="Optimistic",Scenarios!F96,Scenarios!F159)) -> 0 | G29: =IF(Assumptions!$B$64="Base Case",Scenarios!G33,IF(Assumptions!$B$64="Optimistic",Scenarios!G96,Scenarios!G159)) -> 0 | H29: =IF(Assumptions!$B$64="Base Case",Scenarios!H33,IF(Assumptions!$B$64="Optimistic",Scenarios!H96,Scenarios!H159)) -> 0
A30: LT Debt Repayment | B30: 0 | C30: 20000 | D30: =IF(Assumptions!$B$64="Base Case",Scenarios!D34,IF(Assumptions!$B$64="Optimistic",Scenarios!D97,Scenarios!D160)) -> 20000 | E30: =IF(Assumptions!$B$64="Base Case",Scenarios!E34,IF(Assumptions!$B$64="Optimistic",Scenarios!E97,Scenarios!E160)) -> 20000 | F30: =IF(Assumptions!$B$64="Base Case",Scenarios!F34,IF(Assumptions!$B$64="Optimistic",Scenarios!F97,Scenarios!F160)) -> 20000 | G30: =IF(Assumptions!$B$64="Base Case",Scenarios!G34,IF(Assumptions!$B$64="Optimistic",Scenarios!G97,Scenarios!G160)) -> 20000 | H30: =IF(Assumptions!$B$64="Base Case",Scenarios!H34,IF(Assumptions!$B$64="Optimistic",Scenarios!H97,Scenarios!H160)) -> 20000
A31: Current Portion LTD | B31: 20000 | C31: 20000 | D31: =IF(Assumptions!$B$64="Base Case",Scenarios!D35,IF(Assumptions!$B$64="Optimistic",Scenarios!D98,Scenarios!D161)) -> 20000 | E31: =IF(Assumptions!$B$64="Base Case",Scenarios!E35,IF(Assumptions!$B$64="Optimistic",Scenarios!E98,Scenarios!E161)) -> 20000 | F31: =IF(Assumptions!$B$64="Base Case",Scenarios!F35,IF(Assumptions!$B$64="Optimistic",Scenarios!F98,Scenarios!F161)) -> 20000 | G31: =IF(Assumptions!$B$64="Base Case",Scenarios!G35,IF(Assumptions!$B$64="Optimistic",Scenarios!G98,Scenarios!G161)) -> 20000 | H31: =IF(Assumptions!$B$64="Base Case",Scenarios!H35,IF(Assumptions!$B$64="Optimistic",Scenarios!H98,Scenarios!H161)) -> 20000
A32: Dividend Payout Ratio | B32: 0 | C32: 0.46433423 | D32: =IF(Assumptions!$B$64="Base Case",Scenarios!D36,IF(Assumptions!$B$64="Optimistic",Scenarios!D99,Scenarios!D162)) -> 0.3 | E32: =IF(Assumptions!$B$64="Base Case",Scenarios!E36,IF(Assumptions!$B$64="Optimistic",Scenarios!E99,Scenarios!E162)) -> 0.3 | F32: =IF(Assumptions!$B$64="Base Case",Scenarios!F36,IF(Assumptions!$B$64="Optimistic",Scenarios!F99,Scenarios!F162)) -> 0.3 | G32: =IF(Assumptions!$B$64="Base Case",Scenarios!G36,IF(Assumptions!$B$64="Optimistic",Scenarios!G99,Scenarios!G162)) -> 0.3 | H32: =IF(Assumptions!$B$64="Base Case",Scenarios!H36,IF(Assumptions!$B$64="Optimistic",Scenarios!H99,Scenarios!H162)) -> 0.3
A33: Share Repurchase Amount | B33: 0 | C33: 0 | D33: =IF(Assumptions!$B$64="Base Case",Scenarios!D37,IF(Assumptions!$B$64="Optimistic",Scenarios!D100,Scenarios!D163)) -> 0 | E33: =IF(Assumptions!$B$64="Base Case",Scenarios!E37,IF(Assumptions!$B$64="Optimistic",Scenarios!E100,Scenarios!E163)) -> 0 | F33: =IF(Assumptions!$B$64="Base Case",Scenarios!F37,IF(Assumptions!$B$64="Optimistic",Scenarios!F100,Scenarios!F163)) -> 0 | G33: =IF(Assumptions!$B$64="Base Case",Scenarios!G37,IF(Assumptions!$B$64="Optimistic",Scenarios!G100,Scenarios!G163)) -> 0 | H33: =IF(Assumptions!$B$64="Base Case",Scenarios!H37,IF(Assumptions!$B$64="Optimistic",Scenarios!H100,Scenarios!H163)) -> 0
A34: Equity Issuance | B34: 0 | C34: 10000 | D34: =IF(Assumptions!$B$64="Base Case",Scenarios!D38,IF(Assumptions!$B$64="Optimistic",Scenarios!D101,Scenarios!D164)) -> 0 | E34: =IF(Assumptions!$B$64="Base Case",Scenarios!E38,IF(Assumptions!$B$64="Optimistic",Scenarios!E101,Scenarios!E164)) -> 0 | F34: =IF(Assumptions!$B$64="Base Case",Scenarios!F38,IF(Assumptions!$B$64="Optimistic",Scenarios!F101,Scenarios!F164)) -> 0 | G34: =IF(Assumptions!$B$64="Base Case",Scenarios!G38,IF(Assumptions!$B$64="Optimistic",Scenarios!G101,Scenarios!G164)) -> 0 | H34: =IF(Assumptions!$B$64="Base Case",Scenarios!H38,IF(Assumptions!$B$64="Optimistic",Scenarios!H101,Scenarios!H164)) -> 0
A35: ── BS / Equity Direct Values ──
A36: Goodwill | B36: 100000 | C36: 100000 | D36: =IF(Assumptions!$B$64="Base Case",Scenarios!D40,IF(Assumptions!$B$64="Optimistic",Scenarios!D103,Scenarios!D166)) -> 100000 | E36: =IF(Assumptions!$B$64="Base Case",Scenarios!E40,IF(Assumptions!$B$64="Optimistic",Scenarios!E103,Scenarios!E166)) -> 100000 | F36: =IF(Assumptions!$B$64="Base Case",Scenarios!F40,IF(Assumptions!$B$64="Optimistic",Scenarios!F103,Scenarios!F166)) -> 100000 | G36: =IF(Assumptions!$B$64="Base Case",Scenarios!G40,IF(Assumptions!$B$64="Optimistic",Scenarios!G103,Scenarios!G166)) -> 100000 | H36: =IF(Assumptions!$B$64="Base Case",Scenarios!H40,IF(Assumptions!$B$64="Optimistic",Scenarios!H103,Scenarios!H166)) -> 100000
A37: Other Current Assets | B37: 10000 | C37: 10000 | D37: =IF(Assumptions!$B$64="Base Case",Scenarios!D41,IF(Assumptions!$B$64="Optimistic",Scenarios!D104,Scenarios!D167)) -> 10000 | E37: =IF(Assumptions!$B$64="Base Case",Scenarios!E41,IF(Assumptions!$B$64="Optimistic",Scenarios!E104,Scenarios!E167)) -> 10000 | F37: =IF(Assumptions!$B$64="Base Case",Scenarios!F41,IF(Assumptions!$B$64="Optimistic",Scenarios!F104,Scenarios!F167)) -> 10000 | G37: =IF(Assumptions!$B$64="Base Case",Scenarios!G41,IF(Assumptions!$B$64="Optimistic",Scenarios!G104,Scenarios!G167)) -> 10000 | H37: =IF(Assumptions!$B$64="Base Case",Scenarios!H41,IF(Assumptions!$B$64="Optimistic",Scenarios!H104,Scenarios!H167)) -> 10000
A38: Other Long-Term Assets | B38: 20000 | C38: 20000 | D38: =IF(Assumptions!$B$64="Base Case",Scenarios!D42,IF(Assumptions!$B$64="Optimistic",Scenarios!D105,Scenarios!D168)) -> 20000 | E38: =IF(Assumptions!$B$64="Base Case",Scenarios!E42,IF(Assumptions!$B$64="Optimistic",Scenarios!E105,Scenarios!E168)) -> 20000 | F38: =IF(Assumptions!$B$64="Base Case",Scenarios!F42,IF(Assumptions!$B$64="Optimistic",Scenarios!F105,Scenarios!F168)) -> 20000 | G38: =IF(Assumptions!$B$64="Base Case",Scenarios!G42,IF(Assumptions!$B$64="Optimistic",Scenarios!G105,Scenarios!G168)) -> 20000 | H38: =IF(Assumptions!$B$64="Base Case",Scenarios!H42,IF(Assumptions!$B$64="Optimistic",Scenarios!H105,Scenarios!H168)) -> 20000
A39: Other Current Liabilities | B39: 15000 | C39: 15000 | D39: =IF(Assumptions!$B$64="Base Case",Scenarios!D43,IF(Assumptions!$B$64="Optimistic",Scenarios!D106,Scenarios!D169)) -> 15000 | E39: =IF(Assumptions!$B$64="Base Case",Scenarios!E43,IF(Assumptions!$B$64="Optimistic",Scenarios!E106,Scenarios!E169)) -> 15000 | F39: =IF(Assumptions!$B$64="Base Case",Scenarios!F43,IF(Assumptions!$B$64="Optimistic",Scenarios!F106,Scenarios!F169)) -> 15000 | G39: =IF(Assumptions!$B$64="Base Case",Scenarios!G43,IF(Assumptions!$B$64="Optimistic",Scenarios!G106,Scenarios!G169)) -> 15000 | H39: =IF(Assumptions!$B$64="Base Case",Scenarios!H43,IF(Assumptions!$B$64="Optimistic",Scenarios!H106,Scenarios!H169)) -> 15000
A40: Deferred Tax Liabilities | B40: 30000 | C40: 30000 | D40: =IF(Assumptions!$B$64="Base Case",Scenarios!D44,IF(Assumptions!$B$64="Optimistic",Scenarios!D107,Scenarios!D170)) -> 30000 | E40: =IF(Assumptions!$B$64="Base Case",Scenarios!E44,IF(Assumptions!$B$64="Optimistic",Scenarios!E107,Scenarios!E170)) -> 30000 | F40: =IF(Assumptions!$B$64="Base Case",Scenarios!F44,IF(Assumptions!$B$64="Optimistic",Scenarios!F107,Scenarios!F170)) -> 30000 | G40: =IF(Assumptions!$B$64="Base Case",Scenarios!G44,IF(Assumptions!$B$64="Optimistic",Scenarios!G107,Scenarios!G170)) -> 30000 | H40: =IF(Assumptions!$B$64="Base Case",Scenarios!H44,IF(Assumptions!$B$64="Optimistic",Scenarios!H107,Scenarios!H170)) -> 30000
...
