Workbook

Sheet Dashboard
A1: WOLF
A2: FINANCIAL MODEL DASHBOARD · E£ (Egyptian Pound) · CONFIDENTIAL
A4: 📊 SCENARIO CONTROL
A5: Active Scenario | B5: Select Scenario →
A6: ▼ Scenario Selector | B6: Base Case | E6: =IF(B6="Base Case","Central planning — stable market | Revenue 10%→5% | COGS 60%",IF(B6="Optimistic","Bull case — strong execution | Revenue 15%→8% | COGS 55%","Bear case — headwinds | Revenue 5%→2% | COGS 63%")) -> Central planning — stable market | Revenue 10%→5% | COGS 60%
A8: 📈 KEY METRICS — ACTIVE SCENARIO
B9: 2021 | C9: 2022 | D9: 2023 | E9: 2024E | F9: 2025E | G9: 2026E | H9: 2027E | I9: 2028E
A10: 📗 INCOME STATEMENT
A11: Revenue (E£) | B11: =IF(Dashboard!$B$6="Base Case",Scenarios!B67,IF(Dashboard!$B$6="Optimistic",Scenarios!B152,Scenarios!B237)) -> 750000 | C11: =IF(Dashboard!$B$6="Base Case",Scenarios!C67,IF(Dashboard!$B$6="Optimistic",Scenarios!C152,Scenarios!C237)) -> 850000 | D11: =IF(Dashboard!$B$6="Base Case",Scenarios!D67,IF(Dashboard!$B$6="Optimistic",Scenarios!D152,Scenarios!D237)) -> 950000 | E11: =IF(Dashboard!$B$6="Base Case",Scenarios!E67,IF(Dashboard!$B$6="Optimistic",Scenarios!E152,Scenarios!E237)) -> 1045000 | F11: =IF(Dashboard!$B$6="Base Case",Scenarios!F67,IF(Dashboard!$B$6="Optimistic",Scenarios!F152,Scenarios!F237)) -> 1128600 | G11: =IF(Dashboard!$B$6="Base Case",Scenarios!G67,IF(Dashboard!$B$6="Optimistic",Scenarios!G152,Scenarios!G237)) -> 1207602 | H11: =IF(Dashboard!$B$6="Base Case",Scenarios!H67,IF(Dashboard!$B$6="Optimistic",Scenarios!H152,Scenarios!H237)) -> 1280058.1 | I11: =IF(Dashboard!$B$6="Base Case",Scenarios!I67,IF(Dashboard!$B$6="Optimistic",Scenarios!I152,Scenarios!I237)) -> 1344061
A12: Revenue Growth % | B12: =IF(Dashboard!$B$6="Base Case",Scenarios!B68,IF(Dashboard!$B$6="Optimistic",Scenarios!B153,Scenarios!B238)) -> 0 | C12: =IF(Dashboard!$B$6="Base Case",Scenarios!C68,IF(Dashboard!$B$6="Optimistic",Scenarios!C153,Scenarios!C238)) -> 0.13333333 | D12: =IF(Dashboard!$B$6="Base Case",Scenarios!D68,IF(Dashboard!$B$6="Optimistic",Scenarios!D153,Scenarios!D238)) -> 0.11764706 | E12: =IF(Dashboard!$B$6="Base Case",Scenarios!E68,IF(Dashboard!$B$6="Optimistic",Scenarios!E153,Scenarios!E238)) -> 0.1 | F12: =IF(Dashboard!$B$6="Base Case",Scenarios!F68,IF(Dashboard!$B$6="Optimistic",Scenarios!F153,Scenarios!F238)) -> 0.08 | G12: =IF(Dashboard!$B$6="Base Case",Scenarios!G68,IF(Dashboard!$B$6="Optimistic",Scenarios!G153,Scenarios!G238)) -> 0.07 | H12: =IF(Dashboard!$B$6="Base Case",Scenarios!H68,IF(Dashboard!$B$6="Optimistic",Scenarios!H153,Scenarios!H238)) -> 0.06 | I12: =IF(Dashboard!$B$6="Base Case",Scenarios!I68,IF(Dashboard!$B$6="Optimistic",Scenarios!I153,Scenarios!I238)) -> 0.05
A13: Gross Profit (E£) | B13: =IF(Dashboard!$B$6="Base Case",Scenarios!B69,IF(Dashboard!$B$6="Optimistic",Scenarios!B154,Scenarios!B239)) -> 300000 | C13: =IF(Dashboard!$B$6="Base Case",Scenarios!C69,IF(Dashboard!$B$6="Optimistic",Scenarios!C154,Scenarios!C239)) -> 340000 | D13: =IF(Dashboard!$B$6="Base Case",Scenarios!D69,IF(Dashboard!$B$6="Optimistic",Scenarios!D154,Scenarios!D239)) -> 380000 | E13: =IF(Dashboard!$B$6="Base Case",Scenarios!E69,IF(Dashboard!$B$6="Optimistic",Scenarios!E154,Scenarios!E239)) -> 418000 | F13: =IF(Dashboard!$B$6="Base Case",Scenarios!F69,IF(Dashboard!$B$6="Optimistic",Scenarios!F154,Scenarios!F239)) -> 451440 | G13: =IF(Dashboard!$B$6="Base Case",Scenarios!G69,IF(Dashboard!$B$6="Optimistic",Scenarios!G154,Scenarios!G239)) -> 483040.8 | H13: =IF(Dashboard!$B$6="Base Case",Scenarios!H69,IF(Dashboard!$B$6="Optimistic",Scenarios!H154,Scenarios!H239)) -> 512023.25 | I13: =IF(Dashboard!$B$6="Base Case",Scenarios!I69,IF(Dashboard!$B$6="Optimistic",Scenarios!I154,Scenarios!I239)) -> 537624.41
A14: Gross Margin % | B14: =IF(Dashboard!$B$6="Base Case",Scenarios!B70,IF(Dashboard!$B$6="Optimistic",Scenarios!B155,Scenarios!B240)) -> 0.4 | C14: =IF(Dashboard!$B$6="Base Case",Scenarios!C70,IF(Dashboard!$B$6="Optimistic",Scenarios!C155,Scenarios!C240)) -> 0.4 | D14: =IF(Dashboard!$B$6="Base Case",Scenarios!D70,IF(Dashboard!$B$6="Optimistic",Scenarios!D155,Scenarios!D240)) -> 0.4 | E14: =IF(Dashboard!$B$6="Base Case",Scenarios!E70,IF(Dashboard!$B$6="Optimistic",Scenarios!E155,Scenarios!E240)) -> 0.4 | F14: =IF(Dashboard!$B$6="Base Case",Scenarios!F70,IF(Dashboard!$B$6="Optimistic",Scenarios!F155,Scenarios!F240)) -> 0.4 | G14: =IF(Dashboard!$B$6="Base Case",Scenarios!G70,IF(Dashboard!$B$6="Optimistic",Scenarios!G155,Scenarios!G240)) -> 0.4 | H14: =IF(Dashboard!$B$6="Base Case",Scenarios!H70,IF(Dashboard!$B$6="Optimistic",Scenarios!H155,Scenarios!H240)) -> 0.4 | I14: =IF(Dashboard!$B$6="Base Case",Scenarios!I70,IF(Dashboard!$B$6="Optimistic",Scenarios!I155,Scenarios!I240)) -> 0.4
A15: EBITDA (E£) | B15: =IF(Dashboard!$B$6="Base Case",Scenarios!B71,IF(Dashboard!$B$6="Optimistic",Scenarios!B156,Scenarios!B241)) -> 135000 | C15: =IF(Dashboard!$B$6="Base Case",Scenarios!C71,IF(Dashboard!$B$6="Optimistic",Scenarios!C156,Scenarios!C241)) -> 153000 | D15: =IF(Dashboard!$B$6="Base Case",Scenarios!D71,IF(Dashboard!$B$6="Optimistic",Scenarios!D156,Scenarios!D241)) -> 171000 | E15: =IF(Dashboard!$B$6="Base Case",Scenarios!E71,IF(Dashboard!$B$6="Optimistic",Scenarios!E156,Scenarios!E241)) -> 178100 | F15: =IF(Dashboard!$B$6="Base Case",Scenarios!F71,IF(Dashboard!$B$6="Optimistic",Scenarios!F156,Scenarios!F241)) -> 193148 | G15: =IF(Dashboard!$B$6="Base Case",Scenarios!G71,IF(Dashboard!$B$6="Optimistic",Scenarios!G156,Scenarios!G241)) -> 207368.36 | H15: =IF(Dashboard!$B$6="Base Case",Scenarios!H71,IF(Dashboard!$B$6="Optimistic",Scenarios!H156,Scenarios!H241)) -> 220410.46 | I15: =IF(Dashboard!$B$6="Base Case",Scenarios!I71,IF(Dashboard!$B$6="Optimistic",Scenarios!I156,Scenarios!I241)) -> 231930.98
A16: EBIT (E£) | B16: =IF(Dashboard!$B$6="Base Case",Scenarios!B72,IF(Dashboard!$B$6="Optimistic",Scenarios!B157,Scenarios!B242)) -> 105000 | C16: =IF(Dashboard!$B$6="Base Case",Scenarios!C72,IF(Dashboard!$B$6="Optimistic",Scenarios!C157,Scenarios!C242)) -> 120000 | D16: =IF(Dashboard!$B$6="Base Case",Scenarios!D72,IF(Dashboard!$B$6="Optimistic",Scenarios!D157,Scenarios!D242)) -> 134000 | E16: =IF(Dashboard!$B$6="Base Case",Scenarios!E72,IF(Dashboard!$B$6="Optimistic",Scenarios!E157,Scenarios!E242)) -> 131987.5 | F16: =IF(Dashboard!$B$6="Base Case",Scenarios!F72,IF(Dashboard!$B$6="Optimistic",Scenarios!F157,Scenarios!F242)) -> 141601.5 | G16: =IF(Dashboard!$B$6="Base Case",Scenarios!G72,IF(Dashboard!$B$6="Optimistic",Scenarios!G157,Scenarios!G242)) -> 149981.36 | H16: =IF(Dashboard!$B$6="Base Case",Scenarios!H72,IF(Dashboard!$B$6="Optimistic",Scenarios!H157,Scenarios!H242)) -> 156804.31 | I16: =IF(Dashboard!$B$6="Base Case",Scenarios!I72,IF(Dashboard!$B$6="Optimistic",Scenarios!I157,Scenarios!I242)) -> 161764.53
A17: EBIT Margin % | B17: =IF(Dashboard!$B$6="Base Case",Scenarios!B73,IF(Dashboard!$B$6="Optimistic",Scenarios!B158,Scenarios!B243)) -> 0.14 | C17: =IF(Dashboard!$B$6="Base Case",Scenarios!C73,IF(Dashboard!$B$6="Optimistic",Scenarios!C158,Scenarios!C243)) -> 0.14117647 | D17: =IF(Dashboard!$B$6="Base Case",Scenarios!D73,IF(Dashboard!$B$6="Optimistic",Scenarios!D158,Scenarios!D243)) -> 0.14105263 | E17: =IF(Dashboard!$B$6="Base Case",Scenarios!E73,IF(Dashboard!$B$6="Optimistic",Scenarios!E158,Scenarios!E243)) -> 0.12630383 | F17: =IF(Dashboard!$B$6="Base Case",Scenarios!F73,IF(Dashboard!$B$6="Optimistic",Scenarios!F158,Scenarios!F243)) -> 0.12546651 | G17: =IF(Dashboard!$B$6="Base Case",Scenarios!G73,IF(Dashboard!$B$6="Optimistic",Scenarios!G158,Scenarios!G243)) -> 0.12419767 | H17: =IF(Dashboard!$B$6="Base Case",Scenarios!H73,IF(Dashboard!$B$6="Optimistic",Scenarios!H158,Scenarios!H243)) -> 0.1224978 | I17: =IF(Dashboard!$B$6="Base Case",Scenarios!I73,IF(Dashboard!$B$6="Optimistic",Scenarios!I158,Scenarios!I243)) -> 0.12035505
A18: Net Income (E£) | B18: =IF(Dashboard!$B$6="Base Case",Scenarios!B74,IF(Dashboard!$B$6="Optimistic",Scenarios!B159,Scenarios!B244)) -> 68875 | C18: =IF(Dashboard!$B$6="Base Case",Scenarios!C74,IF(Dashboard!$B$6="Optimistic",Scenarios!C159,Scenarios!C244)) -> 81125 | D18: =IF(Dashboard!$B$6="Base Case",Scenarios!D74,IF(Dashboard!$B$6="Optimistic",Scenarios!D159,Scenarios!D244)) -> 92750 | E18: =IF(Dashboard!$B$6="Base Case",Scenarios!E74,IF(Dashboard!$B$6="Optimistic",Scenarios!E159,Scenarios!E244)) -> 63836.015 | F18: =IF(Dashboard!$B$6="Base Case",Scenarios!F74,IF(Dashboard!$B$6="Optimistic",Scenarios!F159,Scenarios!F244)) -> 75076.661 | G18: =IF(Dashboard!$B$6="Base Case",Scenarios!G74,IF(Dashboard!$B$6="Optimistic",Scenarios!G159,Scenarios!G244)) -> 85553.403 | H18: =IF(Dashboard!$B$6="Base Case",Scenarios!H74,IF(Dashboard!$B$6="Optimistic",Scenarios!H159,Scenarios!H244)) -> 95010.855 | I18: =IF(Dashboard!$B$6="Base Case",Scenarios!I74,IF(Dashboard!$B$6="Optimistic",Scenarios!I159,Scenarios!I244)) -> 103208.62
A19: Net Margin % | B19: =IF(Dashboard!$B$6="Base Case",Scenarios!B75,IF(Dashboard!$B$6="Optimistic",Scenarios!B160,Scenarios!B245)) -> 0.091833333 | C19: =IF(Dashboard!$B$6="Base Case",Scenarios!C75,IF(Dashboard!$B$6="Optimistic",Scenarios!C160,Scenarios!C245)) -> 0.095441176 | D19: =IF(Dashboard!$B$6="Base Case",Scenarios!D75,IF(Dashboard!$B$6="Optimistic",Scenarios!D160,Scenarios!D245)) -> 0.097631579 | E19: =IF(Dashboard!$B$6="Base Case",Scenarios!E75,IF(Dashboard!$B$6="Optimistic",Scenarios!E160,Scenarios!E245)) -> 0.061087096 | F19: =IF(Dashboard!$B$6="Base Case",Scenarios!F75,IF(Dashboard!$B$6="Optimistic",Scenarios!F160,Scenarios!F245)) -> 0.066521939 | G19: =IF(Dashboard!$B$6="Base Case",Scenarios!G75,IF(Dashboard!$B$6="Optimistic",Scenarios!G160,Scenarios!G245)) -> 0.070845695 | H19: =IF(Dashboard!$B$6="Base Case",Scenarios!H75,IF(Dashboard!$B$6="Optimistic",Scenarios!H160,Scenarios!H245)) -> 0.07422386 | I19: =IF(Dashboard!$B$6="Base Case",Scenarios!I75,IF(Dashboard!$B$6="Optimistic",Scenarios!I160,Scenarios!I245)) -> 0.076788638
A20: EPS (E£) | B20: =IF(Dashboard!$B$6="Base Case",Scenarios!B76,IF(Dashboard!$B$6="Optimistic",Scenarios!B161,Scenarios!B246)) -> 0.68875 | C20: =IF(Dashboard!$B$6="Base Case",Scenarios!C76,IF(Dashboard!$B$6="Optimistic",Scenarios!C161,Scenarios!C246)) -> 0.81125 | D20: =IF(Dashboard!$B$6="Base Case",Scenarios!D76,IF(Dashboard!$B$6="Optimistic",Scenarios!D161,Scenarios!D246)) -> 0.9275 | E20: =IF(Dashboard!$B$6="Base Case",Scenarios!E76,IF(Dashboard!$B$6="Optimistic",Scenarios!E161,Scenarios!E246)) -> 0.63836015 | F20: =IF(Dashboard!$B$6="Base Case",Scenarios!F76,IF(Dashboard!$B$6="Optimistic",Scenarios!F161,Scenarios!F246)) -> 0.75076661 | G20: =IF(Dashboard!$B$6="Base Case",Scenarios!G76,IF(Dashboard!$B$6="Optimistic",Scenarios!G161,Scenarios!G246)) -> 0.85553403 | H20: =IF(Dashboard!$B$6="Base Case",Scenarios!H76,IF(Dashboard!$B$6="Optimistic",Scenarios!H161,Scenarios!H246)) -> 0.95010855 | I20: =IF(Dashboard!$B$6="Base Case",Scenarios!I76,IF(Dashboard!$B$6="Optimistic",Scenarios!I161,Scenarios!I246)) -> 1.0320862
A21: 💵 CASH FLOW
A22: CFO (E£) | B22: — | C22: =IF(Dashboard!$B$6="Base Case",Scenarios!C77,IF(Dashboard!$B$6="Optimistic",Scenarios!C162,Scenarios!C247)) -> 107439 | D22: =IF(Dashboard!$B$6="Base Case",Scenarios!D77,IF(Dashboard!$B$6="Optimistic",Scenarios!D162,Scenarios!D247)) -> 123067 | E22: =IF(Dashboard!$B$6="Base Case",Scenarios!E77,IF(Dashboard!$B$6="Optimistic",Scenarios!E162,Scenarios!E247)) -> 113596.98 | F22: =IF(Dashboard!$B$6="Base Case",Scenarios!F77,IF(Dashboard!$B$6="Optimistic",Scenarios!F162,Scenarios!F247)) -> 131034.56 | G22: =IF(Dashboard!$B$6="Base Case",Scenarios!G77,IF(Dashboard!$B$6="Optimistic",Scenarios!G162,Scenarios!G247)) -> 147659.18 | H22: =IF(Dashboard!$B$6="Base Case",Scenarios!H77,IF(Dashboard!$B$6="Optimistic",Scenarios!H162,Scenarios!H247)) -> 163773.37 | I22: =IF(Dashboard!$B$6="Base Case",Scenarios!I77,IF(Dashboard!$B$6="Optimistic",Scenarios!I162,Scenarios!I247)) -> 179096.52
A23: Free Cash Flow (E£) | B23: — | C23: =IF(Dashboard!$B$6="Base Case",Scenarios!C78,IF(Dashboard!$B$6="Optimistic",Scenarios!C163,Scenarios!C248)) -> 67439 | D23: =IF(Dashboard!$B$6="Base Case",Scenarios!D78,IF(Dashboard!$B$6="Optimistic",Scenarios!D163,Scenarios!D248)) -> 78067 | E23: =IF(Dashboard!$B$6="Base Case",Scenarios!E78,IF(Dashboard!$B$6="Optimistic",Scenarios!E163,Scenarios!E248)) -> 61346.981 | F23: =IF(Dashboard!$B$6="Base Case",Scenarios!F78,IF(Dashboard!$B$6="Optimistic",Scenarios!F163,Scenarios!F248)) -> 74604.558 | G23: =IF(Dashboard!$B$6="Base Case",Scenarios!G78,IF(Dashboard!$B$6="Optimistic",Scenarios!G163,Scenarios!G248)) -> 87279.078 | H23: =IF(Dashboard!$B$6="Base Case",Scenarios!H78,IF(Dashboard!$B$6="Optimistic",Scenarios!H163,Scenarios!H248)) -> 99770.462 | I23: =IF(Dashboard!$B$6="Base Case",Scenarios!I78,IF(Dashboard!$B$6="Optimistic",Scenarios!I163,Scenarios!I248)) -> 111893.47
A24: Ending Cash (E£) | B24: — | C24: =IF(Dashboard!$B$6="Base Case",Scenarios!C79,IF(Dashboard!$B$6="Optimistic",Scenarios!C164,Scenarios!C249)) -> 175000 | D24: =IF(Dashboard!$B$6="Base Case",Scenarios!D79,IF(Dashboard!$B$6="Optimistic",Scenarios!D164,Scenarios!D249)) -> 200000 | E24: =IF(Dashboard!$B$6="Base Case",Scenarios!E79,IF(Dashboard!$B$6="Optimistic",Scenarios!E164,Scenarios!E249)) -> 238155.18 | F24: =IF(Dashboard!$B$6="Base Case",Scenarios!F79,IF(Dashboard!$B$6="Optimistic",Scenarios!F164,Scenarios!F249)) -> 289005.91 | G24: =IF(Dashboard!$B$6="Base Case",Scenarios!G79,IF(Dashboard!$B$6="Optimistic",Scenarios!G164,Scenarios!G249)) -> 352007.31 | H24: =IF(Dashboard!$B$6="Base Case",Scenarios!H79,IF(Dashboard!$B$6="Optimistic",Scenarios!H164,Scenarios!H249)) -> 427027.23 | I24: =IF(Dashboard!$B$6="Base Case",Scenarios!I79,IF(Dashboard!$B$6="Optimistic",Scenarios!I164,Scenarios!I249)) -> 513760.27
A25: 🏦 BALANCE SHEET
A26: Total Assets (E£) | B26: =IF(Dashboard!$B$6="Base Case",Scenarios!B80,IF(Dashboard!$B$6="Optimistic",Scenarios!B165,Scenarios!B250)) -> 666952 | C26: =IF(Dashboard!$B$6="Base Case",Scenarios!C80,IF(Dashboard!$B$6="Optimistic",Scenarios!C165,Scenarios!C250)) -> 717213 | D26: =IF(Dashboard!$B$6="Base Case",Scenarios!D80,IF(Dashboard!$B$6="Optimistic",Scenarios!D165,Scenarios!D250)) -> 768472 | E26: =IF(Dashboard!$B$6="Base Case",Scenarios!E80,IF(Dashboard!$B$6="Optimistic",Scenarios!E165,Scenarios!E250)) -> 830112.54 | F26: =IF(Dashboard!$B$6="Base Case",Scenarios!F80,IF(Dashboard!$B$6="Optimistic",Scenarios!F165,Scenarios!F250)) -> 901112.36 | G26: =IF(Dashboard!$B$6="Base Case",Scenarios!G80,IF(Dashboard!$B$6="Optimistic",Scenarios!G165,Scenarios!G250)) -> 981532.84 | H26: =IF(Dashboard!$B$6="Base Case",Scenarios!H80,IF(Dashboard!$B$6="Optimistic",Scenarios!H165,Scenarios!H250)) -> 1070180.2 | I26: =IF(Dashboard!$B$6="Base Case",Scenarios!I80,IF(Dashboard!$B$6="Optimistic",Scenarios!I165,Scenarios!I250)) -> 1165636.9
A27: Total Debt (E£) | B27: =IF(Dashboard!$B$6="Base Case",Scenarios!B81,IF(Dashboard!$B$6="Optimistic",Scenarios!B166,Scenarios!B251)) -> 320000 | C27: =IF(Dashboard!$B$6="Base Case",Scenarios!C81,IF(Dashboard!$B$6="Optimistic",Scenarios!C166,Scenarios!C251)) -> 300000 | D27: =IF(Dashboard!$B$6="Base Case",Scenarios!D81,IF(Dashboard!$B$6="Optimistic",Scenarios!D166,Scenarios!D251)) -> 280000 | E27: =IF(Dashboard!$B$6="Base Case",Scenarios!E81,IF(Dashboard!$B$6="Optimistic",Scenarios!E166,Scenarios!E251)) -> 260000 | F27: =IF(Dashboard!$B$6="Base Case",Scenarios!F81,IF(Dashboard!$B$6="Optimistic",Scenarios!F166,Scenarios!F251)) -> 240000 | G27: =IF(Dashboard!$B$6="Base Case",Scenarios!G81,IF(Dashboard!$B$6="Optimistic",Scenarios!G166,Scenarios!G251)) -> 220000 | H27: =IF(Dashboard!$B$6="Base Case",Scenarios!H81,IF(Dashboard!$B$6="Optimistic",Scenarios!H166,Scenarios!H251)) -> 200000 | I27: =IF(Dashboard!$B$6="Base Case",Scenarios!I81,IF(Dashboard!$B$6="Optimistic",Scenarios!I166,Scenarios!I251)) -> 180000
A28: Total Equity (E£) | B28: =IF(Dashboard!$B$6="Base Case",Scenarios!B82,IF(Dashboard!$B$6="Optimistic",Scenarios!B167,Scenarios!B252)) -> 190137 | C28: =IF(Dashboard!$B$6="Base Case",Scenarios!C82,IF(Dashboard!$B$6="Optimistic",Scenarios!C167,Scenarios!C252)) -> 248823 | D28: =IF(Dashboard!$B$6="Base Case",Scenarios!D82,IF(Dashboard!$B$6="Optimistic",Scenarios!D167,Scenarios!D252)) -> 308506 | E28: =IF(Dashboard!$B$6="Base Case",Scenarios!E82,IF(Dashboard!$B$6="Optimistic",Scenarios!E167,Scenarios!E252)) -> 379150.21 | F28: =IF(Dashboard!$B$6="Base Case",Scenarios!F82,IF(Dashboard!$B$6="Optimistic",Scenarios!F167,Scenarios!F252)) -> 460473.04 | G28: =IF(Dashboard!$B$6="Base Case",Scenarios!G82,IF(Dashboard!$B$6="Optimistic",Scenarios!G167,Scenarios!G252)) -> 551748.77 | H28: =IF(Dashboard!$B$6="Base Case",Scenarios!H82,IF(Dashboard!$B$6="Optimistic",Scenarios!H167,Scenarios!H252)) -> 652009.09 | I28: =IF(Dashboard!$B$6="Base Case",Scenarios!I82,IF(Dashboard!$B$6="Optimistic",Scenarios!I167,Scenarios!I252)) -> 760057.27
A29: Cash (E£) | B29: =IF(Dashboard!$B$6="Base Case",Scenarios!B83,IF(Dashboard!$B$6="Optimistic",Scenarios!B168,Scenarios!B253)) -> 150000 | C29: =IF(Dashboard!$B$6="Base Case",Scenarios!C83,IF(Dashboard!$B$6="Optimistic",Scenarios!C168,Scenarios!C253)) -> 175000 | D29: =IF(Dashboard!$B$6="Base Case",Scenarios!D83,IF(Dashboard!$B$6="Optimistic",Scenarios!D168,Scenarios!D253)) -> 200000 | E29: =IF(Dashboard!$B$6="Base Case",Scenarios!E83,IF(Dashboard!$B$6="Optimistic",Scenarios!E168,Scenarios!E253)) -> 238155.18 | F29: =IF(Dashboard!$B$6="Base Case",Scenarios!F83,IF(Dashboard!$B$6="Optimistic",Scenarios!F168,Scenarios!F253)) -> 289005.91 | G29: =IF(Dashboard!$B$6="Base Case",Scenarios!G83,IF(Dashboard!$B$6="Optimistic",Scenarios!G168,Scenarios!G253)) -> 352007.31 | H29: =IF(Dashboard!$B$6="Base Case",Scenarios!H83,IF(Dashboard!$B$6="Optimistic",Scenarios!H168,Scenarios!H253)) -> 427027.23 | I29: =IF(Dashboard!$B$6="Base Case",Scenarios!I83,IF(Dashboard!$B$6="Optimistic",Scenarios!I168,Scenarios!I253)) -> 513760.27
A30: 📊 KEY RATIOS
A31: Current Ratio | B31: =IF(Dashboard!$B$6="Base Case",Scenarios!B84,IF(Dashboard!$B$6="Optimistic",Scenarios!B169,Scenarios!B254)) -> 1.7283241 | C31: =IF(Dashboard!$B$6="Base Case",Scenarios!C84,IF(Dashboard!$B$6="Optimistic",Scenarios!C169,Scenarios!C254)) -> 1.8551339 | D31: =IF(Dashboard!$B$6="Base Case",Scenarios!D84,IF(Dashboard!$B$6="Optimistic",Scenarios!D169,Scenarios!D254)) -> 1.966866 | E31: =IF(Dashboard!$B$6="Base Case",Scenarios!E84,IF(Dashboard!$B$6="Optimistic",Scenarios!E169,Scenarios!E254)) -> 2.1313366 | F31: =IF(Dashboard!$B$6="Base Case",Scenarios!F84,IF(Dashboard!$B$6="Optimistic",Scenarios!F169,Scenarios!F254)) -> 2.3422972 | G31: =IF(Dashboard!$B$6="Base Case",Scenarios!G84,IF(Dashboard!$B$6="Optimistic",Scenarios!G169,Scenarios!G254)) -> 2.5914592 | H31: =IF(Dashboard!$B$6="Base Case",Scenarios!H84,IF(Dashboard!$B$6="Optimistic",Scenarios!H169,Scenarios!H254)) -> 2.8767258 | I31: =IF(Dashboard!$B$6="Base Case",Scenarios!I84,IF(Dashboard!$B$6="Optimistic",Scenarios!I169,Scenarios!I254)) -> 3.197234
A32: Debt / Equity | B32: =IF(Dashboard!$B$6="Base Case",Scenarios!B85,IF(Dashboard!$B$6="Optimistic",Scenarios!B170,Scenarios!B255)) -> 1.682997 | C32: =IF(Dashboard!$B$6="Base Case",Scenarios!C85,IF(Dashboard!$B$6="Optimistic",Scenarios!C170,Scenarios!C255)) -> 1.2056763 | D32: =IF(Dashboard!$B$6="Base Case",Scenarios!D85,IF(Dashboard!$B$6="Optimistic",Scenarios!D170,Scenarios!D255)) -> 0.90759985 | E32: =IF(Dashboard!$B$6="Base Case",Scenarios!E85,IF(Dashboard!$B$6="Optimistic",Scenarios!E170,Scenarios!E255)) -> 0.68574404 | F32: =IF(Dashboard!$B$6="Base Case",Scenarios!F85,IF(Dashboard!$B$6="Optimistic",Scenarios!F170,Scenarios!F255)) -> 0.52120315 | G32: =IF(Dashboard!$B$6="Base Case",Scenarios!G85,IF(Dashboard!$B$6="Optimistic",Scenarios!G170,Scenarios!G255)) -> 0.39873219 | H32: =IF(Dashboard!$B$6="Base Case",Scenarios!H85,IF(Dashboard!$B$6="Optimistic",Scenarios!H170,Scenarios!H255)) -> 0.30674419 | I32: =IF(Dashboard!$B$6="Base Case",Scenarios!I85,IF(Dashboard!$B$6="Optimistic",Scenarios!I170,Scenarios!I255)) -> 0.23682426
A33: ROE % | B33: =IF(Dashboard!$B$6="Base Case",Scenarios!B86,IF(Dashboard!$B$6="Optimistic",Scenarios!B171,Scenarios!B256)) -> 0.36223881 | C33: =IF(Dashboard!$B$6="Base Case",Scenarios!C86,IF(Dashboard!$B$6="Optimistic",Scenarios!C171,Scenarios!C256)) -> 0.36962366 | D33: =IF(Dashboard!$B$6="Base Case",Scenarios!D86,IF(Dashboard!$B$6="Optimistic",Scenarios!D171,Scenarios!D256)) -> 0.33283752 | E33: =IF(Dashboard!$B$6="Base Case",Scenarios!E86,IF(Dashboard!$B$6="Optimistic",Scenarios!E171,Scenarios!E256)) -> 0.18566258 | F33: =IF(Dashboard!$B$6="Base Case",Scenarios!F86,IF(Dashboard!$B$6="Optimistic",Scenarios!F171,Scenarios!F256)) -> 0.17883416 | G33: =IF(Dashboard!$B$6="Base Case",Scenarios!G86,IF(Dashboard!$B$6="Optimistic",Scenarios!G171,Scenarios!G256)) -> 0.16904082 | H33: =IF(Dashboard!$B$6="Base Case",Scenarios!H86,IF(Dashboard!$B$6="Optimistic",Scenarios!H171,Scenarios!H256)) -> 0.15785709 | I33: =IF(Dashboard!$B$6="Base Case",Scenarios!I86,IF(Dashboard!$B$6="Optimistic",Scenarios!I171,Scenarios!I256)) -> 0.14618097
A34: ROA % | B34: =IF(Dashboard!$B$6="Base Case",Scenarios!B87,IF(Dashboard!$B$6="Optimistic",Scenarios!B172,Scenarios!B257)) -> 0.1032683 | C34: =IF(Dashboard!$B$6="Base Case",Scenarios!C87,IF(Dashboard!$B$6="Optimistic",Scenarios!C172,Scenarios!C257)) -> 0.11721868 | D34: =IF(Dashboard!$B$6="Base Case",Scenarios!D87,IF(Dashboard!$B$6="Optimistic",Scenarios!D172,Scenarios!D257)) -> 0.12485823 | E34: =IF(Dashboard!$B$6="Base Case",Scenarios!E87,IF(Dashboard!$B$6="Optimistic",Scenarios!E172,Scenarios!E257)) -> 0.079865673 | F34: =IF(Dashboard!$B$6="Base Case",Scenarios!F87,IF(Dashboard!$B$6="Optimistic",Scenarios!F172,Scenarios!F257)) -> 0.086732418 | G34: =IF(Dashboard!$B$6="Base Case",Scenarios!G87,IF(Dashboard!$B$6="Optimistic",Scenarios!G172,Scenarios!G257)) -> 0.090886379 | H34: =IF(Dashboard!$B$6="Base Case",Scenarios!H87,IF(Dashboard!$B$6="Optimistic",Scenarios!H172,Scenarios!H257)) -> 0.092616124 | I34: =IF(Dashboard!$B$6="Base Case",Scenarios!I87,IF(Dashboard!$B$6="Optimistic",Scenarios!I172,Scenarios!I257)) -> 0.092322948
A37: ⚖️ SCENARIO COMPARISON — Terminal Year
A38: Metric | B38: Active Scenario
A39: Revenue | B39: =IF(Dashboard!$B$6="Base Case",Scenarios!I67,IF(Dashboard!$B$6="Optimistic",Scenarios!I152,Scenarios!I237)) -> 1344061
A40: EBITDA | B40: =IF(Dashboard!$B$6="Base Case",Scenarios!I71,IF(Dashboard!$B$6="Optimistic",Scenarios!I156,Scenarios!I241)) -> 231930.98
A41: Net Income | B41: =IF(Dashboard!$B$6="Base Case",Scenarios!I74,IF(Dashboard!$B$6="Optimistic",Scenarios!I159,Scenarios!I244)) -> 103208.62
A42: Free Cash Flow | B42: =IF(Dashboard!$B$6="Base Case",Scenarios!I78,IF(Dashboard!$B$6="Optimistic",Scenarios!I163,Scenarios!I248)) -> 111893.47
A43: Cash Balance | B43: =IF(Dashboard!$B$6="Base Case",Scenarios!I83,IF(Dashboard!$B$6="Optimistic",Scenarios!I168,Scenarios!I253)) -> 513760.27
A44: Total Equity | B44: =IF(Dashboard!$B$6="Base Case",Scenarios!I82,IF(Dashboard!$B$6="Optimistic",Scenarios!I167,Scenarios!I252)) -> 760057.27
...

Sheet Company Info
A1: COMPANY INFORMATION & MODEL CONFIGURATION
A3: SECTION 1 — COMPANY IDENTIFICATION
A4: Company Name | B4: WOLF | C4: ← Edit
A5: Legal Entity Type | B5: Société Anonyme (S.A.E.) | C5: ← Edit
A6: Industry / Sector | B6: Technology / Software | C6: ← Edit
A7: Founded Year | B7: 2010 | C7: ← Edit
A8: Commercial Register No. | B8: 12345-Cairo-2010 | C8: Auto
A9: Tax Identification No. | B9: 123-456-789 | C9: Auto
A10: Headquarters Address | B10: 5 El-Nile Street, Zamalek, Cairo, Egypt | C10: Auto
A12: SECTION 2 — FINANCIAL MODEL CONFIGURATION
A13: Reporting Currency | B13: Egyptian Pound (EGP) | C13: Auto
A14: Currency Symbol | B14: E£ | C14: Auto
A15: Fiscal Year End | B15: December 31 | C15: ← Edit
A16: Historical Period | B16: 2021 – 2023 (Actual) | C16: Auto
A17: Projection Period | B17: 2024E – 2028E (5 Years) | C17: Auto
A18: Revenue Projection Base (E£) | B18: 1000000 | C18: ← Edit
A19: Model Version | B19: v2.0 | Feb 2026 | C19: Auto
A20: Last Updated | B20: February 20, 2026 | C20: Auto
A22: SECTION 3 — EGYPT REGULATORY / TAX
A23: Corporate Income Tax Rate | B23: 0.225 | C23: ← Edit
A24: VAT Rate (Standard) | B24: 0.14 | C24: ← Edit
A25: Dividend Withholding Tax | B25: 0.1 | C25: ← Edit
A26: CBE Policy Rate (Reference) | B26: 0.2725 | C26: ← Edit
A27: Financial Year Note | B27: July 1 – June 30 (Note: model uses Dec) | C27: Auto
A29: SECTION 4 — REPORT & PREPARER INFORMATION
A30: Prepared By | B30: Financial Modeling Team | C30: ← Edit
A31: Reviewed By | B31: CFO | C31: ← Edit
A32: Preparation Date | B32: February 20, 2026 | C32: ← Edit
A33: Purpose | B33: Internal Planning & Analysis | C33: ← Edit
A34: Confidentiality | B34: CONFIDENTIAL — Internal Use Only | C34: ← Edit
A35: Contact Email | B35: finance@democompany.com | C35: ← Edit
A37: Note: Blue-text cells are editable inputs. Company Name (B4) flows to Dashboard and all sheet headers.

Sheet Scenarios
A1: SCENARIO DATA — COMPLETE ENGINE VALUES
A2: This sheet stores the full engine-computed data for each scenario. All projection columns in Assumptions reference this sheet via IF formulas.
A4: ▎ BASE CASE · Moderate growth with stable margins
A5: Assumption / Computed Value | B5: 2021 | C5: 2022 | D5: 2023 | E5: 2024E | F5: 2025E | G5: 2026E | H5: 2027E | I5: 2028E
A6: ── Income Statement Drivers ──
A7: Revenue Base (Historical) | B7: 750000 | C7: 0 | D7: 0 | E7: 0 | F7: 0 | G7: 0 | H7: 0 | I7: 0
A8: Revenue Base (Projection) | B8: 1000000 | C8: 0 | D8: 0 | E8: 0 | F8: 0 | G8: 0 | H8: 0 | I8: 0
A9: Revenue Growth Rate | B9: 0 | C9: 0.13333333 | D9: 0.11764706 | E9: 0.1 | F9: 0.08 | G9: 0.07 | H9: 0.06 | I9: 0.05
A10: COGS % of Revenue | B10: 0.6 | C10: 0.6 | D10: 0.6 | E10: 0.6 | F10: 0.6 | G10: 0.6 | H10: 0.6 | I10: 0.6
A11: SG&A % of Revenue | B11: 0.15 | C11: 0.15 | D11: 0.15 | E11: 0.15 | F11: 0.15 | G11: 0.15 | H11: 0.15 | I11: 0.15
A12: R&D % of Revenue | B12: 0.05 | C12: 0.05 | D12: 0.05 | E12: 0.05 | F12: 0.05 | G12: 0.05 | H12: 0.05 | I12: 0.05
A13: Other OpEx % of Revenue | B13: 0.02 | C13: 0.02 | D13: 0.02 | E13: 0.02 | F13: 0.02 | G13: 0.02 | H13: 0.02 | I13: 0.02
A14: Tax Rate | B14: 0.2513587 | C14: 0.25230415 | D14: 0.25201613 | E14: 0.225 | F14: 0.225 | G14: 0.225 | H14: 0.225 | I14: 0.225
A15: Other Income / Expense | B15: 0 | C15: 0 | D15: 0 | E15: 0 | F15: 0 | G15: 0 | H15: 0 | I15: 0
A16: Shares Outstanding | B16: 100000 | C16: 100000 | D16: 100000 | E16: 100000 | F16: 100000 | G16: 100000 | H16: 100000 | I16: 100000
A17: Stock-Based Comp Amount | B17: 0 | C17: 0 | D17: 0 | E17: 10000 | F17: 10000 | G17: 10000 | H17: 10000 | I17: 10000
A18: ── Balance Sheet / WC Drivers ──
A19: DSO (Days) | B19: 45.00012 | C19: 45.000206 | D19: 44.999889 | E19: 45 | F19: 45 | G19: 45 | H19: 45 | I19: 45
A20: DIO (Days) | B20: 29.999756 | C20: 30.000137 | D20: 29.999798 | E20: 30 | F20: 30 | G20: 30 | H20: 30 | I20: 30
A21: DPO (Days) | B21: 39.999944 | C21: 39.999706 | D21: 40.000158 | E21: 40 | F21: 40 | G21: 40 | H21: 40 | I21: 40
A22: Prepaid % of Revenue | B22: 0.01 | C22: 0.01 | D22: 0.01 | E22: 0.01 | F22: 0.01 | G22: 0.01 | H22: 0.01 | I22: 0.01
A23: Accrued Exp % of Revenue | B23: 0.03 | C23: 0.03 | D23: 0.03 | E23: 0.03 | F23: 0.03 | G23: 0.03 | H23: 0.03 | I23: 0.03
A24: Deferred Rev % of Revenue | B24: 0.02 | C24: 0.02 | D24: 0.02 | E24: 0.02 | F24: 0.02 | G24: 0.02 | H24: 0.02 | I24: 0.02
A25: ── CapEx & Depreciation ──
A26: CapEx % of Revenue | B26: 0 | C26: 0.047058824 | D26: 0.047368421 | E26: 0.05 | F26: 0.05 | G26: 0.05 | H26: 0.05 | I26: 0.05
A27: Depreciation Rate (% Gross PPE) | B27: 0.083333333 | C27: 0.082352941 | D27: 0.083116883 | E27: 0.094025157 | F27: 0.094284759 | G27: 0.094551124 | H27: 0.094822299 | I27: 0.095096572
A28: Amortization Amount | B28: 5000 | C28: 5000 | D28: 5000 | E28: 5000 | F28: 5000 | G28: 5000 | H28: 5000 | I28: 5000
A29: ── Debt & Financing ──
A30: Interest Rate (on Debt) | B30: 0.2 | C30: 0.2 | D30: 0.2 | E30: 0.2 | F30: 0.2 | G30: 0.2 | H30: 0.2 | I30: 0.2
A31: Interest Income Rate (on Cash) | B31: 0.02 | C31: 0.02 | D31: 0.02 | E31: 0.02 | F31: 0.02 | G31: 0.02 | H31: 0.02 | I31: 0.02
A32: Short-Term Debt | B32: 50000 | C32: 50000 | D32: 50000 | E32: 50000 | F32: 50000 | G32: 50000 | H32: 50000 | I32: 50000
A33: LT Debt Issuance | B33: 0 | C33: 0 | D33: 0 | E33: 0 | F33: 0 | G33: 0 | H33: 0 | I33: 0
A34: LT Debt Repayment | B34: 0 | C34: 20000 | D34: 20000 | E34: 20000 | F34: 20000 | G34: 20000 | H34: 20000 | I34: 20000
A35: Current Portion LTD | B35: 20000 | C35: 20000 | D35: 20000 | E35: 20000 | F35: 20000 | G35: 20000 | H35: 20000 | I35: 20000
A36: Dividend Payout Ratio | B36: 0 | C36: 0.39986441 | D36: 0.46433423 | E36: 0.05 | F36: 0.05 | G36: 0.05 | H36: 0.05 | I36: 0.05
A37: Share Repurchase Amount | B37: 0 | C37: 0 | D37: 0 | E37: 0 | F37: 0 | G37: 0 | H37: 0 | I37: 0
A38: Equity Issuance | B38: 0 | C38: 10000 | D38: 10000 | E38: 0 | F38: 0 | G38: 0 | H38: 0 | I38: 0
A39: ── BS / Equity Direct Values ──
A40: Goodwill | B40: 100000 | C40: 100000 | D40: 100000 | E40: 100000 | F40: 100000 | G40: 100000 | H40: 100000 | I40: 100000
A41: Other Current Assets | B41: 10000 | C41: 10000 | D41: 10000 | E41: 10000 | F41: 10000 | G41: 10000 | H41: 10000 | I41: 10000
...

Sheet Assumptions
A1: Assumption | B1: 2021 | C1: 2022 | D1: 2023 | E1: 2024E | F1: 2025E | G1: 2026E | H1: 2027E | I1: 2028E
A2: ── Income Statement Drivers ──
A3: Revenue Base (Historical) | B3: 750000 | E3: =IF(Assumptions!$B$64="Base Case",Scenarios!E7,IF(Assumptions!$B$64="Optimistic",Scenarios!E92,Scenarios!E177)) -> 0 | F3: =IF(Assumptions!$B$64="Base Case",Scenarios!F7,IF(Assumptions!$B$64="Optimistic",Scenarios!F92,Scenarios!F177)) -> 0 | G3: =IF(Assumptions!$B$64="Base Case",Scenarios!G7,IF(Assumptions!$B$64="Optimistic",Scenarios!G92,Scenarios!G177)) -> 0 | H3: =IF(Assumptions!$B$64="Base Case",Scenarios!H7,IF(Assumptions!$B$64="Optimistic",Scenarios!H92,Scenarios!H177)) -> 0 | I3: =IF(Assumptions!$B$64="Base Case",Scenarios!I7,IF(Assumptions!$B$64="Optimistic",Scenarios!I92,Scenarios!I177)) -> 0
A4: Revenue Base (Projection) | B4: 1000000 | E4: =IF(Assumptions!$B$64="Base Case",Scenarios!E8,IF(Assumptions!$B$64="Optimistic",Scenarios!E93,Scenarios!E178)) -> 0 | F4: =IF(Assumptions!$B$64="Base Case",Scenarios!F8,IF(Assumptions!$B$64="Optimistic",Scenarios!F93,Scenarios!F178)) -> 0 | G4: =IF(Assumptions!$B$64="Base Case",Scenarios!G8,IF(Assumptions!$B$64="Optimistic",Scenarios!G93,Scenarios!G178)) -> 0 | H4: =IF(Assumptions!$B$64="Base Case",Scenarios!H8,IF(Assumptions!$B$64="Optimistic",Scenarios!H93,Scenarios!H178)) -> 0 | I4: =IF(Assumptions!$B$64="Base Case",Scenarios!I8,IF(Assumptions!$B$64="Optimistic",Scenarios!I93,Scenarios!I178)) -> 0
A5: Revenue Growth Rate | B5: 0 | C5: 0.13333333 | D5: 0.11764706 | E5: =IF(Assumptions!$B$64="Base Case",Scenarios!E9,IF(Assumptions!$B$64="Optimistic",Scenarios!E94,Scenarios!E179)) -> 0.1 | F5: =IF(Assumptions!$B$64="Base Case",Scenarios!F9,IF(Assumptions!$B$64="Optimistic",Scenarios!F94,Scenarios!F179)) -> 0.08 | G5: =IF(Assumptions!$B$64="Base Case",Scenarios!G9,IF(Assumptions!$B$64="Optimistic",Scenarios!G94,Scenarios!G179)) -> 0.07 | H5: =IF(Assumptions!$B$64="Base Case",Scenarios!H9,IF(Assumptions!$B$64="Optimistic",Scenarios!H94,Scenarios!H179)) -> 0.06 | I5: =IF(Assumptions!$B$64="Base Case",Scenarios!I9,IF(Assumptions!$B$64="Optimistic",Scenarios!I94,Scenarios!I179)) -> 0.05
A6: COGS % of Revenue | B6: 0.6 | C6: 0.6 | D6: 0.6 | E6: =IF(Assumptions!$B$64="Base Case",Scenarios!E10,IF(Assumptions!$B$64="Optimistic",Scenarios!E95,Scenarios!E180)) -> 0.6 | F6: =IF(Assumptions!$B$64="Base Case",Scenarios!F10,IF(Assumptions!$B$64="Optimistic",Scenarios!F95,Scenarios!F180)) -> 0.6 | G6: =IF(Assumptions!$B$64="Base Case",Scenarios!G10,IF(Assumptions!$B$64="Optimistic",Scenarios!G95,Scenarios!G180)) -> 0.6 | H6: =IF(Assumptions!$B$64="Base Case",Scenarios!H10,IF(Assumptions!$B$64="Optimistic",Scenarios!H95,Scenarios!H180)) -> 0.6 | I6: =IF(Assumptions!$B$64="Base Case",Scenarios!I10,IF(Assumptions!$B$64="Optimistic",Scenarios!I95,Scenarios!I180)) -> 0.6
A7: SG&A % of Revenue | B7: 0.15 | C7: 0.15 | D7: 0.15 | E7: =IF(Assumptions!$B$64="Base Case",Scenarios!E11,IF(Assumptions!$B$64="Optimistic",Scenarios!E96,Scenarios!E181)) -> 0.15 | F7: =IF(Assumptions!$B$64="Base Case",Scenarios!F11,IF(Assumptions!$B$64="Optimistic",Scenarios!F96,Scenarios!F181)) -> 0.15 | G7: =IF(Assumptions!$B$64="Base Case",Scenarios!G11,IF(Assumptions!$B$64="Optimistic",Scenarios!G96,Scenarios!G181)) -> 0.15 | H7: =IF(Assumptions!$B$64="Base Case",Scenarios!H11,IF(Assumptions!$B$64="Optimistic",Scenarios!H96,Scenarios!H181)) -> 0.15 | I7: =IF(Assumptions!$B$64="Base Case",Scenarios!I11,IF(Assumptions!$B$64="Optimistic",Scenarios!I96,Scenarios!I181)) -> 0.15
A8: R&D % of Revenue | B8: 0.05 | C8: 0.05 | D8: 0.05 | E8: =IF(Assumptions!$B$64="Base Case",Scenarios!E12,IF(Assumptions!$B$64="Optimistic",Scenarios!E97,Scenarios!E182)) -> 0.05 | F8: =IF(Assumptions!$B$64="Base Case",Scenarios!F12,IF(Assumptions!$B$64="Optimistic",Scenarios!F97,Scenarios!F182)) -> 0.05 | G8: =IF(Assumptions!$B$64="Base Case",Scenarios!G12,IF(Assumptions!$B$64="Optimistic",Scenarios!G97,Scenarios!G182)) -> 0.05 | H8: =IF(Assumptions!$B$64="Base Case",Scenarios!H12,IF(Assumptions!$B$64="Optimistic",Scenarios!H97,Scenarios!H182)) -> 0.05 | I8: =IF(Assumptions!$B$64="Base Case",Scenarios!I12,IF(Assumptions!$B$64="Optimistic",Scenarios!I97,Scenarios!I182)) -> 0.05
A9: Other OpEx % of Revenue | B9: 0.02 | C9: 0.02 | D9: 0.02 | E9: =IF(Assumptions!$B$64="Base Case",Scenarios!E13,IF(Assumptions!$B$64="Optimistic",Scenarios!E98,Scenarios!E183)) -> 0.02 | F9: =IF(Assumptions!$B$64="Base Case",Scenarios!F13,IF(Assumptions!$B$64="Optimistic",Scenarios!F98,Scenarios!F183)) -> 0.02 | G9: =IF(Assumptions!$B$64="Base Case",Scenarios!G13,IF(Assumptions!$B$64="Optimistic",Scenarios!G98,Scenarios!G183)) -> 0.02 | H9: =IF(Assumptions!$B$64="Base Case",Scenarios!H13,IF(Assumptions!$B$64="Optimistic",Scenarios!H98,Scenarios!H183)) -> 0.02 | I9: =IF(Assumptions!$B$64="Base Case",Scenarios!I13,IF(Assumptions!$B$64="Optimistic",Scenarios!I98,Scenarios!I183)) -> 0.02
A10: Tax Rate | B10: 0.2513587 | C10: 0.25230415 | D10: 0.25201613 | E10: =IF(Assumptions!$B$64="Base Case",Scenarios!E14,IF(Assumptions!$B$64="Optimistic",Scenarios!E99,Scenarios!E184)) -> 0.225 | F10: =IF(Assumptions!$B$64="Base Case",Scenarios!F14,IF(Assumptions!$B$64="Optimistic",Scenarios!F99,Scenarios!F184)) -> 0.225 | G10: =IF(Assumptions!$B$64="Base Case",Scenarios!G14,IF(Assumptions!$B$64="Optimistic",Scenarios!G99,Scenarios!G184)) -> 0.225 | H10: =IF(Assumptions!$B$64="Base Case",Scenarios!H14,IF(Assumptions!$B$64="Optimistic",Scenarios!H99,Scenarios!H184)) -> 0.225 | I10: =IF(Assumptions!$B$64="Base Case",Scenarios!I14,IF(Assumptions!$B$64="Optimistic",Scenarios!I99,Scenarios!I184)) -> 0.225
A11: Other Income / Expense | B11: 0 | C11: 0 | D11: 0 | E11: =IF(Assumptions!$B$64="Base Case",Scenarios!E15,IF(Assumptions!$B$64="Optimistic",Scenarios!E100,Scenarios!E185)) -> 0 | F11: =IF(Assumptions!$B$64="Base Case",Scenarios!F15,IF(Assumptions!$B$64="Optimistic",Scenarios!F100,Scenarios!F185)) -> 0 | G11: =IF(Assumptions!$B$64="Base Case",Scenarios!G15,IF(Assumptions!$B$64="Optimistic",Scenarios!G100,Scenarios!G185)) -> 0 | H11: =IF(Assumptions!$B$64="Base Case",Scenarios!H15,IF(Assumptions!$B$64="Optimistic",Scenarios!H100,Scenarios!H185)) -> 0 | I11: =IF(Assumptions!$B$64="Base Case",Scenarios!I15,IF(Assumptions!$B$64="Optimistic",Scenarios!I100,Scenarios!I185)) -> 0
A12: Shares Outstanding | B12: 100000 | C12: 100000 | D12: 100000 | E12: =IF(Assumptions!$B$64="Base Case",Scenarios!E16,IF(Assumptions!$B$64="Optimistic",Scenarios!E101,Scenarios!E186)) -> 100000 | F12: =IF(Assumptions!$B$64="Base Case",Scenarios!F16,IF(Assumptions!$B$64="Optimistic",Scenarios!F101,Scenarios!F186)) -> 100000 | G12: =IF(Assumptions!$B$64="Base Case",Scenarios!G16,IF(Assumptions!$B$64="Optimistic",Scenarios!G101,Scenarios!G186)) -> 100000 | H12: =IF(Assumptions!$B$64="Base Case",Scenarios!H16,IF(Assumptions!$B$64="Optimistic",Scenarios!H101,Scenarios!H186)) -> 100000 | I12: =IF(Assumptions!$B$64="Base Case",Scenarios!I16,IF(Assumptions!$B$64="Optimistic",Scenarios!I101,Scenarios!I186)) -> 100000
A13: Stock-Based Comp Amount | B13: 0 | C13: 0 | D13: 0 | E13: =IF(Assumptions!$B$64="Base Case",Scenarios!E17,IF(Assumptions!$B$64="Optimistic",Scenarios!E102,Scenarios!E187)) -> 10000 | F13: =IF(Assumptions!$B$64="Base Case",Scenarios!F17,IF(Assumptions!$B$64="Optimistic",Scenarios!F102,Scenarios!F187)) -> 10000 | G13: =IF(Assumptions!$B$64="Base Case",Scenarios!G17,IF(Assumptions!$B$64="Optimistic",Scenarios!G102,Scenarios!G187)) -> 10000 | H13: =IF(Assumptions!$B$64="Base Case",Scenarios!H17,IF(Assumptions!$B$64="Optimistic",Scenarios!H102,Scenarios!H187)) -> 10000 | I13: =IF(Assumptions!$B$64="Base Case",Scenarios!I17,IF(Assumptions!$B$64="Optimistic",Scenarios!I102,Scenarios!I187)) -> 10000
A14: ── Balance Sheet / WC Drivers ──
A15: DSO (Days) | B15: 45.00012 | C15: 45.000206 | D15: 44.999889 | E15: =IF(Assumptions!$B$64="Base Case",Scenarios!E19,IF(Assumptions!$B$64="Optimistic",Scenarios!E104,Scenarios!E189)) -> 45 | F15: =IF(Assumptions!$B$64="Base Case",Scenarios!F19,IF(Assumptions!$B$64="Optimistic",Scenarios!F104,Scenarios!F189)) -> 45 | G15: =IF(Assumptions!$B$64="Base Case",Scenarios!G19,IF(Assumptions!$B$64="Optimistic",Scenarios!G104,Scenarios!G189)) -> 45 | H15: =IF(Assumptions!$B$64="Base Case",Scenarios!H19,IF(Assumptions!$B$64="Optimistic",Scenarios!H104,Scenarios!H189)) -> 45 | I15: =IF(Assumptions!$B$64="Base Case",Scenarios!I19,IF(Assumptions!$B$64="Optimistic",Scenarios!I104,Scenarios!I189)) -> 45
A16: DIO (Days) | B16: 29.999756 | C16: 30.000137 | D16: 29.999798 | E16: =IF(Assumptions!$B$64="Base Case",Scenarios!E20,IF(Assumptions!$B$64="Optimistic",Scenarios!E105,Scenarios!E190)) -> 30 | F16: =IF(Assumptions!$B$64="Base Case",Scenarios!F20,IF(Assumptions!$B$64="Optimistic",Scenarios!F105,Scenarios!F190)) -> 30 | G16: =IF(Assumptions!$B$64="Base Case",Scenarios!G20,IF(Assumptions!$B$64="Optimistic",Scenarios!G105,Scenarios!G190)) -> 30 | H16: =IF(Assumptions!$B$64="Base Case",Scenarios!H20,IF(Assumptions!$B$64="Optimistic",Scenarios!H105,Scenarios!H190)) -> 30 | I16: =IF(Assumptions!$B$64="Base Case",Scenarios!I20,IF(Assumptions!$B$64="Optimistic",Scenarios!I105,Scenarios!I190)) -> 30
A17: DPO (Days) | B17: 39.999944 | C17: 39.999706 | D17: 40.000158 | E17: =IF(Assumptions!$B$64="Base Case",Scenarios!E21,IF(Assumptions!$B$64="Optimistic",Scenarios!E106,Scenarios!E191)) -> 40 | F17: =IF(Assumptions!$B$64="Base Case",Scenarios!F21,IF(Assumptions!$B$64="Optimistic",Scenarios!F106,Scenarios!F191)) -> 40 | G17: =IF(Assumptions!$B$64="Base Case",Scenarios!G21,IF(Assumptions!$B$64="Optimistic",Scenarios!G106,Scenarios!G191)) -> 40 | H17: =IF(Assumptions!$B$64="Base Case",Scenarios!H21,IF(Assumptions!$B$64="Optimistic",Scenarios!H106,Scenarios!H191)) -> 40 | I17: =IF(Assumptions!$B$64="Base Case",Scenarios!I21,IF(Assumptions!$B$64="Optimistic",Scenarios!I106,Scenarios!I191)) -> 40
A18: Prepaid % of Revenue | B18: 0.01 | C18: 0.01 | D18: 0.01 | E18: =IF(Assumptions!$B$64="Base Case",Scenarios!E22,IF(Assumptions!$B$64="Optimistic",Scenarios!E107,Scenarios!E192)) -> 0.01 | F18: =IF(Assumptions!$B$64="Base Case",Scenarios!F22,IF(Assumptions!$B$64="Optimistic",Scenarios!F107,Scenarios!F192)) -> 0.01 | G18: =IF(Assumptions!$B$64="Base Case",Scenarios!G22,IF(Assumptions!$B$64="Optimistic",Scenarios!G107,Scenarios!G192)) -> 0.01 | H18: =IF(Assumptions!$B$64="Base Case",Scenarios!H22,IF(Assumptions!$B$64="Optimistic",Scenarios!H107,Scenarios!H192)) -> 0.01 | I18: =IF(Assumptions!$B$64="Base Case",Scenarios!I22,IF(Assumptions!$B$64="Optimistic",Scenarios!I107,Scenarios!I192)) -> 0.01
A19: Accrued Exp % of Revenue | B19: 0.03 | C19: 0.03 | D19: 0.03 | E19: =IF(Assumptions!$B$64="Base Case",Scenarios!E23,IF(Assumptions!$B$64="Optimistic",Scenarios!E108,Scenarios!E193)) -> 0.03 | F19: =IF(Assumptions!$B$64="Base Case",Scenarios!F23,IF(Assumptions!$B$64="Optimistic",Scenarios!F108,Scenarios!F193)) -> 0.03 | G19: =IF(Assumptions!$B$64="Base Case",Scenarios!G23,IF(Assumptions!$B$64="Optimistic",Scenarios!G108,Scenarios!G193)) -> 0.03 | H19: =IF(Assumptions!$B$64="Base Case",Scenarios!H23,IF(Assumptions!$B$64="Optimistic",Scenarios!H108,Scenarios!H193)) -> 0.03 | I19: =IF(Assumptions!$B$64="Base Case",Scenarios!I23,IF(Assumptions!$B$64="Optimistic",Scenarios!I108,Scenarios!I193)) -> 0.03
A20: Deferred Rev % of Revenue | B20: 0.02 | C20: 0.02 | D20: 0.02 | E20: =IF(Assumptions!$B$64="Base Case",Scenarios!E24,IF(Assumptions!$B$64="Optimistic",Scenarios!E109,Scenarios!E194)) -> 0.02 | F20: =IF(Assumptions!$B$64="Base Case",Scenarios!F24,IF(Assumptions!$B$64="Optimistic",Scenarios!F109,Scenarios!F194)) -> 0.02 | G20: =IF(Assumptions!$B$64="Base Case",Scenarios!G24,IF(Assumptions!$B$64="Optimistic",Scenarios!G109,Scenarios!G194)) -> 0.02 | H20: =IF(Assumptions!$B$64="Base Case",Scenarios!H24,IF(Assumptions!$B$64="Optimistic",Scenarios!H109,Scenarios!H194)) -> 0.02 | I20: =IF(Assumptions!$B$64="Base Case",Scenarios!I24,IF(Assumptions!$B$64="Optimistic",Scenarios!I109,Scenarios!I194)) -> 0.02
A21: ── CapEx & Depreciation Drivers ──
A22: CapEx % of Revenue | B22: 0 | C22: 0.047058824 | D22: 0.047368421 | E22: =IF(Assumptions!$B$64="Base Case",Scenarios!E26,IF(Assumptions!$B$64="Optimistic",Scenarios!E111,Scenarios!E196)) -> 0.05 | F22: =IF(Assumptions!$B$64="Base Case",Scenarios!F26,IF(Assumptions!$B$64="Optimistic",Scenarios!F111,Scenarios!F196)) -> 0.05 | G22: =IF(Assumptions!$B$64="Base Case",Scenarios!G26,IF(Assumptions!$B$64="Optimistic",Scenarios!G111,Scenarios!G196)) -> 0.05 | H22: =IF(Assumptions!$B$64="Base Case",Scenarios!H26,IF(Assumptions!$B$64="Optimistic",Scenarios!H111,Scenarios!H196)) -> 0.05 | I22: =IF(Assumptions!$B$64="Base Case",Scenarios!I26,IF(Assumptions!$B$64="Optimistic",Scenarios!I111,Scenarios!I196)) -> 0.05
A23: Depreciation Rate (% Gross PPE) | B23: 0.083333333 | C23: 0.082352941 | D23: 0.083116883 | E23: =IF(Assumptions!$B$64="Base Case",Scenarios!E27,IF(Assumptions!$B$64="Optimistic",Scenarios!E112,Scenarios!E197)) -> 0.094025157 | F23: =IF(Assumptions!$B$64="Base Case",Scenarios!F27,IF(Assumptions!$B$64="Optimistic",Scenarios!F112,Scenarios!F197)) -> 0.094284759 | G23: =IF(Assumptions!$B$64="Base Case",Scenarios!G27,IF(Assumptions!$B$64="Optimistic",Scenarios!G112,Scenarios!G197)) -> 0.094551124 | H23: =IF(Assumptions!$B$64="Base Case",Scenarios!H27,IF(Assumptions!$B$64="Optimistic",Scenarios!H112,Scenarios!H197)) -> 0.094822299 | I23: =IF(Assumptions!$B$64="Base Case",Scenarios!I27,IF(Assumptions!$B$64="Optimistic",Scenarios!I112,Scenarios!I197)) -> 0.095096572
A24: Amortization Amount | B24: 5000 | C24: 5000 | D24: 5000 | E24: =IF(Assumptions!$B$64="Base Case",Scenarios!E28,IF(Assumptions!$B$64="Optimistic",Scenarios!E113,Scenarios!E198)) -> 5000 | F24: =IF(Assumptions!$B$64="Base Case",Scenarios!F28,IF(Assumptions!$B$64="Optimistic",Scenarios!F113,Scenarios!F198)) -> 5000 | G24: =IF(Assumptions!$B$64="Base Case",Scenarios!G28,IF(Assumptions!$B$64="Optimistic",Scenarios!G113,Scenarios!G198)) -> 5000 | H24: =IF(Assumptions!$B$64="Base Case",Scenarios!H28,IF(Assumptions!$B$64="Optimistic",Scenarios!H113,Scenarios!H198)) -> 5000 | I24: =IF(Assumptions!$B$64="Base Case",Scenarios!I28,IF(Assumptions!$B$64="Optimistic",Scenarios!I113,Scenarios!I198)) -> 5000
A25: ── Debt & Financing ──
A26: Interest Rate (on Debt) | B26: 0.2 | C26: 0.2 | D26: 0.2 | E26: =IF(Assumptions!$B$64="Base Case",Scenarios!E30,IF(Assumptions!$B$64="Optimistic",Scenarios!E115,Scenarios!E200)) -> 0.2 | F26: =IF(Assumptions!$B$64="Base Case",Scenarios!F30,IF(Assumptions!$B$64="Optimistic",Scenarios!F115,Scenarios!F200)) -> 0.2 | G26: =IF(Assumptions!$B$64="Base Case",Scenarios!G30,IF(Assumptions!$B$64="Optimistic",Scenarios!G115,Scenarios!G200)) -> 0.2 | H26: =IF(Assumptions!$B$64="Base Case",Scenarios!H30,IF(Assumptions!$B$64="Optimistic",Scenarios!H115,Scenarios!H200)) -> 0.2 | I26: =IF(Assumptions!$B$64="Base Case",Scenarios!I30,IF(Assumptions!$B$64="Optimistic",Scenarios!I115,Scenarios!I200)) -> 0.2
A27: Interest Income Rate (on Cash) | B27: 0.02 | C27: 0.02 | D27: 0.02 | E27: =IF(Assumptions!$B$64="Base Case",Scenarios!E31,IF(Assumptions!$B$64="Optimistic",Scenarios!E116,Scenarios!E201)) -> 0.02 | F27: =IF(Assumptions!$B$64="Base Case",Scenarios!F31,IF(Assumptions!$B$64="Optimistic",Scenarios!F116,Scenarios!F201)) -> 0.02 | G27: =IF(Assumptions!$B$64="Base Case",Scenarios!G31,IF(Assumptions!$B$64="Optimistic",Scenarios!G116,Scenarios!G201)) -> 0.02 | H27: =IF(Assumptions!$B$64="Base Case",Scenarios!H31,IF(Assumptions!$B$64="Optimistic",Scenarios!H116,Scenarios!H201)) -> 0.02 | I27: =IF(Assumptions!$B$64="Base Case",Scenarios!I31,IF(Assumptions!$B$64="Optimistic",Scenarios!I116,Scenarios!I201)) -> 0.02
A28: Short-Term Debt | B28: 50000 | C28: 50000 | D28: 50000 | E28: =IF(Assumptions!$B$64="Base Case",Scenarios!E32,IF(Assumptions!$B$64="Optimistic",Scenarios!E117,Scenarios!E202)) -> 50000 | F28: =IF(Assumptions!$B$64="Base Case",Scenarios!F32,IF(Assumptions!$B$64="Optimistic",Scenarios!F117,Scenarios!F202)) -> 50000 | G28: =IF(Assumptions!$B$64="Base Case",Scenarios!G32,IF(Assumptions!$B$64="Optimistic",Scenarios!G117,Scenarios!G202)) -> 50000 | H28: =IF(Assumptions!$B$64="Base Case",Scenarios!H32,IF(Assumptions!$B$64="Optimistic",Scenarios!H117,Scenarios!H202)) -> 50000 | I28: =IF(Assumptions!$B$64="Base Case",Scenarios!I32,IF(Assumptions!$B$64="Optimistic",Scenarios!I117,Scenarios!I202)) -> 50000
A29: LT Debt Issuance | B29: 0 | C29: 0 | D29: 0 | E29: =IF(Assumptions!$B$64="Base Case",Scenarios!E33,IF(Assumptions!$B$64="Optimistic",Scenarios!E118,Scenarios!E203)) -> 0 | F29: =IF(Assumptions!$B$64="Base Case",Scenarios!F33,IF(Assumptions!$B$64="Optimistic",Scenarios!F118,Scenarios!F203)) -> 0 | G29: =IF(Assumptions!$B$64="Base Case",Scenarios!G33,IF(Assumptions!$B$64="Optimistic",Scenarios!G118,Scenarios!G203)) -> 0 | H29: =IF(Assumptions!$B$64="Base Case",Scenarios!H33,IF(Assumptions!$B$64="Optimistic",Scenarios!H118,Scenarios!H203)) -> 0 | I29: =IF(Assumptions!$B$64="Base Case",Scenarios!I33,IF(Assumptions!$B$64="Optimistic",Scenarios!I118,Scenarios!I203)) -> 0
A30: LT Debt Repayment | B30: 0 | C30: 20000 | D30: 20000 | E30: =IF(Assumptions!$B$64="Base Case",Scenarios!E34,IF(Assumptions!$B$64="Optimistic",Scenarios!E119,Scenarios!E204)) -> 20000 | F30: =IF(Assumptions!$B$64="Base Case",Scenarios!F34,IF(Assumptions!$B$64="Optimistic",Scenarios!F119,Scenarios!F204)) -> 20000 | G30: =IF(Assumptions!$B$64="Base Case",Scenarios!G34,IF(Assumptions!$B$64="Optimistic",Scenarios!G119,Scenarios!G204)) -> 20000 | H30: =IF(Assumptions!$B$64="Base Case",Scenarios!H34,IF(Assumptions!$B$64="Optimistic",Scenarios!H119,Scenarios!H204)) -> 20000 | I30: =IF(Assumptions!$B$64="Base Case",Scenarios!I34,IF(Assumptions!$B$64="Optimistic",Scenarios!I119,Scenarios!I204)) -> 20000
A31: Current Portion LTD | B31: 20000 | C31: 20000 | D31: 20000 | E31: =IF(Assumptions!$B$64="Base Case",Scenarios!E35,IF(Assumptions!$B$64="Optimistic",Scenarios!E120,Scenarios!E205)) -> 20000 | F31: =IF(Assumptions!$B$64="Base Case",Scenarios!F35,IF(Assumptions!$B$64="Optimistic",Scenarios!F120,Scenarios!F205)) -> 20000 | G31: =IF(Assumptions!$B$64="Base Case",Scenarios!G35,IF(Assumptions!$B$64="Optimistic",Scenarios!G120,Scenarios!G205)) -> 20000 | H31: =IF(Assumptions!$B$64="Base Case",Scenarios!H35,IF(Assumptions!$B$64="Optimistic",Scenarios!H120,Scenarios!H205)) -> 20000 | I31: =IF(Assumptions!$B$64="Base Case",Scenarios!I35,IF(Assumptions!$B$64="Optimistic",Scenarios!I120,Scenarios!I205)) -> 20000
A32: Dividend Payout Ratio | B32: 0 | C32: 0.39986441 | D32: 0.46433423 | E32: =IF(Assumptions!$B$64="Base Case",Scenarios!E36,IF(Assumptions!$B$64="Optimistic",Scenarios!E121,Scenarios!E206)) -> 0.05 | F32: =IF(Assumptions!$B$64="Base Case",Scenarios!F36,IF(Assumptions!$B$64="Optimistic",Scenarios!F121,Scenarios!F206)) -> 0.05 | G32: =IF(Assumptions!$B$64="Base Case",Scenarios!G36,IF(Assumptions!$B$64="Optimistic",Scenarios!G121,Scenarios!G206)) -> 0.05 | H32: =IF(Assumptions!$B$64="Base Case",Scenarios!H36,IF(Assumptions!$B$64="Optimistic",Scenarios!H121,Scenarios!H206)) -> 0.05 | I32: =IF(Assumptions!$B$64="Base Case",Scenarios!I36,IF(Assumptions!$B$64="Optimistic",Scenarios!I121,Scenarios!I206)) -> 0.05
A33: Share Repurchase Amount | B33: 0 | C33: 0 | D33: 0 | E33: =IF(Assumptions!$B$64="Base Case",Scenarios!E37,IF(Assumptions!$B$64="Optimistic",Scenarios!E122,Scenarios!E207)) -> 0 | F33: =IF(Assumptions!$B$64="Base Case",Scenarios!F37,IF(Assumptions!$B$64="Optimistic",Scenarios!F122,Scenarios!F207)) -> 0 | G33: =IF(Assumptions!$B$64="Base Case",Scenarios!G37,IF(Assumptions!$B$64="Optimistic",Scenarios!G122,Scenarios!G207)) -> 0 | H33: =IF(Assumptions!$B$64="Base Case",Scenarios!H37,IF(Assumptions!$B$64="Optimistic",Scenarios!H122,Scenarios!H207)) -> 0 | I33: =IF(Assumptions!$B$64="Base Case",Scenarios!I37,IF(Assumptions!$B$64="Optimistic",Scenarios!I122,Scenarios!I207)) -> 0
A34: Equity Issuance | B34: 0 | C34: 10000 | D34: 10000 | E34: =IF(Assumptions!$B$64="Base Case",Scenarios!E38,IF(Assumptions!$B$64="Optimistic",Scenarios!E123,Scenarios!E208)) -> 0 | F34: =IF(Assumptions!$B$64="Base Case",Scenarios!F38,IF(Assumptions!$B$64="Optimistic",Scenarios!F123,Scenarios!F208)) -> 0 | G34: =IF(Assumptions!$B$64="Base Case",Scenarios!G38,IF(Assumptions!$B$64="Optimistic",Scenarios!G123,Scenarios!G208)) -> 0 | H34: =IF(Assumptions!$B$64="Base Case",Scenarios!H38,IF(Assumptions!$B$64="Optimistic",Scenarios!H123,Scenarios!H208)) -> 0 | I34: =IF(Assumptions!$B$64="Base Case",Scenarios!I38,IF(Assumptions!$B$64="Optimistic",Scenarios!I123,Scenarios!I208)) -> 0
A35: ── BS / Equity Direct Values ──
A36: Goodwill | B36: 100000 | C36: 100000 | D36: 100000 | E36: =IF(Assumptions!$B$64="Base Case",Scenarios!E40,IF(Assumptions!$B$64="Optimistic",Scenarios!E125,Scenarios!E210)) -> 100000 | F36: =IF(Assumptions!$B$64="Base Case",Scenarios!F40,IF(Assumptions!$B$64="Optimistic",Scenarios!F125,Scenarios!F210)) -> 100000 | G36: =IF(Assumptions!$B$64="Base Case",Scenarios!G40,IF(Assumptions!$B$64="Optimistic",Scenarios!G125,Scenarios!G210)) -> 100000 | H36: =IF(Assumptions!$B$64="Base Case",Scenarios!H40,IF(Assumptions!$B$64="Optimistic",Scenarios!H125,Scenarios!H210)) -> 100000 | I36: =IF(Assumptions!$B$64="Base Case",Scenarios!I40,IF(Assumptions!$B$64="Optimistic",Scenarios!I125,Scenarios!I210)) -> 100000
A37: Other Current Assets | B37: 10000 | C37: 10000 | D37: 10000 | E37: =IF(Assumptions!$B$64="Base Case",Scenarios!E41,IF(Assumptions!$B$64="Optimistic",Scenarios!E126,Scenarios!E211)) -> 10000 | F37: =IF(Assumptions!$B$64="Base Case",Scenarios!F41,IF(Assumptions!$B$64="Optimistic",Scenarios!F126,Scenarios!F211)) -> 10000 | G37: =IF(Assumptions!$B$64="Base Case",Scenarios!G41,IF(Assumptions!$B$64="Optimistic",Scenarios!G126,Scenarios!G211)) -> 10000 | H37: =IF(Assumptions!$B$64="Base Case",Scenarios!H41,IF(Assumptions!$B$64="Optimistic",Scenarios!H126,Scenarios!H211)) -> 10000 | I37: =IF(Assumptions!$B$64="Base Case",Scenarios!I41,IF(Assumptions!$B$64="Optimistic",Scenarios!I126,Scenarios!I211)) -> 10000
A38: Other Long-Term Assets | B38: 20000 | C38: 20000 | D38: 20000 | E38: =IF(Assumptions!$B$64="Base Case",Scenarios!E42,IF(Assumptions!$B$64="Optimistic",Scenarios!E127,Scenarios!E212)) -> 20000 | F38: =IF(Assumptions!$B$64="Base Case",Scenarios!F42,IF(Assumptions!$B$64="Optimistic",Scenarios!F127,Scenarios!F212)) -> 20000 | G38: =IF(Assumptions!$B$64="Base Case",Scenarios!G42,IF(Assumptions!$B$64="Optimistic",Scenarios!G127,Scenarios!G212)) -> 20000 | H38: =IF(Assumptions!$B$64="Base Case",Scenarios!H42,IF(Assumptions!$B$64="Optimistic",Scenarios!H127,Scenarios!H212)) -> 20000 | I38: =IF(Assumptions!$B$64="Base Case",Scenarios!I42,IF(Assumptions!$B$64="Optimistic",Scenarios!I127,Scenarios!I212)) -> 20000
A39: Other Current Liabilities | B39: 15000 | C39: 15000 | D39: 15000 | E39: =IF(Assumptions!$B$64="Base Case",Scenarios!E43,IF(Assumptions!$B$64="Optimistic",Scenarios!E128,Scenarios!E213)) -> 15000 | F39: =IF(Assumptions!$B$64="Base Case",Scenarios!F43,IF(Assumptions!$B$64="Optimistic",Scenarios!F128,Scenarios!F213)) -> 15000 | G39: =IF(Assumptions!$B$64="Base Case",Scenarios!G43,IF(Assumptions!$B$64="Optimistic",Scenarios!G128,Scenarios!G213)) -> 15000 | H39: =IF(Assumptions!$B$64="Base Case",Scenarios!H43,IF(Assumptions!$B$64="Optimistic",Scenarios!H128,Scenarios!H213)) -> 15000 | I39: =IF(Assumptions!$B$64="Base Case",Scenarios!I43,IF(Assumptions!$B$64="Optimistic",Scenarios!I128,Scenarios!I213)) -> 15000
A40: Deferred Tax Liabilities | B40: 30000 | C40: 30000 | D40: 30000 | E40: =IF(Assumptions!$B$64="Base Case",Scenarios!E44,IF(Assumptions!$B$64="Optimistic",Scenarios!E129,Scenarios!E214)) -> 30000 | F40: =IF(Assumptions!$B$64="Base Case",Scenarios!F44,IF(Assumptions!$B$64="Optimistic",Scenarios!F129,Scenarios!F214)) -> 30000 | G40: =IF(Assumptions!$B$64="Base Case",Scenarios!G44,IF(Assumptions!$B$64="Optimistic",Scenarios!G129,Scenarios!G214)) -> 30000 | H40: =IF(Assumptions!$B$64="Base Case",Scenarios!H44,IF(Assumptions!$B$64="Optimistic",Scenarios!H129,Scenarios!H214)) -> 30000 | I40: =IF(Assumptions!$B$64="Base Case",Scenarios!I44,IF(Assumptions!$B$64="Optimistic",Scenarios!I129,Scenarios!I214)) -> 30000
...

Sheet Income Statement
A1: WOLF — Income Statement | B1: 2021 (A) | C1: 2022 (A) | D1: 2023 (A) | E1: 2024E | F1: 2025E | G1: 2026E | H1: 2027E | I1: 2028E
A2: Revenue | B2: =Assumptions!B3 -> 750000 | C2: =B2*(1+Assumptions!C5) -> 850000 | D2: =C2*(1+Assumptions!D5) -> 950000 | E2: =D2*(1+Assumptions!E5) -> 1045000 | F2: =E2*(1+Assumptions!F5) -> 1128600 | G2: =F2*(1+Assumptions!G5) -> 1207602 | H2: =G2*(1+Assumptions!H5) -> 1280058.1 | I2: =H2*(1+Assumptions!I5) -> 1344061
A3: Revenue Growth % | B3: =Assumptions!B5 -> 0 | C3: =Assumptions!C5 -> 0.13333333 | D3: =Assumptions!D5 -> 0.11764706 | E3: =Assumptions!E5 -> 0.1 | F3: =Assumptions!F5 -> 0.08 | G3: =Assumptions!G5 -> 0.07 | H3: =Assumptions!H5 -> 0.06 | I3: =Assumptions!I5 -> 0.05
A4: Cost of Goods Sold | B4: =B2*Assumptions!B6 -> 450000 | C4: =C2*Assumptions!C6 -> 510000 | D4: =D2*Assumptions!D6 -> 570000 | E4: =E2*Assumptions!E6 -> 627000 | F4: =F2*Assumptions!F6 -> 677160 | G4: =G2*Assumptions!G6 -> 724561.2 | H4: =H2*Assumptions!H6 -> 768034.87 | I4: =I2*Assumptions!I6 -> 806436.62
A5: Gross Profit | B5: =B2-B4 -> 300000 | C5: =C2-C4 -> 340000 | D5: =D2-D4 -> 380000 | E5: =E2-E4 -> 418000 | F5: =F2-F4 -> 451440 | G5: =G2-G4 -> 483040.8 | H5: =H2-H4 -> 512023.25 | I5: =I2-I4 -> 537624.41
A6: Gross Margin | B6: =IF(B2=0,0,B5/B2) -> 0.4 | C6: =IF(C2=0,0,C5/C2) -> 0.4 | D6: =IF(D2=0,0,D5/D2) -> 0.4 | E6: =IF(E2=0,0,E5/E2) -> 0.4 | F6: =IF(F2=0,0,F5/F2) -> 0.4 | G6: =IF(G2=0,0,G5/G2) -> 0.4 | H6: =IF(H2=0,0,H5/H2) -> 0.4 | I6: =IF(I2=0,0,I5/I2) -> 0.4
A8: Operating Expenses
A9: SG&A | B9: =B2*Assumptions!B7 -> 112500 | C9: =C2*Assumptions!C7 -> 127500 | D9: =D2*Assumptions!D7 -> 142500 | E9: =E2*Assumptions!E7 -> 156750 | F9: =F2*Assumptions!F7 -> 169290 | G9: =G2*Assumptions!G7 -> 181140.3 | H9: =H2*Assumptions!H7 -> 192008.72 | I9: =I2*Assumptions!I7 -> 201609.15
A10: R&D | B10: =B2*Assumptions!B8 -> 37500 | C10: =C2*Assumptions!C8 -> 42500 | D10: =D2*Assumptions!D8 -> 47500 | E10: =E2*Assumptions!E8 -> 52250 | F10: =F2*Assumptions!F8 -> 56430 | G10: =G2*Assumptions!G8 -> 60380.1 | H10: =H2*Assumptions!H8 -> 64002.906 | I10: =I2*Assumptions!I8 -> 67203.051
A11: Depreciation | B11: =Assumptions!B48 -> 25000 | C11: =Assumptions!C48 -> 28000 | D11: =Assumptions!D48 -> 32000 | E11: =(Assumptions!D49+'Income Statement'!E2*Assumptions!E22/2)*Assumptions!E23 -> 41112.5 | F11: =(Assumptions!E49+'Income Statement'!F2*Assumptions!F22/2)*Assumptions!F23 -> 46546.5 | G11: =(Assumptions!F49+'Income Statement'!G2*Assumptions!G22/2)*Assumptions!G23 -> 52387.005 | H11: =(Assumptions!G49+'Income Statement'!H2*Assumptions!H22/2)*Assumptions!H23 -> 58606.155 | I11: =(Assumptions!H49+'Income Statement'!I2*Assumptions!I22/2)*Assumptions!I23 -> 65166.453
A12: Amortization | B12: =Assumptions!B24 -> 5000 | C12: =Assumptions!C24 -> 5000 | D12: =Assumptions!D24 -> 5000 | E12: =Assumptions!E24 -> 5000 | F12: =Assumptions!F24 -> 5000 | G12: =Assumptions!G24 -> 5000 | H12: =Assumptions!H24 -> 5000 | I12: =Assumptions!I24 -> 5000
A13: Other OpEx | B13: =B2*Assumptions!B9 -> 15000 | C13: =C2*Assumptions!C9 -> 17000 | D13: =D2*Assumptions!D9 -> 19000 | E13: =E2*Assumptions!E9 -> 20900 | F13: =F2*Assumptions!F9 -> 22572 | G13: =G2*Assumptions!G9 -> 24152.04 | H13: =H2*Assumptions!H9 -> 25601.162 | I13: =I2*Assumptions!I9 -> 26881.221
A14: Stock-Based Comp | B14: =Assumptions!B13 -> 0 | C14: =Assumptions!C13 -> 0 | D14: =Assumptions!D13 -> 0 | E14: =Assumptions!E13 -> 10000 | F14: =Assumptions!F13 -> 10000 | G14: =Assumptions!G13 -> 10000 | H14: =Assumptions!H13 -> 10000 | I14: =Assumptions!I13 -> 10000
A15: Total OpEx | B15: =B9+B10+B11+B12+B13+B14 -> 195000 | C15: =C9+C10+C11+C12+C13+C14 -> 220000 | D15: =D9+D10+D11+D12+D13+D14 -> 246000 | E15: =E9+E10+E11+E12+E13+E14 -> 286012.5 | F15: =F9+F10+F11+F12+F13+F14 -> 309838.5 | G15: =G9+G10+G11+G12+G13+G14 -> 333059.45 | H15: =H9+H10+H11+H12+H13+H14 -> 355218.94 | I15: =I9+I10+I11+I12+I13+I14 -> 375859.88
A17: EBIT | B17: =B5-B15 -> 105000 | C17: =C5-C15 -> 120000 | D17: =D5-D15 -> 134000 | E17: =E5-E15 -> 131987.5 | F17: =F5-F15 -> 141601.5 | G17: =G5-G15 -> 149981.36 | H17: =H5-H15 -> 156804.31 | I17: =I5-I15 -> 161764.53
A18: EBITDA | B18: =B17+B11+B12 -> 135000 | C18: =C17+C11+C12 -> 153000 | D18: =D17+D11+D12 -> 171000 | E18: =E17+E11+E12 -> 178100 | F18: =F17+F11+F12 -> 193148 | G18: =G17+G11+G12 -> 207368.36 | H18: =H17+H11+H12 -> 220410.46 | I18: =I17+I11+I12 -> 231930.98
A19: EBIT Margin | B19: =IF(B2=0,0,B17/B2) -> 0.14 | C19: =IF(C2=0,0,C17/C2) -> 0.14117647 | D19: =IF(D2=0,0,D17/D2) -> 0.14105263 | E19: =IF(E2=0,0,E17/E2) -> 0.12630383 | F19: =IF(F2=0,0,F17/F2) -> 0.12546651 | G19: =IF(G2=0,0,G17/G2) -> 0.12419767 | H19: =IF(H2=0,0,H17/H2) -> 0.1224978 | I19: =IF(I2=0,0,I17/I2) -> 0.12035505
A21: Interest Income | B21: =Assumptions!B46 -> 2000 | C21: =Assumptions!C46 -> 2500 | D21: =Assumptions!D46 -> 3000 | E21: =Assumptions!E46 -> 4381.5518 | F21: =Assumptions!F46 -> 5271.6108 | G21: =Assumptions!G46 -> 6410.1322 | H21: =Assumptions!H46 -> 7790.3454 | I21: =Assumptions!I46 -> 9407.875
A22: Interest Expense | B22: =Assumptions!B47 -> 15000 | C22: =Assumptions!C47 -> 14000 | D22: =Assumptions!D47 -> 13000 | E22: =Assumptions!E47 -> 54000 | F22: =Assumptions!F47 -> 50000 | G22: =Assumptions!G47 -> 46000 | H22: =Assumptions!H47 -> 42000 | I22: =Assumptions!I47 -> 38000
A23: Other Income/Expense | B23: =Assumptions!B11 -> 0 | C23: =Assumptions!C11 -> 0 | D23: =Assumptions!D11 -> 0 | E23: =Assumptions!E11 -> 0 | F23: =Assumptions!F11 -> 0 | G23: =Assumptions!G11 -> 0 | H23: =Assumptions!H11 -> 0 | I23: =Assumptions!I11 -> 0
A24: EBT | B24: =B17+B21-B22+B23 -> 92000 | C24: =C17+C21-C22+C23 -> 108500 | D24: =D17+D21-D22+D23 -> 124000 | E24: =E17+E21-E22+E23 -> 82369.052 | F24: =F17+F21-F22+F23 -> 96873.111 | G24: =G17+G21-G22+G23 -> 110391.49 | H24: =H17+H21-H22+H23 -> 122594.65 | I24: =I17+I21-I22+I23 -> 133172.41
A25: Tax Expense | B25: =MAX(0,B24*Assumptions!B10) -> 23125 | C25: =MAX(0,C24*Assumptions!C10) -> 27375 | D25: =MAX(0,D24*Assumptions!D10) -> 31250 | E25: =MAX(0,E24*Assumptions!E10) -> 18533.037 | F25: =MAX(0,F24*Assumptions!F10) -> 21796.45 | G25: =MAX(0,G24*Assumptions!G10) -> 24838.085 | H25: =MAX(0,H24*Assumptions!H10) -> 27583.797 | I25: =MAX(0,I24*Assumptions!I10) -> 29963.791
